[2025-03-10T10:38:53.447+0000] {local_task_job_runner.py:123} INFO - ::group::Pre task execution logs
[2025-03-10T10:38:53.669+0000] {taskinstance.py:2614} INFO - Dependencies all met for dep_context=non-requeueable deps ti=<TaskInstance: tiki_extract_dag.crawl_do-choi-me-be manual__2025-03-10T10:33:29.927545+00:00 [queued]>
[2025-03-10T10:38:53.791+0000] {taskinstance.py:2614} INFO - Dependencies all met for dep_context=requeueable deps ti=<TaskInstance: tiki_extract_dag.crawl_do-choi-me-be manual__2025-03-10T10:33:29.927545+00:00 [queued]>
[2025-03-10T10:38:53.793+0000] {taskinstance.py:2867} INFO - Starting attempt 1 of 4
[2025-03-10T10:38:53.914+0000] {taskinstance.py:2890} INFO - Executing <Task(PythonOperator): crawl_do-choi-me-be> on 2025-03-10 10:33:29.927545+00:00
[2025-03-10T10:38:54.066+0000] {standard_task_runner.py:104} INFO - Running: ['***', 'tasks', 'run', 'tiki_extract_dag', 'crawl_do-choi-me-be', 'manual__2025-03-10T10:33:29.927545+00:00', '--job-id', '460', '--raw', '--subdir', 'DAGS_FOLDER/tiki_extract_dag.py', '--cfg-path', '/tmp/tmpiepjaab7']
[2025-03-10T10:38:54.077+0000] {standard_task_runner.py:105} INFO - Job 460: Subtask crawl_do-choi-me-be
[2025-03-10T10:38:54.069+0000] {warnings.py:112} WARNING - /home/***/.local/lib/python3.12/site-packages/***/task/task_runner/standard_task_runner.py:70: DeprecationWarning: This process (pid=192) is multi-threaded, use of fork() may lead to deadlocks in the child.
  pid = os.fork()

[2025-03-10T10:38:54.095+0000] {standard_task_runner.py:72} INFO - Started process 213 to run task
[2025-03-10T10:38:54.607+0000] {task_command.py:467} INFO - Running <TaskInstance: tiki_extract_dag.crawl_do-choi-me-be manual__2025-03-10T10:33:29.927545+00:00 [running]> on host 0c9fb3f19112
[2025-03-10T10:39:03.563+0000] {taskinstance.py:3134} INFO - Exporting env vars: AIRFLOW_CTX_DAG_OWNER='***' AIRFLOW_CTX_DAG_ID='tiki_extract_dag' AIRFLOW_CTX_TASK_ID='crawl_do-choi-me-be' AIRFLOW_CTX_EXECUTION_DATE='2025-03-10T10:33:29.927545+00:00' AIRFLOW_CTX_TRY_NUMBER='1' AIRFLOW_CTX_DAG_RUN_ID='manual__2025-03-10T10:33:29.927545+00:00'
[2025-03-10T10:39:03.582+0000] {logging_mixin.py:190} INFO - Task instance is in running state
[2025-03-10T10:39:03.584+0000] {logging_mixin.py:190} INFO -  Previous state of the Task instance: queued
[2025-03-10T10:39:03.585+0000] {logging_mixin.py:190} INFO - Current task name:crawl_do-choi-me-be state:running start_date:2025-03-10 10:38:53.684356+00:00
[2025-03-10T10:39:03.586+0000] {logging_mixin.py:190} INFO - Dag name:tiki_extract_dag and current dag run status:running
[2025-03-10T10:39:03.587+0000] {taskinstance.py:732} INFO - ::endgroup::
[2025-03-10T10:39:10.761+0000] {tiki_extract_dag.py:132} INFO - Starting crawl for category do-choi-me-be (ID: 2549)
[2025-03-10T10:39:10.763+0000] {tiki_extract_dag.py:134} INFO - Calling API: https://tiki.vn/api/v2/products with params: {'page': 1, 'limit': 40, 'category': '2549'}
[2025-03-10T10:39:12.239+0000] {tiki_extract_dag.py:143} INFO - Total pages for do-choi-me-be: 50 (limited to 50)
[2025-03-10T10:39:36.825+0000] {job.py:229} INFO - Heartbeat recovered after 21.74 seconds
[2025-03-10T10:39:43.309+0000] {tiki_extract_dag.py:119} ERROR - Error fetching details for product 274058666: Expecting value: line 1 column 1 (char 0)
[2025-03-10T10:39:43.462+0000] {tiki_extract_dag.py:119} ERROR - Error fetching details for product 274058660: Expecting value: line 1 column 1 (char 0)
[2025-03-10T10:39:43.614+0000] {tiki_extract_dag.py:119} ERROR - Error fetching details for product 272847939: Expecting value: line 1 column 1 (char 0)
[2025-03-10T10:39:43.776+0000] {tiki_extract_dag.py:119} ERROR - Error fetching details for product 271452044: Expecting value: line 1 column 1 (char 0)
[2025-03-10T10:39:43.922+0000] {tiki_extract_dag.py:119} ERROR - Error fetching details for product 247427686: Expecting value: line 1 column 1 (char 0)
[2025-03-10T10:39:44.067+0000] {tiki_extract_dag.py:119} ERROR - Error fetching details for product 206622901: Expecting value: line 1 column 1 (char 0)
[2025-03-10T10:39:44.213+0000] {tiki_extract_dag.py:119} ERROR - Error fetching details for product 190702377: Expecting value: line 1 column 1 (char 0)
[2025-03-10T10:39:44.415+0000] {tiki_extract_dag.py:119} ERROR - Error fetching details for product 187186772: Expecting value: line 1 column 1 (char 0)
[2025-03-10T10:39:44.652+0000] {tiki_extract_dag.py:119} ERROR - Error fetching details for product 168779219: Expecting value: line 1 column 1 (char 0)
[2025-03-10T10:40:01.081+0000] {connectionpool.py:868} WARNING - Retrying (Retry(total=4, connect=5, read=4, redirect=None, status=None)) after connection broken by 'ReadTimeoutError("HTTPSConnectionPool(host='tiki.vn', port=443): Read timed out. (read timeout=15)")': /api/v2/products/168663291
[2025-03-10T10:40:04.192+0000] {job.py:229} INFO - Heartbeat recovered after 21.89 seconds
[2025-03-10T10:40:04.801+0000] {tiki_extract_dag.py:119} ERROR - Error fetching details for product 168663291: Expecting value: line 1 column 1 (char 0)
[2025-03-10T10:40:04.947+0000] {tiki_extract_dag.py:119} ERROR - Error fetching details for product 168662079: Expecting value: line 1 column 1 (char 0)
[2025-03-10T10:40:05.125+0000] {tiki_extract_dag.py:119} ERROR - Error fetching details for product 159387940: Expecting value: line 1 column 1 (char 0)
[2025-03-10T10:40:05.296+0000] {tiki_extract_dag.py:119} ERROR - Error fetching details for product 117836946: Expecting value: line 1 column 1 (char 0)
[2025-03-10T10:40:05.474+0000] {tiki_extract_dag.py:119} ERROR - Error fetching details for product 114958267: Expecting value: line 1 column 1 (char 0)
[2025-03-10T10:40:05.649+0000] {tiki_extract_dag.py:119} ERROR - Error fetching details for product 95082968: Expecting value: line 1 column 1 (char 0)
[2025-03-10T10:40:05.822+0000] {tiki_extract_dag.py:119} ERROR - Error fetching details for product 88949156: Expecting value: line 1 column 1 (char 0)
[2025-03-10T10:40:05.971+0000] {tiki_extract_dag.py:119} ERROR - Error fetching details for product 68268748: Expecting value: line 1 column 1 (char 0)
[2025-03-10T10:40:06.119+0000] {tiki_extract_dag.py:119} ERROR - Error fetching details for product 59143353: Expecting value: line 1 column 1 (char 0)
[2025-03-10T10:40:06.276+0000] {tiki_extract_dag.py:119} ERROR - Error fetching details for product 57044926: Expecting value: line 1 column 1 (char 0)
[2025-03-10T10:40:06.450+0000] {tiki_extract_dag.py:119} ERROR - Error fetching details for product 34537694: Expecting value: line 1 column 1 (char 0)
[2025-03-10T10:40:06.619+0000] {tiki_extract_dag.py:119} ERROR - Error fetching details for product 24028050: Expecting value: line 1 column 1 (char 0)
[2025-03-10T10:40:06.769+0000] {tiki_extract_dag.py:119} ERROR - Error fetching details for product 17888580: Expecting value: line 1 column 1 (char 0)
[2025-03-10T10:40:06.925+0000] {tiki_extract_dag.py:119} ERROR - Error fetching details for product 7827140: Expecting value: line 1 column 1 (char 0)
[2025-03-10T10:40:07.075+0000] {tiki_extract_dag.py:119} ERROR - Error fetching details for product 1000540: Expecting value: line 1 column 1 (char 0)
[2025-03-10T10:40:07.234+0000] {tiki_extract_dag.py:119} ERROR - Error fetching details for product 1000532: Expecting value: line 1 column 1 (char 0)
[2025-03-10T10:40:07.235+0000] {tiki_extract_dag.py:156} INFO - Calling API: https://tiki.vn/api/v2/products with params: {'page': 2, 'limit': 40, 'category': '2549'}
[2025-03-10T10:40:07.392+0000] {tiki_extract_dag.py:178} ERROR - API error at page 2 in category do-choi-me-be: Expecting value: line 1 column 1 (char 0)
[2025-03-10T10:40:27.530+0000] {taskinstance.py:3313} ERROR - Task failed with exception
Traceback (most recent call last):
  File "/home/airflow/.local/lib/python3.12/site-packages/urllib3/connection.py", line 198, in _new_conn
    sock = connection.create_connection(
           ^^^^^^^^^^^^^^^^^^^^^^^^^^^^^
  File "/home/airflow/.local/lib/python3.12/site-packages/urllib3/util/connection.py", line 60, in create_connection
    for res in socket.getaddrinfo(host, port, family, socket.SOCK_STREAM):
               ^^^^^^^^^^^^^^^^^^^^^^^^^^^^^^^^^^^^^^^^^^^^^^^^^^^^^^^^^^
  File "/usr/local/lib/python3.12/socket.py", line 978, in getaddrinfo
    for res in _socket.getaddrinfo(host, port, family, type, proto, flags):
               ^^^^^^^^^^^^^^^^^^^^^^^^^^^^^^^^^^^^^^^^^^^^^^^^^^^^^^^^^^^
socket.gaierror: [Errno -3] Temporary failure in name resolution

The above exception was the direct cause of the following exception:

Traceback (most recent call last):
  File "/home/airflow/.local/lib/python3.12/site-packages/urllib3/connectionpool.py", line 787, in urlopen
    response = self._make_request(
               ^^^^^^^^^^^^^^^^^^^
  File "/home/airflow/.local/lib/python3.12/site-packages/urllib3/connectionpool.py", line 488, in _make_request
    raise new_e
  File "/home/airflow/.local/lib/python3.12/site-packages/urllib3/connectionpool.py", line 464, in _make_request
    self._validate_conn(conn)
  File "/home/airflow/.local/lib/python3.12/site-packages/urllib3/connectionpool.py", line 1093, in _validate_conn
    conn.connect()
  File "/home/airflow/.local/lib/python3.12/site-packages/urllib3/connection.py", line 704, in connect
    self.sock = sock = self._new_conn()
                       ^^^^^^^^^^^^^^^^
  File "/home/airflow/.local/lib/python3.12/site-packages/urllib3/connection.py", line 205, in _new_conn
    raise NameResolutionError(self.host, self, e) from e
urllib3.exceptions.NameResolutionError: <urllib3.connection.HTTPSConnection object at 0x7f8e6724e270>: Failed to resolve 'storage.googleapis.com' ([Errno -3] Temporary failure in name resolution)

The above exception was the direct cause of the following exception:

Traceback (most recent call last):
  File "/home/airflow/.local/lib/python3.12/site-packages/requests/adapters.py", line 667, in send
    resp = conn.urlopen(
           ^^^^^^^^^^^^^
  File "/home/airflow/.local/lib/python3.12/site-packages/urllib3/connectionpool.py", line 841, in urlopen
    retries = retries.increment(
              ^^^^^^^^^^^^^^^^^^
  File "/home/airflow/.local/lib/python3.12/site-packages/urllib3/util/retry.py", line 519, in increment
    raise MaxRetryError(_pool, url, reason) from reason  # type: ignore[arg-type]
    ^^^^^^^^^^^^^^^^^^^^^^^^^^^^^^^^^^^^^^^^^^^^^^^^^^^
urllib3.exceptions.MaxRetryError: HTTPSConnectionPool(host='storage.googleapis.com', port=443): Max retries exceeded with url: /upload/storage/v1/b/tiki-pipeline/o?uploadType=multipart (Caused by NameResolutionError("<urllib3.connection.HTTPSConnection object at 0x7f8e6724e270>: Failed to resolve 'storage.googleapis.com' ([Errno -3] Temporary failure in name resolution)"))

During handling of the above exception, another exception occurred:

Traceback (most recent call last):
  File "/home/airflow/.local/lib/python3.12/site-packages/airflow/models/taskinstance.py", line 768, in _execute_task
    result = _execute_callable(context=context, **execute_callable_kwargs)
             ^^^^^^^^^^^^^^^^^^^^^^^^^^^^^^^^^^^^^^^^^^^^^^^^^^^^^^^^^^^^^
  File "/home/airflow/.local/lib/python3.12/site-packages/airflow/models/taskinstance.py", line 734, in _execute_callable
    return ExecutionCallableRunner(
           ^^^^^^^^^^^^^^^^^^^^^^^^
  File "/home/airflow/.local/lib/python3.12/site-packages/airflow/utils/operator_helpers.py", line 252, in run
    return self.func(*args, **kwargs)
           ^^^^^^^^^^^^^^^^^^^^^^^^^^
  File "/home/airflow/.local/lib/python3.12/site-packages/airflow/models/baseoperator.py", line 424, in wrapper
    return func(self, *args, **kwargs)
           ^^^^^^^^^^^^^^^^^^^^^^^^^^^
  File "/home/airflow/.local/lib/python3.12/site-packages/airflow/operators/python.py", line 238, in execute
    return_value = self.execute_callable()
                   ^^^^^^^^^^^^^^^^^^^^^^^
  File "/home/airflow/.local/lib/python3.12/site-packages/airflow/operators/python.py", line 256, in execute_callable
    return runner.run(*self.op_args, **self.op_kwargs)
           ^^^^^^^^^^^^^^^^^^^^^^^^^^^^^^^^^^^^^^^^^^^
  File "/home/airflow/.local/lib/python3.12/site-packages/airflow/utils/operator_helpers.py", line 252, in run
    return self.func(*args, **kwargs)
           ^^^^^^^^^^^^^^^^^^^^^^^^^^
  File "/opt/airflow/dags/tiki_extract_dag.py", line 190, in crawl_category
    blob.upload_from_string(json.dumps(all_raw_data), content_type='application/json')
  File "/usr/local/lib/python3.12/contextlib.py", line 81, in inner
    return func(*args, **kwds)
           ^^^^^^^^^^^^^^^^^^^
  File "/home/airflow/.local/lib/python3.12/site-packages/google/cloud/storage/blob.py", line 3128, in upload_from_string
    self.upload_from_file(
  File "/usr/local/lib/python3.12/contextlib.py", line 81, in inner
    return func(*args, **kwds)
           ^^^^^^^^^^^^^^^^^^^
  File "/home/airflow/.local/lib/python3.12/site-packages/google/cloud/storage/blob.py", line 2851, in upload_from_file
    self._prep_and_do_upload(
  File "/home/airflow/.local/lib/python3.12/site-packages/google/cloud/storage/blob.py", line 2700, in _prep_and_do_upload
    created_json = self._do_upload(
                   ^^^^^^^^^^^^^^^^
  File "/home/airflow/.local/lib/python3.12/site-packages/google/cloud/storage/blob.py", line 2506, in _do_upload
    response = self._do_multipart_upload(
               ^^^^^^^^^^^^^^^^^^^^^^^^^^
  File "/home/airflow/.local/lib/python3.12/site-packages/google/cloud/storage/blob.py", line 2007, in _do_multipart_upload
    response = upload.transmit(
               ^^^^^^^^^^^^^^^^
  File "/home/airflow/.local/lib/python3.12/site-packages/google/resumable_media/requests/upload.py", line 153, in transmit
    return _request_helpers.wait_and_retry(
           ^^^^^^^^^^^^^^^^^^^^^^^^^^^^^^^^
  File "/home/airflow/.local/lib/python3.12/site-packages/google/resumable_media/requests/_request_helpers.py", line 178, in wait_and_retry
    raise error
  File "/home/airflow/.local/lib/python3.12/site-packages/google/resumable_media/requests/_request_helpers.py", line 155, in wait_and_retry
    response = func()
               ^^^^^^
  File "/home/airflow/.local/lib/python3.12/site-packages/google/resumable_media/requests/upload.py", line 145, in retriable_request
    result = transport.request(
             ^^^^^^^^^^^^^^^^^^
  File "/home/airflow/.local/lib/python3.12/site-packages/google/auth/transport/requests.py", line 537, in request
    response = super(AuthorizedSession, self).request(
               ^^^^^^^^^^^^^^^^^^^^^^^^^^^^^^^^^^^^^^^
  File "/home/airflow/.local/lib/python3.12/site-packages/requests/sessions.py", line 589, in request
    resp = self.send(prep, **send_kwargs)
           ^^^^^^^^^^^^^^^^^^^^^^^^^^^^^^
  File "/home/airflow/.local/lib/python3.12/site-packages/requests/sessions.py", line 703, in send
    r = adapter.send(request, **kwargs)
        ^^^^^^^^^^^^^^^^^^^^^^^^^^^^^^^
  File "/home/airflow/.local/lib/python3.12/site-packages/requests/adapters.py", line 700, in send
    raise ConnectionError(e, request=request)
requests.exceptions.ConnectionError: HTTPSConnectionPool(host='storage.googleapis.com', port=443): Max retries exceeded with url: /upload/storage/v1/b/tiki-pipeline/o?uploadType=multipart (Caused by NameResolutionError("<urllib3.connection.HTTPSConnection object at 0x7f8e6724e270>: Failed to resolve 'storage.googleapis.com' ([Errno -3] Temporary failure in name resolution)"))
[2025-03-10T10:40:29.061+0000] {job.py:229} INFO - Heartbeat recovered after 24.88 seconds
[2025-03-10T10:40:29.157+0000] {logging_mixin.py:190} INFO - Task instance in failure state
[2025-03-10T10:40:29.159+0000] {logging_mixin.py:190} INFO - Task start:2025-03-10 10:38:53.684356+00:00 end:2025-03-10 10:40:29.154746+00:00 duration:95.47039
[2025-03-10T10:40:29.161+0000] {logging_mixin.py:190} INFO - Task:<Task(PythonOperator): crawl_do-choi-me-be> dag:<DAG: tiki_extract_dag> dagrun:<DagRun tiki_extract_dag @ 2025-03-10 10:33:29.927545+00:00: manual__2025-03-10T10:33:29.927545+00:00, state:running, queued_at: 2025-03-10 10:33:30.016202+00:00. externally triggered: True>
[2025-03-10T10:40:29.163+0000] {logging_mixin.py:190} INFO - Failure caused by HTTPSConnectionPool(host='storage.googleapis.com', port=443): Max retries exceeded with url: /upload/storage/v1/b/tiki-pipeline/o?uploadType=multipart (Caused by NameResolutionError("<urllib3.connection.HTTPSConnection object at 0x7f8e6724e270>: Failed to resolve 'storage.googleapis.com' ([Errno -3] Temporary failure in name resolution)"))
[2025-03-10T10:40:29.164+0000] {taskinstance.py:1226} INFO - Marking task as UP_FOR_RETRY. dag_id=tiki_extract_dag, task_id=crawl_do-choi-me-be, run_id=manual__2025-03-10T10:33:29.927545+00:00, execution_date=20250310T103329, start_date=20250310T103853, end_date=20250310T104029
[2025-03-10T10:40:29.279+0000] {taskinstance.py:341} INFO - ::group::Post task execution logs
[2025-03-10T10:40:29.287+0000] {standard_task_runner.py:124} ERROR - Failed to execute job 460 for task crawl_do-choi-me-be (HTTPSConnectionPool(host='storage.googleapis.com', port=443): Max retries exceeded with url: /upload/storage/v1/b/tiki-pipeline/o?uploadType=multipart (Caused by NameResolutionError("<urllib3.connection.HTTPSConnection object at 0x7f8e6724e270>: Failed to resolve 'storage.googleapis.com' ([Errno -3] Temporary failure in name resolution)")); 213)
Traceback (most recent call last):
  File "/home/airflow/.local/lib/python3.12/site-packages/urllib3/connection.py", line 198, in _new_conn
    sock = connection.create_connection(
           ^^^^^^^^^^^^^^^^^^^^^^^^^^^^^
  File "/home/airflow/.local/lib/python3.12/site-packages/urllib3/util/connection.py", line 60, in create_connection
    for res in socket.getaddrinfo(host, port, family, socket.SOCK_STREAM):
               ^^^^^^^^^^^^^^^^^^^^^^^^^^^^^^^^^^^^^^^^^^^^^^^^^^^^^^^^^^
  File "/usr/local/lib/python3.12/socket.py", line 978, in getaddrinfo
    for res in _socket.getaddrinfo(host, port, family, type, proto, flags):
               ^^^^^^^^^^^^^^^^^^^^^^^^^^^^^^^^^^^^^^^^^^^^^^^^^^^^^^^^^^^
socket.gaierror: [Errno -3] Temporary failure in name resolution

The above exception was the direct cause of the following exception:

Traceback (most recent call last):
  File "/home/airflow/.local/lib/python3.12/site-packages/urllib3/connectionpool.py", line 787, in urlopen
    response = self._make_request(
               ^^^^^^^^^^^^^^^^^^^
  File "/home/airflow/.local/lib/python3.12/site-packages/urllib3/connectionpool.py", line 488, in _make_request
    raise new_e
  File "/home/airflow/.local/lib/python3.12/site-packages/urllib3/connectionpool.py", line 464, in _make_request
    self._validate_conn(conn)
  File "/home/airflow/.local/lib/python3.12/site-packages/urllib3/connectionpool.py", line 1093, in _validate_conn
    conn.connect()
  File "/home/airflow/.local/lib/python3.12/site-packages/urllib3/connection.py", line 704, in connect
    self.sock = sock = self._new_conn()
                       ^^^^^^^^^^^^^^^^
  File "/home/airflow/.local/lib/python3.12/site-packages/urllib3/connection.py", line 205, in _new_conn
    raise NameResolutionError(self.host, self, e) from e
urllib3.exceptions.NameResolutionError: <urllib3.connection.HTTPSConnection object at 0x7f8e6724e270>: Failed to resolve 'storage.googleapis.com' ([Errno -3] Temporary failure in name resolution)

The above exception was the direct cause of the following exception:

Traceback (most recent call last):
  File "/home/airflow/.local/lib/python3.12/site-packages/requests/adapters.py", line 667, in send
    resp = conn.urlopen(
           ^^^^^^^^^^^^^
  File "/home/airflow/.local/lib/python3.12/site-packages/urllib3/connectionpool.py", line 841, in urlopen
    retries = retries.increment(
              ^^^^^^^^^^^^^^^^^^
  File "/home/airflow/.local/lib/python3.12/site-packages/urllib3/util/retry.py", line 519, in increment
    raise MaxRetryError(_pool, url, reason) from reason  # type: ignore[arg-type]
    ^^^^^^^^^^^^^^^^^^^^^^^^^^^^^^^^^^^^^^^^^^^^^^^^^^^
urllib3.exceptions.MaxRetryError: HTTPSConnectionPool(host='storage.googleapis.com', port=443): Max retries exceeded with url: /upload/storage/v1/b/tiki-pipeline/o?uploadType=multipart (Caused by NameResolutionError("<urllib3.connection.HTTPSConnection object at 0x7f8e6724e270>: Failed to resolve 'storage.googleapis.com' ([Errno -3] Temporary failure in name resolution)"))

During handling of the above exception, another exception occurred:

Traceback (most recent call last):
  File "/home/airflow/.local/lib/python3.12/site-packages/airflow/task/task_runner/standard_task_runner.py", line 117, in _start_by_fork
    ret = args.func(args, dag=self.dag)
          ^^^^^^^^^^^^^^^^^^^^^^^^^^^^^
  File "/home/airflow/.local/lib/python3.12/site-packages/airflow/cli/cli_config.py", line 49, in command
    return func(*args, **kwargs)
           ^^^^^^^^^^^^^^^^^^^^^
  File "/home/airflow/.local/lib/python3.12/site-packages/airflow/utils/cli.py", line 116, in wrapper
    return f(*args, **kwargs)
           ^^^^^^^^^^^^^^^^^^
  File "/home/airflow/.local/lib/python3.12/site-packages/airflow/cli/commands/task_command.py", line 483, in task_run
    task_return_code = _run_task_by_selected_method(args, _dag, ti)
                       ^^^^^^^^^^^^^^^^^^^^^^^^^^^^^^^^^^^^^^^^^^^^
  File "/home/airflow/.local/lib/python3.12/site-packages/airflow/cli/commands/task_command.py", line 256, in _run_task_by_selected_method
    return _run_raw_task(args, ti)
           ^^^^^^^^^^^^^^^^^^^^^^^
  File "/home/airflow/.local/lib/python3.12/site-packages/airflow/cli/commands/task_command.py", line 341, in _run_raw_task
    return ti._run_raw_task(
           ^^^^^^^^^^^^^^^^^
  File "/home/airflow/.local/lib/python3.12/site-packages/airflow/utils/session.py", line 97, in wrapper
    return func(*args, session=session, **kwargs)
           ^^^^^^^^^^^^^^^^^^^^^^^^^^^^^^^^^^^^^^
  File "/home/airflow/.local/lib/python3.12/site-packages/airflow/models/taskinstance.py", line 3006, in _run_raw_task
    return _run_raw_task(
           ^^^^^^^^^^^^^^
  File "/home/airflow/.local/lib/python3.12/site-packages/airflow/models/taskinstance.py", line 274, in _run_raw_task
    TaskInstance._execute_task_with_callbacks(
  File "/home/airflow/.local/lib/python3.12/site-packages/airflow/models/taskinstance.py", line 3161, in _execute_task_with_callbacks
    result = self._execute_task(context, task_orig)
             ^^^^^^^^^^^^^^^^^^^^^^^^^^^^^^^^^^^^^^
  File "/home/airflow/.local/lib/python3.12/site-packages/airflow/models/taskinstance.py", line 3185, in _execute_task
    return _execute_task(self, context, task_orig)
           ^^^^^^^^^^^^^^^^^^^^^^^^^^^^^^^^^^^^^^^
  File "/home/airflow/.local/lib/python3.12/site-packages/airflow/models/taskinstance.py", line 768, in _execute_task
    result = _execute_callable(context=context, **execute_callable_kwargs)
             ^^^^^^^^^^^^^^^^^^^^^^^^^^^^^^^^^^^^^^^^^^^^^^^^^^^^^^^^^^^^^
  File "/home/airflow/.local/lib/python3.12/site-packages/airflow/models/taskinstance.py", line 734, in _execute_callable
    return ExecutionCallableRunner(
           ^^^^^^^^^^^^^^^^^^^^^^^^
  File "/home/airflow/.local/lib/python3.12/site-packages/airflow/utils/operator_helpers.py", line 252, in run
    return self.func(*args, **kwargs)
           ^^^^^^^^^^^^^^^^^^^^^^^^^^
  File "/home/airflow/.local/lib/python3.12/site-packages/airflow/models/baseoperator.py", line 424, in wrapper
    return func(self, *args, **kwargs)
           ^^^^^^^^^^^^^^^^^^^^^^^^^^^
  File "/home/airflow/.local/lib/python3.12/site-packages/airflow/operators/python.py", line 238, in execute
    return_value = self.execute_callable()
                   ^^^^^^^^^^^^^^^^^^^^^^^
  File "/home/airflow/.local/lib/python3.12/site-packages/airflow/operators/python.py", line 256, in execute_callable
    return runner.run(*self.op_args, **self.op_kwargs)
           ^^^^^^^^^^^^^^^^^^^^^^^^^^^^^^^^^^^^^^^^^^^
  File "/home/airflow/.local/lib/python3.12/site-packages/airflow/utils/operator_helpers.py", line 252, in run
    return self.func(*args, **kwargs)
           ^^^^^^^^^^^^^^^^^^^^^^^^^^
  File "/opt/airflow/dags/tiki_extract_dag.py", line 190, in crawl_category
    blob.upload_from_string(json.dumps(all_raw_data), content_type='application/json')
  File "/usr/local/lib/python3.12/contextlib.py", line 81, in inner
    return func(*args, **kwds)
           ^^^^^^^^^^^^^^^^^^^
  File "/home/airflow/.local/lib/python3.12/site-packages/google/cloud/storage/blob.py", line 3128, in upload_from_string
    self.upload_from_file(
  File "/usr/local/lib/python3.12/contextlib.py", line 81, in inner
    return func(*args, **kwds)
           ^^^^^^^^^^^^^^^^^^^
  File "/home/airflow/.local/lib/python3.12/site-packages/google/cloud/storage/blob.py", line 2851, in upload_from_file
    self._prep_and_do_upload(
  File "/home/airflow/.local/lib/python3.12/site-packages/google/cloud/storage/blob.py", line 2700, in _prep_and_do_upload
    created_json = self._do_upload(
                   ^^^^^^^^^^^^^^^^
  File "/home/airflow/.local/lib/python3.12/site-packages/google/cloud/storage/blob.py", line 2506, in _do_upload
    response = self._do_multipart_upload(
               ^^^^^^^^^^^^^^^^^^^^^^^^^^
  File "/home/airflow/.local/lib/python3.12/site-packages/google/cloud/storage/blob.py", line 2007, in _do_multipart_upload
    response = upload.transmit(
               ^^^^^^^^^^^^^^^^
  File "/home/airflow/.local/lib/python3.12/site-packages/google/resumable_media/requests/upload.py", line 153, in transmit
    return _request_helpers.wait_and_retry(
           ^^^^^^^^^^^^^^^^^^^^^^^^^^^^^^^^
  File "/home/airflow/.local/lib/python3.12/site-packages/google/resumable_media/requests/_request_helpers.py", line 178, in wait_and_retry
    raise error
  File "/home/airflow/.local/lib/python3.12/site-packages/google/resumable_media/requests/_request_helpers.py", line 155, in wait_and_retry
    response = func()
               ^^^^^^
  File "/home/airflow/.local/lib/python3.12/site-packages/google/resumable_media/requests/upload.py", line 145, in retriable_request
    result = transport.request(
             ^^^^^^^^^^^^^^^^^^
  File "/home/airflow/.local/lib/python3.12/site-packages/google/auth/transport/requests.py", line 537, in request
    response = super(AuthorizedSession, self).request(
               ^^^^^^^^^^^^^^^^^^^^^^^^^^^^^^^^^^^^^^^
  File "/home/airflow/.local/lib/python3.12/site-packages/requests/sessions.py", line 589, in request
    resp = self.send(prep, **send_kwargs)
           ^^^^^^^^^^^^^^^^^^^^^^^^^^^^^^
  File "/home/airflow/.local/lib/python3.12/site-packages/requests/sessions.py", line 703, in send
    r = adapter.send(request, **kwargs)
        ^^^^^^^^^^^^^^^^^^^^^^^^^^^^^^^
  File "/home/airflow/.local/lib/python3.12/site-packages/requests/adapters.py", line 700, in send
    raise ConnectionError(e, request=request)
requests.exceptions.ConnectionError: HTTPSConnectionPool(host='storage.googleapis.com', port=443): Max retries exceeded with url: /upload/storage/v1/b/tiki-pipeline/o?uploadType=multipart (Caused by NameResolutionError("<urllib3.connection.HTTPSConnection object at 0x7f8e6724e270>: Failed to resolve 'storage.googleapis.com' ([Errno -3] Temporary failure in name resolution)"))
[2025-03-10T10:40:29.446+0000] {local_task_job_runner.py:266} INFO - Task exited with return code 1
[2025-03-10T10:40:29.705+0000] {taskinstance.py:3901} INFO - 0 downstream tasks scheduled from follow-on schedule check
[2025-03-10T10:40:29.717+0000] {local_task_job_runner.py:245} INFO - ::endgroup::
