[2025-03-11T09:29:21.199+0000] {local_task_job_runner.py:123} INFO - ::group::Pre task execution logs
[2025-03-11T09:29:21.271+0000] {taskinstance.py:2614} INFO - Dependencies all met for dep_context=non-requeueable deps ti=<TaskInstance: tiki_extract_dag.crawl_laptop-may-vi-tinh-linh-kien manual__2025-03-11T08:53:49.647616+00:00 [queued]>
[2025-03-11T09:29:21.304+0000] {taskinstance.py:2614} INFO - Dependencies all met for dep_context=requeueable deps ti=<TaskInstance: tiki_extract_dag.crawl_laptop-may-vi-tinh-linh-kien manual__2025-03-11T08:53:49.647616+00:00 [queued]>
[2025-03-11T09:29:21.305+0000] {taskinstance.py:2867} INFO - Starting attempt 4 of 4
[2025-03-11T09:29:21.362+0000] {taskinstance.py:2890} INFO - Executing <Task(PythonOperator): crawl_laptop-may-vi-tinh-linh-kien> on 2025-03-11 08:53:49.647616+00:00
[2025-03-11T09:29:21.384+0000] {warnings.py:112} WARNING - /home/***/.local/lib/python3.12/site-packages/***/task/task_runner/standard_task_runner.py:70: DeprecationWarning: This process (pid=511) is multi-threaded, use of fork() may lead to deadlocks in the child.
  pid = os.fork()

[2025-03-11T09:29:21.390+0000] {standard_task_runner.py:72} INFO - Started process 527 to run task
[2025-03-11T09:29:21.411+0000] {standard_task_runner.py:104} INFO - Running: ['***', 'tasks', 'run', 'tiki_extract_dag', 'crawl_laptop-may-vi-tinh-linh-kien', 'manual__2025-03-11T08:53:49.647616+00:00', '--job-id', '570', '--raw', '--subdir', 'DAGS_FOLDER/tiki_extract_dag.py', '--cfg-path', '/tmp/tmptal7q78h']
[2025-03-11T09:29:21.418+0000] {standard_task_runner.py:105} INFO - Job 570: Subtask crawl_laptop-may-vi-tinh-linh-kien
[2025-03-11T09:29:21.702+0000] {task_command.py:467} INFO - Running <TaskInstance: tiki_extract_dag.crawl_laptop-may-vi-tinh-linh-kien manual__2025-03-11T08:53:49.647616+00:00 [running]> on host 5c8190d7da62
[2025-03-11T09:29:28.768+0000] {taskinstance.py:3134} INFO - Exporting env vars: AIRFLOW_CTX_DAG_OWNER='***' AIRFLOW_CTX_DAG_ID='tiki_extract_dag' AIRFLOW_CTX_TASK_ID='crawl_laptop-may-vi-tinh-linh-kien' AIRFLOW_CTX_EXECUTION_DATE='2025-03-11T08:53:49.647616+00:00' AIRFLOW_CTX_TRY_NUMBER='4' AIRFLOW_CTX_DAG_RUN_ID='manual__2025-03-11T08:53:49.647616+00:00'
[2025-03-11T09:29:28.856+0000] {logging_mixin.py:190} INFO - Task instance is in running state
[2025-03-11T09:29:28.930+0000] {logging_mixin.py:190} INFO -  Previous state of the Task instance: queued
[2025-03-11T09:29:29.187+0000] {logging_mixin.py:190} INFO - Current task name:crawl_laptop-may-vi-tinh-linh-kien state:running start_date:2025-03-11 09:29:21.274173+00:00
[2025-03-11T09:29:29.445+0000] {logging_mixin.py:190} INFO - Dag name:tiki_extract_dag and current dag run status:running
[2025-03-11T09:29:29.889+0000] {taskinstance.py:732} INFO - ::endgroup::
[2025-03-11T09:29:53.768+0000] {job.py:229} INFO - Heartbeat recovered after 33.04 seconds
[2025-03-11T09:29:56.529+0000] {tiki_extract_dag.py:139} INFO - Starting crawl for category laptop-may-vi-tinh-linh-kien (ID: 1846)
[2025-03-11T09:29:56.530+0000] {tiki_extract_dag.py:141} INFO - Calling API: https://tiki.vn/api/v2/products with params: {'page': 1, 'limit': 40, 'category': '1846'}
[2025-03-11T09:29:57.014+0000] {tiki_extract_dag.py:150} INFO - Total pages for laptop-may-vi-tinh-linh-kien: 50 (limited to 50)
[2025-03-11T09:30:32.785+0000] {connectionpool.py:868} WARNING - Retrying (Retry(total=4, connect=5, read=4, redirect=None, status=None)) after connection broken by 'ReadTimeoutError("HTTPSConnectionPool(host='tiki.vn', port=443): Read timed out. (read timeout=15)")': /api/v2/products/76181490
[2025-03-11T09:30:40.168+0000] {job.py:229} INFO - Heartbeat recovered after 35.55 seconds
[2025-03-11T09:30:46.017+0000] {tiki_extract_dag.py:163} INFO - Calling API: https://tiki.vn/api/v2/products with params: {'page': 2, 'limit': 40, 'category': '1846'}
[2025-03-11T09:30:58.881+0000] {tiki_extract_dag.py:183} INFO - Extracted page 2/50 for category laptop-may-vi-tinh-linh-kien, total items: 80
[2025-03-11T09:31:13.910+0000] {tiki_extract_dag.py:163} INFO - Calling API: https://tiki.vn/api/v2/products with params: {'page': 3, 'limit': 40, 'category': '1846'}
[2025-03-11T09:31:27.309+0000] {tiki_extract_dag.py:183} INFO - Extracted page 3/50 for category laptop-may-vi-tinh-linh-kien, total items: 120
[2025-03-11T09:31:46.594+0000] {tiki_extract_dag.py:163} INFO - Calling API: https://tiki.vn/api/v2/products with params: {'page': 4, 'limit': 40, 'category': '1846'}
[2025-03-11T09:32:20.985+0000] {connectionpool.py:868} WARNING - Retrying (Retry(total=4, connect=5, read=4, redirect=None, status=None)) after connection broken by 'ReadTimeoutError("HTTPSConnectionPool(host='tiki.vn', port=443): Read timed out. (read timeout=15)")': /api/v2/products?page=4&limit=40&category=1846
[2025-03-11T09:32:32.869+0000] {job.py:229} INFO - Heartbeat recovered after 61.67 seconds
[2025-03-11T09:32:45.748+0000] {tiki_extract_dag.py:183} INFO - Extracted page 4/50 for category laptop-may-vi-tinh-linh-kien, total items: 160
[2025-03-11T09:33:01.754+0000] {tiki_extract_dag.py:163} INFO - Calling API: https://tiki.vn/api/v2/products with params: {'page': 5, 'limit': 40, 'category': '1846'}
[2025-03-11T09:33:14.067+0000] {tiki_extract_dag.py:183} INFO - Extracted page 5/50 for category laptop-may-vi-tinh-linh-kien, total items: 200
[2025-03-11T09:33:29.956+0000] {tiki_extract_dag.py:163} INFO - Calling API: https://tiki.vn/api/v2/products with params: {'page': 6, 'limit': 40, 'category': '1846'}
[2025-03-11T09:33:42.879+0000] {tiki_extract_dag.py:183} INFO - Extracted page 6/50 for category laptop-may-vi-tinh-linh-kien, total items: 240
[2025-03-11T09:33:58.225+0000] {tiki_extract_dag.py:163} INFO - Calling API: https://tiki.vn/api/v2/products with params: {'page': 7, 'limit': 40, 'category': '1846'}
[2025-03-11T09:34:13.008+0000] {tiki_extract_dag.py:183} INFO - Extracted page 7/50 for category laptop-may-vi-tinh-linh-kien, total items: 280
[2025-03-11T09:34:32.017+0000] {tiki_extract_dag.py:163} INFO - Calling API: https://tiki.vn/api/v2/products with params: {'page': 8, 'limit': 40, 'category': '1846'}
[2025-03-11T09:35:11.073+0000] {connectionpool.py:868} WARNING - Retrying (Retry(total=4, connect=5, read=4, redirect=None, status=None)) after connection broken by 'ReadTimeoutError("HTTPSConnectionPool(host='tiki.vn', port=443): Read timed out. (read timeout=15)")': /api/v2/products/8018484
[2025-03-11T09:35:53.891+0000] {connectionpool.py:868} WARNING - Retrying (Retry(total=3, connect=4, read=4, redirect=None, status=None)) after connection broken by 'NameResolutionError("<urllib3.connection.HTTPSConnection object at 0x7f729b97e240>: Failed to resolve 'tiki.vn' ([Errno -3] Temporary failure in name resolution)")': /api/v2/products/8018484
[2025-03-11T09:36:05.844+0000] {job.py:239} ERROR - Job heartbeat failed with error
Traceback (most recent call last):
  File "/home/airflow/.local/lib/python3.12/site-packages/sqlalchemy/engine/base.py", line 3371, in _wrap_pool_connect
    return fn()
           ^^^^
  File "/home/airflow/.local/lib/python3.12/site-packages/sqlalchemy/pool/base.py", line 327, in connect
    return _ConnectionFairy._checkout(self)
           ^^^^^^^^^^^^^^^^^^^^^^^^^^^^^^^^
  File "/home/airflow/.local/lib/python3.12/site-packages/sqlalchemy/pool/base.py", line 894, in _checkout
    fairy = _ConnectionRecord.checkout(pool)
            ^^^^^^^^^^^^^^^^^^^^^^^^^^^^^^^^
  File "/home/airflow/.local/lib/python3.12/site-packages/sqlalchemy/pool/base.py", line 493, in checkout
    rec = pool._do_get()
          ^^^^^^^^^^^^^^
  File "/home/airflow/.local/lib/python3.12/site-packages/sqlalchemy/pool/impl.py", line 256, in _do_get
    return self._create_connection()
           ^^^^^^^^^^^^^^^^^^^^^^^^^
  File "/home/airflow/.local/lib/python3.12/site-packages/sqlalchemy/pool/base.py", line 273, in _create_connection
    return _ConnectionRecord(self)
           ^^^^^^^^^^^^^^^^^^^^^^^
  File "/home/airflow/.local/lib/python3.12/site-packages/sqlalchemy/pool/base.py", line 388, in __init__
    self.__connect()
  File "/home/airflow/.local/lib/python3.12/site-packages/sqlalchemy/pool/base.py", line 690, in __connect
    with util.safe_reraise():
         ^^^^^^^^^^^^^^^^^^^
  File "/home/airflow/.local/lib/python3.12/site-packages/sqlalchemy/util/langhelpers.py", line 70, in __exit__
    compat.raise_(
  File "/home/airflow/.local/lib/python3.12/site-packages/sqlalchemy/util/compat.py", line 211, in raise_
    raise exception
  File "/home/airflow/.local/lib/python3.12/site-packages/sqlalchemy/pool/base.py", line 686, in __connect
    self.dbapi_connection = connection = pool._invoke_creator(self)
                                         ^^^^^^^^^^^^^^^^^^^^^^^^^^
  File "/home/airflow/.local/lib/python3.12/site-packages/sqlalchemy/engine/create.py", line 574, in connect
    return dialect.connect(*cargs, **cparams)
           ^^^^^^^^^^^^^^^^^^^^^^^^^^^^^^^^^^
  File "/home/airflow/.local/lib/python3.12/site-packages/sqlalchemy/engine/default.py", line 598, in connect
    return self.dbapi.connect(*cargs, **cparams)
           ^^^^^^^^^^^^^^^^^^^^^^^^^^^^^^^^^^^^^
  File "/home/airflow/.local/lib/python3.12/site-packages/psycopg2/__init__.py", line 122, in connect
    conn = _connect(dsn, connection_factory=connection_factory, **kwasync)
           ^^^^^^^^^^^^^^^^^^^^^^^^^^^^^^^^^^^^^^^^^^^^^^^^^^^^^^^^^^^^^^^
psycopg2.OperationalError: could not translate host name "postgres" to address: Temporary failure in name resolution


The above exception was the direct cause of the following exception:

Traceback (most recent call last):
  File "/home/airflow/.local/lib/python3.12/site-packages/airflow/jobs/job.py", line 207, in heartbeat
    self._merge_from(Job._fetch_from_db(self, session))
                     ^^^^^^^^^^^^^^^^^^^^^^^^^^^^^^^^^
  File "/home/airflow/.local/lib/python3.12/site-packages/airflow/api_internal/internal_api_call.py", line 166, in wrapper
    return func(*args, **kwargs)
           ^^^^^^^^^^^^^^^^^^^^^
  File "/home/airflow/.local/lib/python3.12/site-packages/airflow/utils/session.py", line 94, in wrapper
    return func(*args, **kwargs)
           ^^^^^^^^^^^^^^^^^^^^^
  File "/home/airflow/.local/lib/python3.12/site-packages/airflow/utils/retries.py", line 93, in wrapped_function
    for attempt in run_with_db_retries(max_retries=retries, logger=logger, **retry_kwargs):
                   ^^^^^^^^^^^^^^^^^^^^^^^^^^^^^^^^^^^^^^^^^^^^^^^^^^^^^^^^^^^^^^^^^^^^^^^
  File "/home/airflow/.local/lib/python3.12/site-packages/tenacity/__init__.py", line 443, in __iter__
    do = self.iter(retry_state=retry_state)
         ^^^^^^^^^^^^^^^^^^^^^^^^^^^^^^^^^^
  File "/home/airflow/.local/lib/python3.12/site-packages/tenacity/__init__.py", line 376, in iter
    result = action(retry_state)
             ^^^^^^^^^^^^^^^^^^^
  File "/home/airflow/.local/lib/python3.12/site-packages/tenacity/__init__.py", line 418, in exc_check
    raise retry_exc.reraise()
          ^^^^^^^^^^^^^^^^^^^
  File "/home/airflow/.local/lib/python3.12/site-packages/tenacity/__init__.py", line 185, in reraise
    raise self.last_attempt.result()
          ^^^^^^^^^^^^^^^^^^^^^^^^^^
  File "/usr/local/lib/python3.12/concurrent/futures/_base.py", line 449, in result
    return self.__get_result()
           ^^^^^^^^^^^^^^^^^^^
  File "/usr/local/lib/python3.12/concurrent/futures/_base.py", line 401, in __get_result
    raise self._exception
  File "/home/airflow/.local/lib/python3.12/site-packages/airflow/utils/retries.py", line 102, in wrapped_function
    return func(*args, **kwargs)
           ^^^^^^^^^^^^^^^^^^^^^
  File "/home/airflow/.local/lib/python3.12/site-packages/airflow/jobs/job.py", line 335, in _fetch_from_db
    session.merge(job)
  File "/home/airflow/.local/lib/python3.12/site-packages/sqlalchemy/orm/session.py", line 3056, in merge
    return self._merge(
           ^^^^^^^^^^^^
  File "/home/airflow/.local/lib/python3.12/site-packages/sqlalchemy/orm/session.py", line 3136, in _merge
    merged = self.get(
             ^^^^^^^^^
  File "/home/airflow/.local/lib/python3.12/site-packages/sqlalchemy/orm/session.py", line 2853, in get
    return self._get_impl(
           ^^^^^^^^^^^^^^^
  File "/home/airflow/.local/lib/python3.12/site-packages/sqlalchemy/orm/session.py", line 2975, in _get_impl
    return db_load_fn(
           ^^^^^^^^^^^
  File "/home/airflow/.local/lib/python3.12/site-packages/sqlalchemy/orm/loading.py", line 530, in load_on_pk_identity
    session.execute(
  File "/home/airflow/.local/lib/python3.12/site-packages/sqlalchemy/orm/session.py", line 1716, in execute
    conn = self._connection_for_bind(bind)
           ^^^^^^^^^^^^^^^^^^^^^^^^^^^^^^^
  File "/home/airflow/.local/lib/python3.12/site-packages/sqlalchemy/orm/session.py", line 1555, in _connection_for_bind
    return self._transaction._connection_for_bind(
           ^^^^^^^^^^^^^^^^^^^^^^^^^^^^^^^^^^^^^^^
  File "/home/airflow/.local/lib/python3.12/site-packages/sqlalchemy/orm/session.py", line 750, in _connection_for_bind
    conn = bind.connect()
           ^^^^^^^^^^^^^^
  File "/home/airflow/.local/lib/python3.12/site-packages/sqlalchemy/future/engine.py", line 412, in connect
    return super(Engine, self).connect()
           ^^^^^^^^^^^^^^^^^^^^^^^^^^^^^
  File "/home/airflow/.local/lib/python3.12/site-packages/sqlalchemy/engine/base.py", line 3325, in connect
    return self._connection_cls(self, close_with_result=close_with_result)
           ^^^^^^^^^^^^^^^^^^^^^^^^^^^^^^^^^^^^^^^^^^^^^^^^^^^^^^^^^^^^^^^
  File "/home/airflow/.local/lib/python3.12/site-packages/sqlalchemy/engine/base.py", line 96, in __init__
    else engine.raw_connection()
         ^^^^^^^^^^^^^^^^^^^^^^^
  File "/home/airflow/.local/lib/python3.12/site-packages/sqlalchemy/engine/base.py", line 3404, in raw_connection
    return self._wrap_pool_connect(self.pool.connect, _connection)
           ^^^^^^^^^^^^^^^^^^^^^^^^^^^^^^^^^^^^^^^^^^^^^^^^^^^^^^^
  File "/home/airflow/.local/lib/python3.12/site-packages/sqlalchemy/engine/base.py", line 3374, in _wrap_pool_connect
    Connection._handle_dbapi_exception_noconnection(
  File "/home/airflow/.local/lib/python3.12/site-packages/sqlalchemy/engine/base.py", line 2208, in _handle_dbapi_exception_noconnection
    util.raise_(
  File "/home/airflow/.local/lib/python3.12/site-packages/sqlalchemy/util/compat.py", line 211, in raise_
    raise exception
  File "/home/airflow/.local/lib/python3.12/site-packages/sqlalchemy/engine/base.py", line 3371, in _wrap_pool_connect
    return fn()
           ^^^^
  File "/home/airflow/.local/lib/python3.12/site-packages/sqlalchemy/pool/base.py", line 327, in connect
    return _ConnectionFairy._checkout(self)
           ^^^^^^^^^^^^^^^^^^^^^^^^^^^^^^^^
  File "/home/airflow/.local/lib/python3.12/site-packages/sqlalchemy/pool/base.py", line 894, in _checkout
    fairy = _ConnectionRecord.checkout(pool)
            ^^^^^^^^^^^^^^^^^^^^^^^^^^^^^^^^
  File "/home/airflow/.local/lib/python3.12/site-packages/sqlalchemy/pool/base.py", line 493, in checkout
    rec = pool._do_get()
          ^^^^^^^^^^^^^^
  File "/home/airflow/.local/lib/python3.12/site-packages/sqlalchemy/pool/impl.py", line 256, in _do_get
    return self._create_connection()
           ^^^^^^^^^^^^^^^^^^^^^^^^^
  File "/home/airflow/.local/lib/python3.12/site-packages/sqlalchemy/pool/base.py", line 273, in _create_connection
    return _ConnectionRecord(self)
           ^^^^^^^^^^^^^^^^^^^^^^^
  File "/home/airflow/.local/lib/python3.12/site-packages/sqlalchemy/pool/base.py", line 388, in __init__
    self.__connect()
  File "/home/airflow/.local/lib/python3.12/site-packages/sqlalchemy/pool/base.py", line 690, in __connect
    with util.safe_reraise():
         ^^^^^^^^^^^^^^^^^^^
  File "/home/airflow/.local/lib/python3.12/site-packages/sqlalchemy/util/langhelpers.py", line 70, in __exit__
    compat.raise_(
  File "/home/airflow/.local/lib/python3.12/site-packages/sqlalchemy/util/compat.py", line 211, in raise_
    raise exception
  File "/home/airflow/.local/lib/python3.12/site-packages/sqlalchemy/pool/base.py", line 686, in __connect
    self.dbapi_connection = connection = pool._invoke_creator(self)
                                         ^^^^^^^^^^^^^^^^^^^^^^^^^^
  File "/home/airflow/.local/lib/python3.12/site-packages/sqlalchemy/engine/create.py", line 574, in connect
    return dialect.connect(*cargs, **cparams)
           ^^^^^^^^^^^^^^^^^^^^^^^^^^^^^^^^^^
  File "/home/airflow/.local/lib/python3.12/site-packages/sqlalchemy/engine/default.py", line 598, in connect
    return self.dbapi.connect(*cargs, **cparams)
           ^^^^^^^^^^^^^^^^^^^^^^^^^^^^^^^^^^^^^
  File "/home/airflow/.local/lib/python3.12/site-packages/psycopg2/__init__.py", line 122, in connect
    conn = _connect(dsn, connection_factory=connection_factory, **kwasync)
           ^^^^^^^^^^^^^^^^^^^^^^^^^^^^^^^^^^^^^^^^^^^^^^^^^^^^^^^^^^^^^^^
sqlalchemy.exc.OperationalError: (psycopg2.OperationalError) could not translate host name "postgres" to address: Temporary failure in name resolution

(Background on this error at: https://sqlalche.me/e/14/e3q8)
[2025-03-11T09:36:06.244+0000] {job.py:254} ERROR - Job heartbeat failed with error. Scheduler is in unhealthy state
[2025-03-11T09:36:13.058+0000] {tiki_extract_dag.py:183} INFO - Extracted page 8/50 for category laptop-may-vi-tinh-linh-kien, total items: 320
[2025-03-11T09:36:13.441+0000] {job.py:229} INFO - Heartbeat recovered after 92.99 seconds
[2025-03-11T09:36:24.126+0000] {local_task_job_runner.py:266} INFO - Task exited with return code -9. For more information, see https://***.apache.org/docs/apache-***/stable/troubleshooting.html#LocalTaskJob-killed
[2025-03-11T09:36:24.833+0000] {taskinstance.py:3901} INFO - 0 downstream tasks scheduled from follow-on schedule check
[2025-03-11T09:36:24.882+0000] {local_task_job_runner.py:245} INFO - ::endgroup::
