[2025-03-11T09:36:13.690+0000] {local_task_job_runner.py:123} INFO - ::group::Pre task execution logs
[2025-03-11T09:36:13.923+0000] {taskinstance.py:2614} INFO - Dependencies all met for dep_context=non-requeueable deps ti=<TaskInstance: tiki_extract_dag.crawl_dien-thoai-may-tinh-bang manual__2025-03-11T08:53:49.647616+00:00 [queued]>
[2025-03-11T09:36:14.089+0000] {taskinstance.py:2614} INFO - Dependencies all met for dep_context=requeueable deps ti=<TaskInstance: tiki_extract_dag.crawl_dien-thoai-may-tinh-bang manual__2025-03-11T08:53:49.647616+00:00 [queued]>
[2025-03-11T09:36:14.091+0000] {taskinstance.py:2867} INFO - Starting attempt 4 of 4
[2025-03-11T09:36:14.341+0000] {taskinstance.py:2890} INFO - Executing <Task(PythonOperator): crawl_dien-thoai-may-tinh-bang> on 2025-03-11 08:53:49.647616+00:00
[2025-03-11T09:36:14.398+0000] {warnings.py:112} WARNING - /home/***/.local/lib/python3.12/site-packages/***/task/task_runner/standard_task_runner.py:70: DeprecationWarning: This process (pid=572) is multi-threaded, use of fork() may lead to deadlocks in the child.
  pid = os.fork()

[2025-03-11T09:36:14.404+0000] {standard_task_runner.py:104} INFO - Running: ['***', 'tasks', 'run', 'tiki_extract_dag', 'crawl_dien-thoai-may-tinh-bang', 'manual__2025-03-11T08:53:49.647616+00:00', '--job-id', '574', '--raw', '--subdir', 'DAGS_FOLDER/tiki_extract_dag.py', '--cfg-path', '/tmp/tmpwz_t243e']
[2025-03-11T09:36:14.431+0000] {standard_task_runner.py:105} INFO - Job 574: Subtask crawl_dien-thoai-may-tinh-bang
[2025-03-11T09:36:14.420+0000] {standard_task_runner.py:72} INFO - Started process 583 to run task
[2025-03-11T09:36:14.815+0000] {task_command.py:467} INFO - Running <TaskInstance: tiki_extract_dag.crawl_dien-thoai-may-tinh-bang manual__2025-03-11T08:53:49.647616+00:00 [running]> on host 5c8190d7da62
[2025-03-11T09:36:15.436+0000] {taskinstance.py:3134} INFO - Exporting env vars: AIRFLOW_CTX_DAG_OWNER='***' AIRFLOW_CTX_DAG_ID='tiki_extract_dag' AIRFLOW_CTX_TASK_ID='crawl_dien-thoai-may-tinh-bang' AIRFLOW_CTX_EXECUTION_DATE='2025-03-11T08:53:49.647616+00:00' AIRFLOW_CTX_TRY_NUMBER='4' AIRFLOW_CTX_DAG_RUN_ID='manual__2025-03-11T08:53:49.647616+00:00'
[2025-03-11T09:36:15.439+0000] {logging_mixin.py:190} INFO - Task instance is in running state
[2025-03-11T09:36:15.440+0000] {logging_mixin.py:190} INFO -  Previous state of the Task instance: queued
[2025-03-11T09:36:15.441+0000] {logging_mixin.py:190} INFO - Current task name:crawl_dien-thoai-may-tinh-bang state:running start_date:2025-03-11 09:36:13.940921+00:00
[2025-03-11T09:36:15.443+0000] {logging_mixin.py:190} INFO - Dag name:tiki_extract_dag and current dag run status:running
[2025-03-11T09:36:15.444+0000] {taskinstance.py:732} INFO - ::endgroup::
[2025-03-11T09:36:23.415+0000] {job.py:229} INFO - Heartbeat recovered after 14.71 seconds
[2025-03-11T09:36:26.801+0000] {tiki_extract_dag.py:139} INFO - Starting crawl for category dien-thoai-may-tinh-bang (ID: 1789)
[2025-03-11T09:36:26.807+0000] {tiki_extract_dag.py:141} INFO - Calling API: https://tiki.vn/api/v2/products with params: {'page': 1, 'limit': 40, 'category': '1789'}
[2025-03-11T09:36:27.758+0000] {tiki_extract_dag.py:150} INFO - Total pages for dien-thoai-may-tinh-bang: 10 (limited to 50)
[2025-03-11T09:36:39.958+0000] {tiki_extract_dag.py:163} INFO - Calling API: https://tiki.vn/api/v2/products with params: {'page': 2, 'limit': 40, 'category': '1789'}
[2025-03-11T09:36:52.543+0000] {tiki_extract_dag.py:183} INFO - Extracted page 2/10 for category dien-thoai-may-tinh-bang, total items: 80
[2025-03-11T09:37:08.065+0000] {tiki_extract_dag.py:163} INFO - Calling API: https://tiki.vn/api/v2/products with params: {'page': 3, 'limit': 40, 'category': '1789'}
[2025-03-11T09:37:21.873+0000] {tiki_extract_dag.py:120} ERROR - Error fetching details for product 160450655 on attempt 1/3: Expecting value: line 1 column 1 (char 0)
[2025-03-11T09:37:27.291+0000] {tiki_extract_dag.py:183} INFO - Extracted page 3/10 for category dien-thoai-may-tinh-bang, total items: 120
[2025-03-11T09:37:42.892+0000] {tiki_extract_dag.py:163} INFO - Calling API: https://tiki.vn/api/v2/products with params: {'page': 4, 'limit': 40, 'category': '1789'}
[2025-03-11T09:37:55.308+0000] {tiki_extract_dag.py:183} INFO - Extracted page 4/10 for category dien-thoai-may-tinh-bang, total items: 160
[2025-03-11T09:38:13.905+0000] {tiki_extract_dag.py:163} INFO - Calling API: https://tiki.vn/api/v2/products with params: {'page': 5, 'limit': 40, 'category': '1789'}
[2025-03-11T09:38:44.039+0000] {connectionpool.py:868} WARNING - Retrying (Retry(total=4, connect=5, read=4, redirect=None, status=None)) after connection broken by 'ReadTimeoutError("HTTPSConnectionPool(host='tiki.vn', port=443): Read timed out. (read timeout=15)")': /api/v2/products/276146274
[2025-03-11T09:39:35.878+0000] {connectionpool.py:868} WARNING - Retrying (Retry(total=3, connect=4, read=4, redirect=None, status=None)) after connection broken by 'NameResolutionError("<urllib3.connection.HTTPSConnection object at 0x7f729bca3410>: Failed to resolve 'tiki.vn' ([Errno -3] Temporary failure in name resolution)")': /api/v2/products/276146274
[2025-03-11T09:40:04.769+0000] {job.py:229} INFO - Heartbeat recovered after 113.75 seconds
[2025-03-11T09:40:21.831+0000] {tiki_extract_dag.py:183} INFO - Extracted page 5/10 for category dien-thoai-may-tinh-bang, total items: 200
[2025-03-11T09:40:39.507+0000] {tiki_extract_dag.py:163} INFO - Calling API: https://tiki.vn/api/v2/products with params: {'page': 6, 'limit': 40, 'category': '1789'}
[2025-03-11T09:41:09.976+0000] {connectionpool.py:868} WARNING - Retrying (Retry(total=4, connect=5, read=4, redirect=None, status=None)) after connection broken by 'ReadTimeoutError("HTTPSConnectionPool(host='tiki.vn', port=443): Read timed out. (read timeout=15)")': /api/v2/products/248929458
[2025-03-11T09:42:01.405+0000] {connectionpool.py:868} WARNING - Retrying (Retry(total=3, connect=4, read=4, redirect=None, status=None)) after connection broken by 'NameResolutionError("<urllib3.connection.HTTPSConnection object at 0x7f729bc9db80>: Failed to resolve 'tiki.vn' ([Errno -3] Temporary failure in name resolution)")': /api/v2/products/248929458
[2025-03-11T09:42:55.698+0000] {job.py:239} ERROR - Job heartbeat failed with error
Traceback (most recent call last):
  File "/home/airflow/.local/lib/python3.12/site-packages/sqlalchemy/engine/base.py", line 3371, in _wrap_pool_connect
    return fn()
           ^^^^
  File "/home/airflow/.local/lib/python3.12/site-packages/sqlalchemy/pool/base.py", line 327, in connect
    return _ConnectionFairy._checkout(self)
           ^^^^^^^^^^^^^^^^^^^^^^^^^^^^^^^^
  File "/home/airflow/.local/lib/python3.12/site-packages/sqlalchemy/pool/base.py", line 894, in _checkout
    fairy = _ConnectionRecord.checkout(pool)
            ^^^^^^^^^^^^^^^^^^^^^^^^^^^^^^^^
  File "/home/airflow/.local/lib/python3.12/site-packages/sqlalchemy/pool/base.py", line 493, in checkout
    rec = pool._do_get()
          ^^^^^^^^^^^^^^
  File "/home/airflow/.local/lib/python3.12/site-packages/sqlalchemy/pool/impl.py", line 256, in _do_get
    return self._create_connection()
           ^^^^^^^^^^^^^^^^^^^^^^^^^
  File "/home/airflow/.local/lib/python3.12/site-packages/sqlalchemy/pool/base.py", line 273, in _create_connection
    return _ConnectionRecord(self)
           ^^^^^^^^^^^^^^^^^^^^^^^
  File "/home/airflow/.local/lib/python3.12/site-packages/sqlalchemy/pool/base.py", line 388, in __init__
    self.__connect()
  File "/home/airflow/.local/lib/python3.12/site-packages/sqlalchemy/pool/base.py", line 690, in __connect
    with util.safe_reraise():
         ^^^^^^^^^^^^^^^^^^^
  File "/home/airflow/.local/lib/python3.12/site-packages/sqlalchemy/util/langhelpers.py", line 70, in __exit__
    compat.raise_(
  File "/home/airflow/.local/lib/python3.12/site-packages/sqlalchemy/util/compat.py", line 211, in raise_
    raise exception
  File "/home/airflow/.local/lib/python3.12/site-packages/sqlalchemy/pool/base.py", line 686, in __connect
    self.dbapi_connection = connection = pool._invoke_creator(self)
                                         ^^^^^^^^^^^^^^^^^^^^^^^^^^
  File "/home/airflow/.local/lib/python3.12/site-packages/sqlalchemy/engine/create.py", line 574, in connect
    return dialect.connect(*cargs, **cparams)
           ^^^^^^^^^^^^^^^^^^^^^^^^^^^^^^^^^^
  File "/home/airflow/.local/lib/python3.12/site-packages/sqlalchemy/engine/default.py", line 598, in connect
    return self.dbapi.connect(*cargs, **cparams)
           ^^^^^^^^^^^^^^^^^^^^^^^^^^^^^^^^^^^^^
  File "/home/airflow/.local/lib/python3.12/site-packages/psycopg2/__init__.py", line 122, in connect
    conn = _connect(dsn, connection_factory=connection_factory, **kwasync)
           ^^^^^^^^^^^^^^^^^^^^^^^^^^^^^^^^^^^^^^^^^^^^^^^^^^^^^^^^^^^^^^^
psycopg2.OperationalError: could not translate host name "postgres" to address: Temporary failure in name resolution


The above exception was the direct cause of the following exception:

Traceback (most recent call last):
  File "/home/airflow/.local/lib/python3.12/site-packages/airflow/jobs/job.py", line 207, in heartbeat
    self._merge_from(Job._fetch_from_db(self, session))
                     ^^^^^^^^^^^^^^^^^^^^^^^^^^^^^^^^^
  File "/home/airflow/.local/lib/python3.12/site-packages/airflow/api_internal/internal_api_call.py", line 166, in wrapper
    return func(*args, **kwargs)
           ^^^^^^^^^^^^^^^^^^^^^
  File "/home/airflow/.local/lib/python3.12/site-packages/airflow/utils/session.py", line 94, in wrapper
    return func(*args, **kwargs)
           ^^^^^^^^^^^^^^^^^^^^^
  File "/home/airflow/.local/lib/python3.12/site-packages/airflow/utils/retries.py", line 93, in wrapped_function
    for attempt in run_with_db_retries(max_retries=retries, logger=logger, **retry_kwargs):
                   ^^^^^^^^^^^^^^^^^^^^^^^^^^^^^^^^^^^^^^^^^^^^^^^^^^^^^^^^^^^^^^^^^^^^^^^
  File "/home/airflow/.local/lib/python3.12/site-packages/tenacity/__init__.py", line 443, in __iter__
    do = self.iter(retry_state=retry_state)
         ^^^^^^^^^^^^^^^^^^^^^^^^^^^^^^^^^^
  File "/home/airflow/.local/lib/python3.12/site-packages/tenacity/__init__.py", line 376, in iter
    result = action(retry_state)
             ^^^^^^^^^^^^^^^^^^^
  File "/home/airflow/.local/lib/python3.12/site-packages/tenacity/__init__.py", line 418, in exc_check
    raise retry_exc.reraise()
          ^^^^^^^^^^^^^^^^^^^
  File "/home/airflow/.local/lib/python3.12/site-packages/tenacity/__init__.py", line 185, in reraise
    raise self.last_attempt.result()
          ^^^^^^^^^^^^^^^^^^^^^^^^^^
  File "/usr/local/lib/python3.12/concurrent/futures/_base.py", line 449, in result
    return self.__get_result()
           ^^^^^^^^^^^^^^^^^^^
  File "/usr/local/lib/python3.12/concurrent/futures/_base.py", line 401, in __get_result
    raise self._exception
  File "/home/airflow/.local/lib/python3.12/site-packages/airflow/utils/retries.py", line 102, in wrapped_function
    return func(*args, **kwargs)
           ^^^^^^^^^^^^^^^^^^^^^
  File "/home/airflow/.local/lib/python3.12/site-packages/airflow/jobs/job.py", line 335, in _fetch_from_db
    session.merge(job)
  File "/home/airflow/.local/lib/python3.12/site-packages/sqlalchemy/orm/session.py", line 3056, in merge
    return self._merge(
           ^^^^^^^^^^^^
  File "/home/airflow/.local/lib/python3.12/site-packages/sqlalchemy/orm/session.py", line 3136, in _merge
    merged = self.get(
             ^^^^^^^^^
  File "/home/airflow/.local/lib/python3.12/site-packages/sqlalchemy/orm/session.py", line 2853, in get
    return self._get_impl(
           ^^^^^^^^^^^^^^^
  File "/home/airflow/.local/lib/python3.12/site-packages/sqlalchemy/orm/session.py", line 2975, in _get_impl
    return db_load_fn(
           ^^^^^^^^^^^
  File "/home/airflow/.local/lib/python3.12/site-packages/sqlalchemy/orm/loading.py", line 530, in load_on_pk_identity
    session.execute(
  File "/home/airflow/.local/lib/python3.12/site-packages/sqlalchemy/orm/session.py", line 1716, in execute
    conn = self._connection_for_bind(bind)
           ^^^^^^^^^^^^^^^^^^^^^^^^^^^^^^^
  File "/home/airflow/.local/lib/python3.12/site-packages/sqlalchemy/orm/session.py", line 1555, in _connection_for_bind
    return self._transaction._connection_for_bind(
           ^^^^^^^^^^^^^^^^^^^^^^^^^^^^^^^^^^^^^^^
  File "/home/airflow/.local/lib/python3.12/site-packages/sqlalchemy/orm/session.py", line 750, in _connection_for_bind
    conn = bind.connect()
           ^^^^^^^^^^^^^^
  File "/home/airflow/.local/lib/python3.12/site-packages/sqlalchemy/future/engine.py", line 412, in connect
    return super(Engine, self).connect()
           ^^^^^^^^^^^^^^^^^^^^^^^^^^^^^
  File "/home/airflow/.local/lib/python3.12/site-packages/sqlalchemy/engine/base.py", line 3325, in connect
    return self._connection_cls(self, close_with_result=close_with_result)
           ^^^^^^^^^^^^^^^^^^^^^^^^^^^^^^^^^^^^^^^^^^^^^^^^^^^^^^^^^^^^^^^
  File "/home/airflow/.local/lib/python3.12/site-packages/sqlalchemy/engine/base.py", line 96, in __init__
    else engine.raw_connection()
         ^^^^^^^^^^^^^^^^^^^^^^^
  File "/home/airflow/.local/lib/python3.12/site-packages/sqlalchemy/engine/base.py", line 3404, in raw_connection
    return self._wrap_pool_connect(self.pool.connect, _connection)
           ^^^^^^^^^^^^^^^^^^^^^^^^^^^^^^^^^^^^^^^^^^^^^^^^^^^^^^^
  File "/home/airflow/.local/lib/python3.12/site-packages/sqlalchemy/engine/base.py", line 3374, in _wrap_pool_connect
    Connection._handle_dbapi_exception_noconnection(
  File "/home/airflow/.local/lib/python3.12/site-packages/sqlalchemy/engine/base.py", line 2208, in _handle_dbapi_exception_noconnection
    util.raise_(
  File "/home/airflow/.local/lib/python3.12/site-packages/sqlalchemy/util/compat.py", line 211, in raise_
    raise exception
  File "/home/airflow/.local/lib/python3.12/site-packages/sqlalchemy/engine/base.py", line 3371, in _wrap_pool_connect
    return fn()
           ^^^^
  File "/home/airflow/.local/lib/python3.12/site-packages/sqlalchemy/pool/base.py", line 327, in connect
    return _ConnectionFairy._checkout(self)
           ^^^^^^^^^^^^^^^^^^^^^^^^^^^^^^^^
  File "/home/airflow/.local/lib/python3.12/site-packages/sqlalchemy/pool/base.py", line 894, in _checkout
    fairy = _ConnectionRecord.checkout(pool)
            ^^^^^^^^^^^^^^^^^^^^^^^^^^^^^^^^
  File "/home/airflow/.local/lib/python3.12/site-packages/sqlalchemy/pool/base.py", line 493, in checkout
    rec = pool._do_get()
          ^^^^^^^^^^^^^^
  File "/home/airflow/.local/lib/python3.12/site-packages/sqlalchemy/pool/impl.py", line 256, in _do_get
    return self._create_connection()
           ^^^^^^^^^^^^^^^^^^^^^^^^^
  File "/home/airflow/.local/lib/python3.12/site-packages/sqlalchemy/pool/base.py", line 273, in _create_connection
    return _ConnectionRecord(self)
           ^^^^^^^^^^^^^^^^^^^^^^^
  File "/home/airflow/.local/lib/python3.12/site-packages/sqlalchemy/pool/base.py", line 388, in __init__
    self.__connect()
  File "/home/airflow/.local/lib/python3.12/site-packages/sqlalchemy/pool/base.py", line 690, in __connect
    with util.safe_reraise():
         ^^^^^^^^^^^^^^^^^^^
  File "/home/airflow/.local/lib/python3.12/site-packages/sqlalchemy/util/langhelpers.py", line 70, in __exit__
    compat.raise_(
  File "/home/airflow/.local/lib/python3.12/site-packages/sqlalchemy/util/compat.py", line 211, in raise_
    raise exception
  File "/home/airflow/.local/lib/python3.12/site-packages/sqlalchemy/pool/base.py", line 686, in __connect
    self.dbapi_connection = connection = pool._invoke_creator(self)
                                         ^^^^^^^^^^^^^^^^^^^^^^^^^^
  File "/home/airflow/.local/lib/python3.12/site-packages/sqlalchemy/engine/create.py", line 574, in connect
    return dialect.connect(*cargs, **cparams)
           ^^^^^^^^^^^^^^^^^^^^^^^^^^^^^^^^^^
  File "/home/airflow/.local/lib/python3.12/site-packages/sqlalchemy/engine/default.py", line 598, in connect
    return self.dbapi.connect(*cargs, **cparams)
           ^^^^^^^^^^^^^^^^^^^^^^^^^^^^^^^^^^^^^
  File "/home/airflow/.local/lib/python3.12/site-packages/psycopg2/__init__.py", line 122, in connect
    conn = _connect(dsn, connection_factory=connection_factory, **kwasync)
           ^^^^^^^^^^^^^^^^^^^^^^^^^^^^^^^^^^^^^^^^^^^^^^^^^^^^^^^^^^^^^^^
sqlalchemy.exc.OperationalError: (psycopg2.OperationalError) could not translate host name "postgres" to address: Temporary failure in name resolution

(Background on this error at: https://sqlalche.me/e/14/e3q8)
[2025-03-11T09:42:56.239+0000] {job.py:254} ERROR - Job heartbeat failed with error. Scheduler is in unhealthy state
[2025-03-11T09:42:59.678+0000] {connectionpool.py:868} WARNING - Retrying (Retry(total=2, connect=3, read=4, redirect=None, status=None)) after connection broken by 'NameResolutionError("<urllib3.connection.HTTPSConnection object at 0x7f729bc9eab0>: Failed to resolve 'tiki.vn' ([Errno -3] Temporary failure in name resolution)")': /api/v2/products/248929458
[2025-03-11T09:43:01.441+0000] {job.py:229} INFO - Heartbeat recovered after 135.07 seconds
[2025-03-11T09:43:05.449+0000] {tiki_extract_dag.py:183} INFO - Extracted page 6/10 for category dien-thoai-may-tinh-bang, total items: 240
[2025-03-11T09:43:22.311+0000] {tiki_extract_dag.py:163} INFO - Calling API: https://tiki.vn/api/v2/products with params: {'page': 7, 'limit': 40, 'category': '1789'}
[2025-03-11T09:43:34.925+0000] {tiki_extract_dag.py:183} INFO - Extracted page 7/10 for category dien-thoai-may-tinh-bang, total items: 280
[2025-03-11T09:43:54.036+0000] {tiki_extract_dag.py:163} INFO - Calling API: https://tiki.vn/api/v2/products with params: {'page': 8, 'limit': 40, 'category': '1789'}
[2025-03-11T09:44:06.330+0000] {taskinstance.py:3313} ERROR - Task failed with exception
Traceback (most recent call last):
  File "/home/airflow/.local/lib/python3.12/site-packages/airflow/models/taskinstance.py", line 768, in _execute_task
    result = _execute_callable(context=context, **execute_callable_kwargs)
             ^^^^^^^^^^^^^^^^^^^^^^^^^^^^^^^^^^^^^^^^^^^^^^^^^^^^^^^^^^^^^
  File "/home/airflow/.local/lib/python3.12/site-packages/airflow/models/taskinstance.py", line 734, in _execute_callable
    return ExecutionCallableRunner(
           ^^^^^^^^^^^^^^^^^^^^^^^^
  File "/home/airflow/.local/lib/python3.12/site-packages/airflow/utils/operator_helpers.py", line 252, in run
    return self.func(*args, **kwargs)
           ^^^^^^^^^^^^^^^^^^^^^^^^^^
  File "/home/airflow/.local/lib/python3.12/site-packages/airflow/models/baseoperator.py", line 424, in wrapper
    return func(self, *args, **kwargs)
           ^^^^^^^^^^^^^^^^^^^^^^^^^^^
  File "/home/airflow/.local/lib/python3.12/site-packages/airflow/operators/python.py", line 238, in execute
    return_value = self.execute_callable()
                   ^^^^^^^^^^^^^^^^^^^^^^^
  File "/home/airflow/.local/lib/python3.12/site-packages/airflow/operators/python.py", line 256, in execute_callable
    return runner.run(*self.op_args, **self.op_kwargs)
           ^^^^^^^^^^^^^^^^^^^^^^^^^^^^^^^^^^^^^^^^^^^
  File "/home/airflow/.local/lib/python3.12/site-packages/airflow/utils/operator_helpers.py", line 252, in run
    return self.func(*args, **kwargs)
           ^^^^^^^^^^^^^^^^^^^^^^^^^^
  File "/opt/airflow/dags/tiki_extract_dag.py", line 179, in crawl_category
    parsed_item = parse_product(item, detailed_item)
                  ^^^^^^^^^^^^^^^^^^^^^^^^^^^^^^^^^^
  File "/opt/airflow/dags/tiki_extract_dag.py", line 90, in parse_product
    'seller_product_id': str(detailed_item.get('current_seller', {}).get('product_id', '')),
                             ^^^^^^^^^^^^^^^^^^^^^^^^^^^^^^^^^^^^^^^^^^^
AttributeError: 'NoneType' object has no attribute 'get'
[2025-03-11T09:44:06.885+0000] {logging_mixin.py:190} INFO - Task instance in failure state
[2025-03-11T09:44:06.887+0000] {logging_mixin.py:190} INFO - Task start:2025-03-11 09:36:13.940921+00:00 end:2025-03-11 09:44:06.813413+00:00 duration:472.872492
[2025-03-11T09:44:06.898+0000] {logging_mixin.py:190} INFO - Task:<Task(PythonOperator): crawl_dien-thoai-may-tinh-bang> dag:<DAG: tiki_extract_dag> dagrun:<DagRun tiki_extract_dag @ 2025-03-11 08:53:49.647616+00:00: manual__2025-03-11T08:53:49.647616+00:00, state:running, queued_at: 2025-03-11 08:53:49.700607+00:00. externally triggered: True>
[2025-03-11T09:44:06.901+0000] {logging_mixin.py:190} INFO - Failure caused by 'NoneType' object has no attribute 'get'
[2025-03-11T09:44:06.906+0000] {taskinstance.py:1226} INFO - Marking task as FAILED. dag_id=tiki_extract_dag, task_id=crawl_dien-thoai-may-tinh-bang, run_id=manual__2025-03-11T08:53:49.647616+00:00, execution_date=20250311T085349, start_date=20250311T093613, end_date=20250311T094406
[2025-03-11T09:44:07.415+0000] {taskinstance.py:341} INFO - ::group::Post task execution logs
[2025-03-11T09:44:07.436+0000] {standard_task_runner.py:124} ERROR - Failed to execute job 574 for task crawl_dien-thoai-may-tinh-bang ('NoneType' object has no attribute 'get'; 583)
Traceback (most recent call last):
  File "/home/airflow/.local/lib/python3.12/site-packages/airflow/task/task_runner/standard_task_runner.py", line 117, in _start_by_fork
    ret = args.func(args, dag=self.dag)
          ^^^^^^^^^^^^^^^^^^^^^^^^^^^^^
  File "/home/airflow/.local/lib/python3.12/site-packages/airflow/cli/cli_config.py", line 49, in command
    return func(*args, **kwargs)
           ^^^^^^^^^^^^^^^^^^^^^
  File "/home/airflow/.local/lib/python3.12/site-packages/airflow/utils/cli.py", line 116, in wrapper
    return f(*args, **kwargs)
           ^^^^^^^^^^^^^^^^^^
  File "/home/airflow/.local/lib/python3.12/site-packages/airflow/cli/commands/task_command.py", line 483, in task_run
    task_return_code = _run_task_by_selected_method(args, _dag, ti)
                       ^^^^^^^^^^^^^^^^^^^^^^^^^^^^^^^^^^^^^^^^^^^^
  File "/home/airflow/.local/lib/python3.12/site-packages/airflow/cli/commands/task_command.py", line 256, in _run_task_by_selected_method
    return _run_raw_task(args, ti)
           ^^^^^^^^^^^^^^^^^^^^^^^
  File "/home/airflow/.local/lib/python3.12/site-packages/airflow/cli/commands/task_command.py", line 341, in _run_raw_task
    return ti._run_raw_task(
           ^^^^^^^^^^^^^^^^^
  File "/home/airflow/.local/lib/python3.12/site-packages/airflow/utils/session.py", line 97, in wrapper
    return func(*args, session=session, **kwargs)
           ^^^^^^^^^^^^^^^^^^^^^^^^^^^^^^^^^^^^^^
  File "/home/airflow/.local/lib/python3.12/site-packages/airflow/models/taskinstance.py", line 3006, in _run_raw_task
    return _run_raw_task(
           ^^^^^^^^^^^^^^
  File "/home/airflow/.local/lib/python3.12/site-packages/airflow/models/taskinstance.py", line 274, in _run_raw_task
    TaskInstance._execute_task_with_callbacks(
  File "/home/airflow/.local/lib/python3.12/site-packages/airflow/models/taskinstance.py", line 3161, in _execute_task_with_callbacks
    result = self._execute_task(context, task_orig)
             ^^^^^^^^^^^^^^^^^^^^^^^^^^^^^^^^^^^^^^
  File "/home/airflow/.local/lib/python3.12/site-packages/airflow/models/taskinstance.py", line 3185, in _execute_task
    return _execute_task(self, context, task_orig)
           ^^^^^^^^^^^^^^^^^^^^^^^^^^^^^^^^^^^^^^^
  File "/home/airflow/.local/lib/python3.12/site-packages/airflow/models/taskinstance.py", line 768, in _execute_task
    result = _execute_callable(context=context, **execute_callable_kwargs)
             ^^^^^^^^^^^^^^^^^^^^^^^^^^^^^^^^^^^^^^^^^^^^^^^^^^^^^^^^^^^^^
  File "/home/airflow/.local/lib/python3.12/site-packages/airflow/models/taskinstance.py", line 734, in _execute_callable
    return ExecutionCallableRunner(
           ^^^^^^^^^^^^^^^^^^^^^^^^
  File "/home/airflow/.local/lib/python3.12/site-packages/airflow/utils/operator_helpers.py", line 252, in run
    return self.func(*args, **kwargs)
           ^^^^^^^^^^^^^^^^^^^^^^^^^^
  File "/home/airflow/.local/lib/python3.12/site-packages/airflow/models/baseoperator.py", line 424, in wrapper
    return func(self, *args, **kwargs)
           ^^^^^^^^^^^^^^^^^^^^^^^^^^^
  File "/home/airflow/.local/lib/python3.12/site-packages/airflow/operators/python.py", line 238, in execute
    return_value = self.execute_callable()
                   ^^^^^^^^^^^^^^^^^^^^^^^
  File "/home/airflow/.local/lib/python3.12/site-packages/airflow/operators/python.py", line 256, in execute_callable
    return runner.run(*self.op_args, **self.op_kwargs)
           ^^^^^^^^^^^^^^^^^^^^^^^^^^^^^^^^^^^^^^^^^^^
  File "/home/airflow/.local/lib/python3.12/site-packages/airflow/utils/operator_helpers.py", line 252, in run
    return self.func(*args, **kwargs)
           ^^^^^^^^^^^^^^^^^^^^^^^^^^
  File "/opt/airflow/dags/tiki_extract_dag.py", line 179, in crawl_category
    parsed_item = parse_product(item, detailed_item)
                  ^^^^^^^^^^^^^^^^^^^^^^^^^^^^^^^^^^
  File "/opt/airflow/dags/tiki_extract_dag.py", line 90, in parse_product
    'seller_product_id': str(detailed_item.get('current_seller', {}).get('product_id', '')),
                             ^^^^^^^^^^^^^^^^^^^^^^^^^^^^^^^^^^^^^^^^^^^
AttributeError: 'NoneType' object has no attribute 'get'
[2025-03-11T09:44:07.634+0000] {local_task_job_runner.py:266} INFO - Task exited with return code 1
[2025-03-11T09:44:07.918+0000] {taskinstance.py:3901} INFO - 0 downstream tasks scheduled from follow-on schedule check
[2025-03-11T09:44:07.925+0000] {local_task_job_runner.py:245} INFO - ::endgroup::
