[2025-03-11T08:58:09.151+0000] {local_task_job_runner.py:123} INFO - ::group::Pre task execution logs
[2025-03-11T08:58:09.389+0000] {taskinstance.py:2614} INFO - Dependencies all met for dep_context=non-requeueable deps ti=<TaskInstance: tiki_extract_dag.crawl_dien-thoai-may-tinh-bang manual__2025-03-11T08:53:49.647616+00:00 [queued]>
[2025-03-11T08:58:09.495+0000] {taskinstance.py:2614} INFO - Dependencies all met for dep_context=requeueable deps ti=<TaskInstance: tiki_extract_dag.crawl_dien-thoai-may-tinh-bang manual__2025-03-11T08:53:49.647616+00:00 [queued]>
[2025-03-11T08:58:09.498+0000] {taskinstance.py:2867} INFO - Starting attempt 1 of 4
[2025-03-11T08:58:09.620+0000] {taskinstance.py:2890} INFO - Executing <Task(PythonOperator): crawl_dien-thoai-may-tinh-bang> on 2025-03-11 08:53:49.647616+00:00
[2025-03-11T08:58:09.685+0000] {warnings.py:112} WARNING - /home/***/.local/lib/python3.12/site-packages/***/task/task_runner/standard_task_runner.py:70: DeprecationWarning: This process (pid=173) is multi-threaded, use of fork() may lead to deadlocks in the child.
  pid = os.fork()

[2025-03-11T08:58:09.691+0000] {standard_task_runner.py:72} INFO - Started process 197 to run task
[2025-03-11T08:58:09.690+0000] {standard_task_runner.py:104} INFO - Running: ['***', 'tasks', 'run', 'tiki_extract_dag', 'crawl_dien-thoai-may-tinh-bang', 'manual__2025-03-11T08:53:49.647616+00:00', '--job-id', '536', '--raw', '--subdir', 'DAGS_FOLDER/tiki_extract_dag.py', '--cfg-path', '/tmp/tmp5cqy_jbp']
[2025-03-11T08:58:09.708+0000] {standard_task_runner.py:105} INFO - Job 536: Subtask crawl_dien-thoai-may-tinh-bang
[2025-03-11T08:58:10.000+0000] {task_command.py:467} INFO - Running <TaskInstance: tiki_extract_dag.crawl_dien-thoai-may-tinh-bang manual__2025-03-11T08:53:49.647616+00:00 [running]> on host 5c8190d7da62
[2025-03-11T08:58:11.339+0000] {taskinstance.py:3134} INFO - Exporting env vars: AIRFLOW_CTX_DAG_OWNER='***' AIRFLOW_CTX_DAG_ID='tiki_extract_dag' AIRFLOW_CTX_TASK_ID='crawl_dien-thoai-may-tinh-bang' AIRFLOW_CTX_EXECUTION_DATE='2025-03-11T08:53:49.647616+00:00' AIRFLOW_CTX_TRY_NUMBER='1' AIRFLOW_CTX_DAG_RUN_ID='manual__2025-03-11T08:53:49.647616+00:00'
[2025-03-11T08:58:11.345+0000] {logging_mixin.py:190} INFO - Task instance is in running state
[2025-03-11T08:58:11.348+0000] {logging_mixin.py:190} INFO -  Previous state of the Task instance: queued
[2025-03-11T08:58:11.349+0000] {logging_mixin.py:190} INFO - Current task name:crawl_dien-thoai-may-tinh-bang state:running start_date:2025-03-11 08:58:09.400071+00:00
[2025-03-11T08:58:11.351+0000] {logging_mixin.py:190} INFO - Dag name:tiki_extract_dag and current dag run status:running
[2025-03-11T08:58:11.355+0000] {taskinstance.py:732} INFO - ::endgroup::
[2025-03-11T08:58:21.908+0000] {connectionpool.py:868} WARNING - Retrying (Retry(total=2, connect=None, read=None, redirect=None, status=None)) after connection broken by 'NameResolutionError("<urllib3.connection.HTTPSConnection object at 0x7f72a01b5940>: Failed to resolve 'oauth2.googleapis.com' ([Errno -3] Temporary failure in name resolution)")': /token
[2025-03-11T08:58:36.587+0000] {connectionpool.py:868} WARNING - Retrying (Retry(total=1, connect=None, read=None, redirect=None, status=None)) after connection broken by 'NameResolutionError("<urllib3.connection.HTTPSConnection object at 0x7f729bc15dc0>: Failed to resolve 'oauth2.googleapis.com' ([Errno -3] Temporary failure in name resolution)")': /token
[2025-03-11T08:58:59.499+0000] {connectionpool.py:868} WARNING - Retrying (Retry(total=0, connect=None, read=None, redirect=None, status=None)) after connection broken by 'NameResolutionError("<urllib3.connection.HTTPSConnection object at 0x7f72a05238c0>: Failed to resolve 'oauth2.googleapis.com' ([Errno -3] Temporary failure in name resolution)")': /token
[2025-03-11T08:59:14.982+0000] {job.py:239} ERROR - Job heartbeat failed with error
Traceback (most recent call last):
  File "/home/airflow/.local/lib/python3.12/site-packages/sqlalchemy/engine/base.py", line 3371, in _wrap_pool_connect
    return fn()
           ^^^^
  File "/home/airflow/.local/lib/python3.12/site-packages/sqlalchemy/pool/base.py", line 327, in connect
    return _ConnectionFairy._checkout(self)
           ^^^^^^^^^^^^^^^^^^^^^^^^^^^^^^^^
  File "/home/airflow/.local/lib/python3.12/site-packages/sqlalchemy/pool/base.py", line 894, in _checkout
    fairy = _ConnectionRecord.checkout(pool)
            ^^^^^^^^^^^^^^^^^^^^^^^^^^^^^^^^
  File "/home/airflow/.local/lib/python3.12/site-packages/sqlalchemy/pool/base.py", line 493, in checkout
    rec = pool._do_get()
          ^^^^^^^^^^^^^^
  File "/home/airflow/.local/lib/python3.12/site-packages/sqlalchemy/pool/impl.py", line 256, in _do_get
    return self._create_connection()
           ^^^^^^^^^^^^^^^^^^^^^^^^^
  File "/home/airflow/.local/lib/python3.12/site-packages/sqlalchemy/pool/base.py", line 273, in _create_connection
    return _ConnectionRecord(self)
           ^^^^^^^^^^^^^^^^^^^^^^^
  File "/home/airflow/.local/lib/python3.12/site-packages/sqlalchemy/pool/base.py", line 388, in __init__
    self.__connect()
  File "/home/airflow/.local/lib/python3.12/site-packages/sqlalchemy/pool/base.py", line 690, in __connect
    with util.safe_reraise():
         ^^^^^^^^^^^^^^^^^^^
  File "/home/airflow/.local/lib/python3.12/site-packages/sqlalchemy/util/langhelpers.py", line 70, in __exit__
    compat.raise_(
  File "/home/airflow/.local/lib/python3.12/site-packages/sqlalchemy/util/compat.py", line 211, in raise_
    raise exception
  File "/home/airflow/.local/lib/python3.12/site-packages/sqlalchemy/pool/base.py", line 686, in __connect
    self.dbapi_connection = connection = pool._invoke_creator(self)
                                         ^^^^^^^^^^^^^^^^^^^^^^^^^^
  File "/home/airflow/.local/lib/python3.12/site-packages/sqlalchemy/engine/create.py", line 574, in connect
    return dialect.connect(*cargs, **cparams)
           ^^^^^^^^^^^^^^^^^^^^^^^^^^^^^^^^^^
  File "/home/airflow/.local/lib/python3.12/site-packages/sqlalchemy/engine/default.py", line 598, in connect
    return self.dbapi.connect(*cargs, **cparams)
           ^^^^^^^^^^^^^^^^^^^^^^^^^^^^^^^^^^^^^
  File "/home/airflow/.local/lib/python3.12/site-packages/psycopg2/__init__.py", line 122, in connect
    conn = _connect(dsn, connection_factory=connection_factory, **kwasync)
           ^^^^^^^^^^^^^^^^^^^^^^^^^^^^^^^^^^^^^^^^^^^^^^^^^^^^^^^^^^^^^^^
psycopg2.OperationalError: could not translate host name "postgres" to address: Temporary failure in name resolution


The above exception was the direct cause of the following exception:

Traceback (most recent call last):
  File "/home/airflow/.local/lib/python3.12/site-packages/airflow/jobs/job.py", line 207, in heartbeat
    self._merge_from(Job._fetch_from_db(self, session))
                     ^^^^^^^^^^^^^^^^^^^^^^^^^^^^^^^^^
  File "/home/airflow/.local/lib/python3.12/site-packages/airflow/api_internal/internal_api_call.py", line 166, in wrapper
    return func(*args, **kwargs)
           ^^^^^^^^^^^^^^^^^^^^^
  File "/home/airflow/.local/lib/python3.12/site-packages/airflow/utils/session.py", line 94, in wrapper
    return func(*args, **kwargs)
           ^^^^^^^^^^^^^^^^^^^^^
  File "/home/airflow/.local/lib/python3.12/site-packages/airflow/utils/retries.py", line 93, in wrapped_function
    for attempt in run_with_db_retries(max_retries=retries, logger=logger, **retry_kwargs):
                   ^^^^^^^^^^^^^^^^^^^^^^^^^^^^^^^^^^^^^^^^^^^^^^^^^^^^^^^^^^^^^^^^^^^^^^^
  File "/home/airflow/.local/lib/python3.12/site-packages/tenacity/__init__.py", line 443, in __iter__
    do = self.iter(retry_state=retry_state)
         ^^^^^^^^^^^^^^^^^^^^^^^^^^^^^^^^^^
  File "/home/airflow/.local/lib/python3.12/site-packages/tenacity/__init__.py", line 376, in iter
    result = action(retry_state)
             ^^^^^^^^^^^^^^^^^^^
  File "/home/airflow/.local/lib/python3.12/site-packages/tenacity/__init__.py", line 418, in exc_check
    raise retry_exc.reraise()
          ^^^^^^^^^^^^^^^^^^^
  File "/home/airflow/.local/lib/python3.12/site-packages/tenacity/__init__.py", line 185, in reraise
    raise self.last_attempt.result()
          ^^^^^^^^^^^^^^^^^^^^^^^^^^
  File "/usr/local/lib/python3.12/concurrent/futures/_base.py", line 449, in result
    return self.__get_result()
           ^^^^^^^^^^^^^^^^^^^
  File "/usr/local/lib/python3.12/concurrent/futures/_base.py", line 401, in __get_result
    raise self._exception
  File "/home/airflow/.local/lib/python3.12/site-packages/airflow/utils/retries.py", line 102, in wrapped_function
    return func(*args, **kwargs)
           ^^^^^^^^^^^^^^^^^^^^^
  File "/home/airflow/.local/lib/python3.12/site-packages/airflow/jobs/job.py", line 335, in _fetch_from_db
    session.merge(job)
  File "/home/airflow/.local/lib/python3.12/site-packages/sqlalchemy/orm/session.py", line 3056, in merge
    return self._merge(
           ^^^^^^^^^^^^
  File "/home/airflow/.local/lib/python3.12/site-packages/sqlalchemy/orm/session.py", line 3136, in _merge
    merged = self.get(
             ^^^^^^^^^
  File "/home/airflow/.local/lib/python3.12/site-packages/sqlalchemy/orm/session.py", line 2853, in get
    return self._get_impl(
           ^^^^^^^^^^^^^^^
  File "/home/airflow/.local/lib/python3.12/site-packages/sqlalchemy/orm/session.py", line 2975, in _get_impl
    return db_load_fn(
           ^^^^^^^^^^^
  File "/home/airflow/.local/lib/python3.12/site-packages/sqlalchemy/orm/loading.py", line 530, in load_on_pk_identity
    session.execute(
  File "/home/airflow/.local/lib/python3.12/site-packages/sqlalchemy/orm/session.py", line 1716, in execute
    conn = self._connection_for_bind(bind)
           ^^^^^^^^^^^^^^^^^^^^^^^^^^^^^^^
  File "/home/airflow/.local/lib/python3.12/site-packages/sqlalchemy/orm/session.py", line 1555, in _connection_for_bind
    return self._transaction._connection_for_bind(
           ^^^^^^^^^^^^^^^^^^^^^^^^^^^^^^^^^^^^^^^
  File "/home/airflow/.local/lib/python3.12/site-packages/sqlalchemy/orm/session.py", line 750, in _connection_for_bind
    conn = bind.connect()
           ^^^^^^^^^^^^^^
  File "/home/airflow/.local/lib/python3.12/site-packages/sqlalchemy/future/engine.py", line 412, in connect
    return super(Engine, self).connect()
           ^^^^^^^^^^^^^^^^^^^^^^^^^^^^^
  File "/home/airflow/.local/lib/python3.12/site-packages/sqlalchemy/engine/base.py", line 3325, in connect
    return self._connection_cls(self, close_with_result=close_with_result)
           ^^^^^^^^^^^^^^^^^^^^^^^^^^^^^^^^^^^^^^^^^^^^^^^^^^^^^^^^^^^^^^^
  File "/home/airflow/.local/lib/python3.12/site-packages/sqlalchemy/engine/base.py", line 96, in __init__
    else engine.raw_connection()
         ^^^^^^^^^^^^^^^^^^^^^^^
  File "/home/airflow/.local/lib/python3.12/site-packages/sqlalchemy/engine/base.py", line 3404, in raw_connection
    return self._wrap_pool_connect(self.pool.connect, _connection)
           ^^^^^^^^^^^^^^^^^^^^^^^^^^^^^^^^^^^^^^^^^^^^^^^^^^^^^^^
  File "/home/airflow/.local/lib/python3.12/site-packages/sqlalchemy/engine/base.py", line 3374, in _wrap_pool_connect
    Connection._handle_dbapi_exception_noconnection(
  File "/home/airflow/.local/lib/python3.12/site-packages/sqlalchemy/engine/base.py", line 2208, in _handle_dbapi_exception_noconnection
    util.raise_(
  File "/home/airflow/.local/lib/python3.12/site-packages/sqlalchemy/util/compat.py", line 211, in raise_
    raise exception
  File "/home/airflow/.local/lib/python3.12/site-packages/sqlalchemy/engine/base.py", line 3371, in _wrap_pool_connect
    return fn()
           ^^^^
  File "/home/airflow/.local/lib/python3.12/site-packages/sqlalchemy/pool/base.py", line 327, in connect
    return _ConnectionFairy._checkout(self)
           ^^^^^^^^^^^^^^^^^^^^^^^^^^^^^^^^
  File "/home/airflow/.local/lib/python3.12/site-packages/sqlalchemy/pool/base.py", line 894, in _checkout
    fairy = _ConnectionRecord.checkout(pool)
            ^^^^^^^^^^^^^^^^^^^^^^^^^^^^^^^^
  File "/home/airflow/.local/lib/python3.12/site-packages/sqlalchemy/pool/base.py", line 493, in checkout
    rec = pool._do_get()
          ^^^^^^^^^^^^^^
  File "/home/airflow/.local/lib/python3.12/site-packages/sqlalchemy/pool/impl.py", line 256, in _do_get
    return self._create_connection()
           ^^^^^^^^^^^^^^^^^^^^^^^^^
  File "/home/airflow/.local/lib/python3.12/site-packages/sqlalchemy/pool/base.py", line 273, in _create_connection
    return _ConnectionRecord(self)
           ^^^^^^^^^^^^^^^^^^^^^^^
  File "/home/airflow/.local/lib/python3.12/site-packages/sqlalchemy/pool/base.py", line 388, in __init__
    self.__connect()
  File "/home/airflow/.local/lib/python3.12/site-packages/sqlalchemy/pool/base.py", line 690, in __connect
    with util.safe_reraise():
         ^^^^^^^^^^^^^^^^^^^
  File "/home/airflow/.local/lib/python3.12/site-packages/sqlalchemy/util/langhelpers.py", line 70, in __exit__
    compat.raise_(
  File "/home/airflow/.local/lib/python3.12/site-packages/sqlalchemy/util/compat.py", line 211, in raise_
    raise exception
  File "/home/airflow/.local/lib/python3.12/site-packages/sqlalchemy/pool/base.py", line 686, in __connect
    self.dbapi_connection = connection = pool._invoke_creator(self)
                                         ^^^^^^^^^^^^^^^^^^^^^^^^^^
  File "/home/airflow/.local/lib/python3.12/site-packages/sqlalchemy/engine/create.py", line 574, in connect
    return dialect.connect(*cargs, **cparams)
           ^^^^^^^^^^^^^^^^^^^^^^^^^^^^^^^^^^
  File "/home/airflow/.local/lib/python3.12/site-packages/sqlalchemy/engine/default.py", line 598, in connect
    return self.dbapi.connect(*cargs, **cparams)
           ^^^^^^^^^^^^^^^^^^^^^^^^^^^^^^^^^^^^^
  File "/home/airflow/.local/lib/python3.12/site-packages/psycopg2/__init__.py", line 122, in connect
    conn = _connect(dsn, connection_factory=connection_factory, **kwasync)
           ^^^^^^^^^^^^^^^^^^^^^^^^^^^^^^^^^^^^^^^^^^^^^^^^^^^^^^^^^^^^^^^
sqlalchemy.exc.OperationalError: (psycopg2.OperationalError) could not translate host name "postgres" to address: Temporary failure in name resolution

(Background on this error at: https://sqlalche.me/e/14/e3q8)
[2025-03-11T08:59:15.094+0000] {job.py:254} ERROR - Job heartbeat failed with error. Scheduler is in unhealthy state
[2025-03-11T09:00:08.551+0000] {connectionpool.py:868} WARNING - Retrying (Retry(total=2, connect=None, read=None, redirect=None, status=None)) after connection broken by 'NameResolutionError("<urllib3.connection.HTTPSConnection object at 0x7f72a03c2030>: Failed to resolve 'oauth2.googleapis.com' ([Errno -3] Temporary failure in name resolution)")': /token
[2025-03-11T09:00:12.890+0000] {job.py:229} INFO - Heartbeat recovered after 124.12 seconds
[2025-03-11T09:00:24.294+0000] {tiki_extract_dag.py:36} ERROR - Error reading crawled products: Timeout of 120.0s exceeded, last exception: HTTPSConnectionPool(host='storage.googleapis.com', port=443): Max retries exceeded with url: /storage/v1/b/tiki-pipeline/o/tiki_crawled%2Fcrawled_products.json?fields=name&prettyPrint=false (Caused by NameResolutionError("<urllib3.connection.HTTPSConnection object at 0x7f72a0335e50>: Failed to resolve 'storage.googleapis.com' ([Errno -3] Temporary failure in name resolution)"))
[2025-03-11T09:00:24.790+0000] {tiki_extract_dag.py:139} INFO - Starting crawl for category dien-thoai-may-tinh-bang (ID: 1789)
[2025-03-11T09:00:26.395+0000] {tiki_extract_dag.py:141} INFO - Calling API: https://tiki.vn/api/v2/products with params: {'page': 1, 'limit': 40, 'category': '1789'}
[2025-03-11T09:00:44.419+0000] {connectionpool.py:868} WARNING - Retrying (Retry(total=4, connect=4, read=5, redirect=None, status=None)) after connection broken by 'NameResolutionError("<urllib3.connection.HTTPSConnection object at 0x7f72a0337650>: Failed to resolve 'tiki.vn' ([Errno -3] Temporary failure in name resolution)")': /api/v2/products?page=1&limit=40&category=1789
[2025-03-11T09:01:06.073+0000] {job.py:229} INFO - Heartbeat recovered after 53.20 seconds
[2025-03-11T09:01:06.625+0000] {tiki_extract_dag.py:150} INFO - Total pages for dien-thoai-may-tinh-bang: 9 (limited to 50)
[2025-03-11T09:01:37.615+0000] {tiki_extract_dag.py:120} ERROR - Error fetching details for product 217706932 on attempt 1/3: Expecting value: line 1 column 1 (char 0)
[2025-03-11T09:01:43.845+0000] {tiki_extract_dag.py:120} ERROR - Error fetching details for product 217706932 on attempt 2/3: Expecting value: line 1 column 1 (char 0)
[2025-03-11T09:02:01.168+0000] {tiki_extract_dag.py:163} INFO - Calling API: https://tiki.vn/api/v2/products with params: {'page': 2, 'limit': 40, 'category': '1789'}
[2025-03-11T09:02:12.656+0000] {tiki_extract_dag.py:120} ERROR - Error fetching details for product 275589968 on attempt 1/3: Expecting value: line 1 column 1 (char 0)
[2025-03-11T09:02:20.132+0000] {tiki_extract_dag.py:120} ERROR - Error fetching details for product 275589968 on attempt 2/3: Expecting value: line 1 column 1 (char 0)
[2025-03-11T09:02:44.635+0000] {connectionpool.py:868} WARNING - Retrying (Retry(total=4, connect=5, read=4, redirect=None, status=None)) after connection broken by 'ReadTimeoutError("HTTPSConnectionPool(host='tiki.vn', port=443): Read timed out. (read timeout=15)")': /api/v2/products/275589968
[2025-03-11T09:02:44.773+0000] {job.py:239} ERROR - Job heartbeat failed with error
Traceback (most recent call last):
  File "/home/airflow/.local/lib/python3.12/site-packages/sqlalchemy/engine/base.py", line 3371, in _wrap_pool_connect
    return fn()
           ^^^^
  File "/home/airflow/.local/lib/python3.12/site-packages/sqlalchemy/pool/base.py", line 327, in connect
    return _ConnectionFairy._checkout(self)
           ^^^^^^^^^^^^^^^^^^^^^^^^^^^^^^^^
  File "/home/airflow/.local/lib/python3.12/site-packages/sqlalchemy/pool/base.py", line 894, in _checkout
    fairy = _ConnectionRecord.checkout(pool)
            ^^^^^^^^^^^^^^^^^^^^^^^^^^^^^^^^
  File "/home/airflow/.local/lib/python3.12/site-packages/sqlalchemy/pool/base.py", line 493, in checkout
    rec = pool._do_get()
          ^^^^^^^^^^^^^^
  File "/home/airflow/.local/lib/python3.12/site-packages/sqlalchemy/pool/impl.py", line 256, in _do_get
    return self._create_connection()
           ^^^^^^^^^^^^^^^^^^^^^^^^^
  File "/home/airflow/.local/lib/python3.12/site-packages/sqlalchemy/pool/base.py", line 273, in _create_connection
    return _ConnectionRecord(self)
           ^^^^^^^^^^^^^^^^^^^^^^^
  File "/home/airflow/.local/lib/python3.12/site-packages/sqlalchemy/pool/base.py", line 388, in __init__
    self.__connect()
  File "/home/airflow/.local/lib/python3.12/site-packages/sqlalchemy/pool/base.py", line 690, in __connect
    with util.safe_reraise():
         ^^^^^^^^^^^^^^^^^^^
  File "/home/airflow/.local/lib/python3.12/site-packages/sqlalchemy/util/langhelpers.py", line 70, in __exit__
    compat.raise_(
  File "/home/airflow/.local/lib/python3.12/site-packages/sqlalchemy/util/compat.py", line 211, in raise_
    raise exception
  File "/home/airflow/.local/lib/python3.12/site-packages/sqlalchemy/pool/base.py", line 686, in __connect
    self.dbapi_connection = connection = pool._invoke_creator(self)
                                         ^^^^^^^^^^^^^^^^^^^^^^^^^^
  File "/home/airflow/.local/lib/python3.12/site-packages/sqlalchemy/engine/create.py", line 574, in connect
    return dialect.connect(*cargs, **cparams)
           ^^^^^^^^^^^^^^^^^^^^^^^^^^^^^^^^^^
  File "/home/airflow/.local/lib/python3.12/site-packages/sqlalchemy/engine/default.py", line 598, in connect
    return self.dbapi.connect(*cargs, **cparams)
           ^^^^^^^^^^^^^^^^^^^^^^^^^^^^^^^^^^^^^
  File "/home/airflow/.local/lib/python3.12/site-packages/psycopg2/__init__.py", line 122, in connect
    conn = _connect(dsn, connection_factory=connection_factory, **kwasync)
           ^^^^^^^^^^^^^^^^^^^^^^^^^^^^^^^^^^^^^^^^^^^^^^^^^^^^^^^^^^^^^^^
psycopg2.OperationalError: could not translate host name "postgres" to address: Temporary failure in name resolution


The above exception was the direct cause of the following exception:

Traceback (most recent call last):
  File "/home/airflow/.local/lib/python3.12/site-packages/airflow/jobs/job.py", line 233, in heartbeat
    heartbeat_callback(session)
  File "/home/airflow/.local/lib/python3.12/site-packages/airflow/utils/session.py", line 94, in wrapper
    return func(*args, **kwargs)
           ^^^^^^^^^^^^^^^^^^^^^
  File "/home/airflow/.local/lib/python3.12/site-packages/airflow/jobs/local_task_job_runner.py", line 284, in heartbeat_callback
    self.task_instance.refresh_from_db()
  File "/home/airflow/.local/lib/python3.12/site-packages/airflow/utils/session.py", line 97, in wrapper
    return func(*args, session=session, **kwargs)
           ^^^^^^^^^^^^^^^^^^^^^^^^^^^^^^^^^^^^^^
  File "/home/airflow/.local/lib/python3.12/site-packages/airflow/models/taskinstance.py", line 2360, in refresh_from_db
    _refresh_from_db(task_instance=self, session=session, lock_for_update=lock_for_update)
  File "/home/airflow/.local/lib/python3.12/site-packages/airflow/models/taskinstance.py", line 873, in _refresh_from_db
    ti = TaskInstance.get_task_instance(
         ^^^^^^^^^^^^^^^^^^^^^^^^^^^^^^^
  File "/home/airflow/.local/lib/python3.12/site-packages/airflow/api_internal/internal_api_call.py", line 166, in wrapper
    return func(*args, **kwargs)
           ^^^^^^^^^^^^^^^^^^^^^
  File "/home/airflow/.local/lib/python3.12/site-packages/airflow/utils/session.py", line 94, in wrapper
    return func(*args, **kwargs)
           ^^^^^^^^^^^^^^^^^^^^^
  File "/home/airflow/.local/lib/python3.12/site-packages/airflow/models/taskinstance.py", line 2346, in get_task_instance
    return query.one_or_none()
           ^^^^^^^^^^^^^^^^^^^
  File "/home/airflow/.local/lib/python3.12/site-packages/sqlalchemy/orm/query.py", line 2850, in one_or_none
    return self._iter().one_or_none()
           ^^^^^^^^^^^^
  File "/home/airflow/.local/lib/python3.12/site-packages/sqlalchemy/orm/query.py", line 2916, in _iter
    result = self.session.execute(
             ^^^^^^^^^^^^^^^^^^^^^
  File "/home/airflow/.local/lib/python3.12/site-packages/sqlalchemy/orm/session.py", line 1716, in execute
    conn = self._connection_for_bind(bind)
           ^^^^^^^^^^^^^^^^^^^^^^^^^^^^^^^
  File "/home/airflow/.local/lib/python3.12/site-packages/sqlalchemy/orm/session.py", line 1555, in _connection_for_bind
    return self._transaction._connection_for_bind(
           ^^^^^^^^^^^^^^^^^^^^^^^^^^^^^^^^^^^^^^^
  File "/home/airflow/.local/lib/python3.12/site-packages/sqlalchemy/orm/session.py", line 750, in _connection_for_bind
    conn = bind.connect()
           ^^^^^^^^^^^^^^
  File "/home/airflow/.local/lib/python3.12/site-packages/sqlalchemy/future/engine.py", line 412, in connect
    return super(Engine, self).connect()
           ^^^^^^^^^^^^^^^^^^^^^^^^^^^^^
  File "/home/airflow/.local/lib/python3.12/site-packages/sqlalchemy/engine/base.py", line 3325, in connect
    return self._connection_cls(self, close_with_result=close_with_result)
           ^^^^^^^^^^^^^^^^^^^^^^^^^^^^^^^^^^^^^^^^^^^^^^^^^^^^^^^^^^^^^^^
  File "/home/airflow/.local/lib/python3.12/site-packages/sqlalchemy/engine/base.py", line 96, in __init__
    else engine.raw_connection()
         ^^^^^^^^^^^^^^^^^^^^^^^
  File "/home/airflow/.local/lib/python3.12/site-packages/sqlalchemy/engine/base.py", line 3404, in raw_connection
    return self._wrap_pool_connect(self.pool.connect, _connection)
           ^^^^^^^^^^^^^^^^^^^^^^^^^^^^^^^^^^^^^^^^^^^^^^^^^^^^^^^
  File "/home/airflow/.local/lib/python3.12/site-packages/sqlalchemy/engine/base.py", line 3374, in _wrap_pool_connect
    Connection._handle_dbapi_exception_noconnection(
  File "/home/airflow/.local/lib/python3.12/site-packages/sqlalchemy/engine/base.py", line 2208, in _handle_dbapi_exception_noconnection
    util.raise_(
  File "/home/airflow/.local/lib/python3.12/site-packages/sqlalchemy/util/compat.py", line 211, in raise_
    raise exception
  File "/home/airflow/.local/lib/python3.12/site-packages/sqlalchemy/engine/base.py", line 3371, in _wrap_pool_connect
    return fn()
           ^^^^
  File "/home/airflow/.local/lib/python3.12/site-packages/sqlalchemy/pool/base.py", line 327, in connect
    return _ConnectionFairy._checkout(self)
           ^^^^^^^^^^^^^^^^^^^^^^^^^^^^^^^^
  File "/home/airflow/.local/lib/python3.12/site-packages/sqlalchemy/pool/base.py", line 894, in _checkout
    fairy = _ConnectionRecord.checkout(pool)
            ^^^^^^^^^^^^^^^^^^^^^^^^^^^^^^^^
  File "/home/airflow/.local/lib/python3.12/site-packages/sqlalchemy/pool/base.py", line 493, in checkout
    rec = pool._do_get()
          ^^^^^^^^^^^^^^
  File "/home/airflow/.local/lib/python3.12/site-packages/sqlalchemy/pool/impl.py", line 256, in _do_get
    return self._create_connection()
           ^^^^^^^^^^^^^^^^^^^^^^^^^
  File "/home/airflow/.local/lib/python3.12/site-packages/sqlalchemy/pool/base.py", line 273, in _create_connection
    return _ConnectionRecord(self)
           ^^^^^^^^^^^^^^^^^^^^^^^
  File "/home/airflow/.local/lib/python3.12/site-packages/sqlalchemy/pool/base.py", line 388, in __init__
    self.__connect()
  File "/home/airflow/.local/lib/python3.12/site-packages/sqlalchemy/pool/base.py", line 690, in __connect
    with util.safe_reraise():
         ^^^^^^^^^^^^^^^^^^^
  File "/home/airflow/.local/lib/python3.12/site-packages/sqlalchemy/util/langhelpers.py", line 70, in __exit__
    compat.raise_(
  File "/home/airflow/.local/lib/python3.12/site-packages/sqlalchemy/util/compat.py", line 211, in raise_
    raise exception
  File "/home/airflow/.local/lib/python3.12/site-packages/sqlalchemy/pool/base.py", line 686, in __connect
    self.dbapi_connection = connection = pool._invoke_creator(self)
                                         ^^^^^^^^^^^^^^^^^^^^^^^^^^
  File "/home/airflow/.local/lib/python3.12/site-packages/sqlalchemy/engine/create.py", line 574, in connect
    return dialect.connect(*cargs, **cparams)
           ^^^^^^^^^^^^^^^^^^^^^^^^^^^^^^^^^^
  File "/home/airflow/.local/lib/python3.12/site-packages/sqlalchemy/engine/default.py", line 598, in connect
    return self.dbapi.connect(*cargs, **cparams)
           ^^^^^^^^^^^^^^^^^^^^^^^^^^^^^^^^^^^^^
  File "/home/airflow/.local/lib/python3.12/site-packages/psycopg2/__init__.py", line 122, in connect
    conn = _connect(dsn, connection_factory=connection_factory, **kwasync)
           ^^^^^^^^^^^^^^^^^^^^^^^^^^^^^^^^^^^^^^^^^^^^^^^^^^^^^^^^^^^^^^^
sqlalchemy.exc.OperationalError: (psycopg2.OperationalError) could not translate host name "postgres" to address: Temporary failure in name resolution

(Background on this error at: https://sqlalche.me/e/14/e3q8)
[2025-03-11T09:02:45.127+0000] {job.py:254} ERROR - Job heartbeat failed with error. Scheduler is in unhealthy state
[2025-03-11T09:03:02.428+0000] {job.py:229} INFO - Heartbeat recovered after 39.77 seconds
[2025-03-11T09:03:02.850+0000] {connectionpool.py:868} WARNING - Retrying (Retry(total=3, connect=4, read=4, redirect=None, status=None)) after connection broken by 'NameResolutionError("<urllib3.connection.HTTPSConnection object at 0x7f729bbe6b70>: Failed to resolve 'tiki.vn' ([Errno -3] Temporary failure in name resolution)")': /api/v2/products/275589968
[2025-03-11T09:03:17.755+0000] {tiki_extract_dag.py:183} INFO - Extracted page 2/9 for category dien-thoai-may-tinh-bang, total items: 80
[2025-03-11T09:03:34.379+0000] {tiki_extract_dag.py:163} INFO - Calling API: https://tiki.vn/api/v2/products with params: {'page': 3, 'limit': 40, 'category': '1789'}
[2025-03-11T09:03:39.326+0000] {tiki_extract_dag.py:120} ERROR - Error fetching details for product 275621214 on attempt 1/3: Expecting value: line 1 column 1 (char 0)
[2025-03-11T09:03:56.211+0000] {tiki_extract_dag.py:120} ERROR - Error fetching details for product 275621214 on attempt 2/3: Expecting value: line 1 column 1 (char 0)
[2025-03-11T09:03:57.613+0000] {job.py:229} INFO - Heartbeat recovered after 19.68 seconds
[2025-03-11T09:04:01.457+0000] {tiki_extract_dag.py:120} ERROR - Error fetching details for product 275621214 on attempt 3/3: Expecting value: line 1 column 1 (char 0)
[2025-03-11T09:04:01.605+0000] {tiki_extract_dag.py:120} ERROR - Error fetching details for product 275335546 on attempt 1/3: Expecting value: line 1 column 1 (char 0)
[2025-03-11T09:04:18.940+0000] {tiki_extract_dag.py:183} INFO - Extracted page 3/9 for category dien-thoai-may-tinh-bang, total items: 120
[2025-03-11T09:04:37.784+0000] {tiki_extract_dag.py:163} INFO - Calling API: https://tiki.vn/api/v2/products with params: {'page': 4, 'limit': 40, 'category': '1789'}
[2025-03-11T09:04:51.410+0000] {tiki_extract_dag.py:120} ERROR - Error fetching details for product 118486668 on attempt 1/3: Expecting value: line 1 column 1 (char 0)
[2025-03-11T09:04:57.713+0000] {tiki_extract_dag.py:120} ERROR - Error fetching details for product 118486668 on attempt 2/3: Expecting value: line 1 column 1 (char 0)
[2025-03-11T09:05:05.145+0000] {tiki_extract_dag.py:183} INFO - Extracted page 4/9 for category dien-thoai-may-tinh-bang, total items: 160
[2025-03-11T09:05:21.378+0000] {tiki_extract_dag.py:163} INFO - Calling API: https://tiki.vn/api/v2/products with params: {'page': 5, 'limit': 40, 'category': '1789'}
[2025-03-11T09:05:35.755+0000] {tiki_extract_dag.py:183} INFO - Extracted page 5/9 for category dien-thoai-may-tinh-bang, total items: 200
[2025-03-11T09:05:51.882+0000] {tiki_extract_dag.py:163} INFO - Calling API: https://tiki.vn/api/v2/products with params: {'page': 6, 'limit': 40, 'category': '1789'}
[2025-03-11T09:05:52.027+0000] {tiki_extract_dag.py:186} ERROR - API error at page 6 in category dien-thoai-may-tinh-bang on attempt 1/3: Expecting value: line 1 column 1 (char 0)
[2025-03-11T09:05:57.649+0000] {tiki_extract_dag.py:186} ERROR - API error at page 6 in category dien-thoai-may-tinh-bang on attempt 2/3: Expecting value: line 1 column 1 (char 0)
[2025-03-11T09:06:17.919+0000] {tiki_extract_dag.py:183} INFO - Extracted page 6/9 for category dien-thoai-may-tinh-bang, total items: 240
[2025-03-11T09:06:37.282+0000] {tiki_extract_dag.py:163} INFO - Calling API: https://tiki.vn/api/v2/products with params: {'page': 7, 'limit': 40, 'category': '1789'}
[2025-03-11T09:06:48.265+0000] {tiki_extract_dag.py:120} ERROR - Error fetching details for product 270791102 on attempt 1/3: Expecting value: line 1 column 1 (char 0)
[2025-03-11T09:06:56.026+0000] {tiki_extract_dag.py:120} ERROR - Error fetching details for product 270791102 on attempt 2/3: Expecting value: line 1 column 1 (char 0)
