[2025-03-11T18:08:54.640+0000] {local_task_job_runner.py:123} INFO - ::group::Pre task execution logs
[2025-03-11T18:08:54.674+0000] {taskinstance.py:2614} INFO - Dependencies all met for dep_context=non-requeueable deps ti=<TaskInstance: tiki_schema_management_dag.create_dataset_and_tables manual__2025-03-11T18:08:50.397454+00:00 [queued]>
[2025-03-11T18:08:54.692+0000] {taskinstance.py:2614} INFO - Dependencies all met for dep_context=requeueable deps ti=<TaskInstance: tiki_schema_management_dag.create_dataset_and_tables manual__2025-03-11T18:08:50.397454+00:00 [queued]>
[2025-03-11T18:08:54.694+0000] {taskinstance.py:2867} INFO - Starting attempt 1 of 4
[2025-03-11T18:08:54.723+0000] {taskinstance.py:2890} INFO - Executing <Task(PythonOperator): create_dataset_and_tables> on 2025-03-11 18:08:50.397454+00:00
[2025-03-11T18:08:54.741+0000] {warnings.py:112} WARNING - /home/***/.local/lib/python3.12/site-packages/***/task/task_runner/standard_task_runner.py:70: DeprecationWarning: This process (pid=1325) is multi-threaded, use of fork() may lead to deadlocks in the child.
  pid = os.fork()

[2025-03-11T18:08:54.743+0000] {standard_task_runner.py:72} INFO - Started process 1334 to run task
[2025-03-11T18:08:54.744+0000] {standard_task_runner.py:104} INFO - Running: ['***', 'tasks', 'run', 'tiki_schema_management_dag', 'create_dataset_and_tables', 'manual__2025-03-11T18:08:50.397454+00:00', '--job-id', '627', '--raw', '--subdir', 'DAGS_FOLDER/tiki_schema_management_dag.py', '--cfg-path', '/tmp/tmpdjjzx1tq']
[2025-03-11T18:08:54.747+0000] {standard_task_runner.py:105} INFO - Job 627: Subtask create_dataset_and_tables
[2025-03-11T18:08:54.833+0000] {task_command.py:467} INFO - Running <TaskInstance: tiki_schema_management_dag.create_dataset_and_tables manual__2025-03-11T18:08:50.397454+00:00 [running]> on host 5c8190d7da62
[2025-03-11T18:08:55.000+0000] {taskinstance.py:3134} INFO - Exporting env vars: AIRFLOW_CTX_DAG_OWNER='***' AIRFLOW_CTX_DAG_ID='tiki_schema_management_dag' AIRFLOW_CTX_TASK_ID='create_dataset_and_tables' AIRFLOW_CTX_EXECUTION_DATE='2025-03-11T18:08:50.397454+00:00' AIRFLOW_CTX_TRY_NUMBER='1' AIRFLOW_CTX_DAG_RUN_ID='manual__2025-03-11T18:08:50.397454+00:00'
[2025-03-11T18:08:55.002+0000] {logging_mixin.py:190} INFO - Task instance is in running state
[2025-03-11T18:08:55.003+0000] {logging_mixin.py:190} INFO -  Previous state of the Task instance: queued
[2025-03-11T18:08:55.004+0000] {logging_mixin.py:190} INFO - Current task name:create_dataset_and_tables state:running start_date:2025-03-11 18:08:54.675621+00:00
[2025-03-11T18:08:55.005+0000] {logging_mixin.py:190} INFO - Dag name:tiki_schema_management_dag and current dag run status:running
[2025-03-11T18:08:55.006+0000] {taskinstance.py:732} INFO - ::endgroup::
[2025-03-11T18:08:56.077+0000] {tiki_schema_management_dag.py:27} INFO - Dataset tiki_data already exists
[2025-03-11T18:08:56.481+0000] {tiki_schema_management_dag.py:93} INFO - Table Fact_Sales already exists, checking schema...
[2025-03-11T18:08:56.949+0000] {tiki_schema_management_dag.py:98} INFO - Updating schema for Fact_Sales
[2025-03-11T18:08:57.767+0000] {taskinstance.py:3313} ERROR - Task failed with exception
Traceback (most recent call last):
  File "/home/airflow/.local/lib/python3.12/site-packages/airflow/models/taskinstance.py", line 768, in _execute_task
    result = _execute_callable(context=context, **execute_callable_kwargs)
             ^^^^^^^^^^^^^^^^^^^^^^^^^^^^^^^^^^^^^^^^^^^^^^^^^^^^^^^^^^^^^
  File "/home/airflow/.local/lib/python3.12/site-packages/airflow/models/taskinstance.py", line 734, in _execute_callable
    return ExecutionCallableRunner(
           ^^^^^^^^^^^^^^^^^^^^^^^^
  File "/home/airflow/.local/lib/python3.12/site-packages/airflow/utils/operator_helpers.py", line 252, in run
    return self.func(*args, **kwargs)
           ^^^^^^^^^^^^^^^^^^^^^^^^^^
  File "/home/airflow/.local/lib/python3.12/site-packages/airflow/models/baseoperator.py", line 424, in wrapper
    return func(self, *args, **kwargs)
           ^^^^^^^^^^^^^^^^^^^^^^^^^^^
  File "/home/airflow/.local/lib/python3.12/site-packages/airflow/operators/python.py", line 238, in execute
    return_value = self.execute_callable()
                   ^^^^^^^^^^^^^^^^^^^^^^^
  File "/home/airflow/.local/lib/python3.12/site-packages/airflow/operators/python.py", line 256, in execute_callable
    return runner.run(*self.op_args, **self.op_kwargs)
           ^^^^^^^^^^^^^^^^^^^^^^^^^^^^^^^^^^^^^^^^^^^
  File "/home/airflow/.local/lib/python3.12/site-packages/airflow/utils/operator_helpers.py", line 252, in run
    return self.func(*args, **kwargs)
           ^^^^^^^^^^^^^^^^^^^^^^^^^^
  File "/opt/airflow/dags/tiki_schema_management_dag.py", line 103, in create_dataset_and_tables
    bq_client.create_table(table)
  File "/home/airflow/.local/lib/python3.12/site-packages/google/cloud/bigquery/client.py", line 797, in create_table
    api_response = self._call_api(
                   ^^^^^^^^^^^^^^^
  File "/home/airflow/.local/lib/python3.12/site-packages/google/cloud/bigquery/client.py", line 831, in _call_api
    return call()
           ^^^^^^
  File "/home/airflow/.local/lib/python3.12/site-packages/google/api_core/retry/retry_unary.py", line 293, in retry_wrapped_func
    return retry_target(
           ^^^^^^^^^^^^^
  File "/home/airflow/.local/lib/python3.12/site-packages/google/api_core/retry/retry_unary.py", line 153, in retry_target
    _retry_error_helper(
  File "/home/airflow/.local/lib/python3.12/site-packages/google/api_core/retry/retry_base.py", line 212, in _retry_error_helper
    raise final_exc from source_exc
  File "/home/airflow/.local/lib/python3.12/site-packages/google/api_core/retry/retry_unary.py", line 144, in retry_target
    result = target()
             ^^^^^^^^
  File "/home/airflow/.local/lib/python3.12/site-packages/google/cloud/_http/__init__.py", line 494, in api_request
    raise exceptions.from_http_response(response)
google.api_core.exceptions.Conflict: 409 POST https://bigquery.googleapis.com/bigquery/v2/projects/vietadc/datasets/tiki_data/tables?prettyPrint=false: Already Exists: Table vietadc:tiki_data.Fact_Sales
[2025-03-11T18:08:57.802+0000] {logging_mixin.py:190} INFO - Task instance in failure state
[2025-03-11T18:08:57.802+0000] {logging_mixin.py:190} INFO - Task start:2025-03-11 18:08:54.675621+00:00 end:2025-03-11 18:08:57.801286+00:00 duration:3.125665
[2025-03-11T18:08:57.803+0000] {logging_mixin.py:190} INFO - Task:<Task(PythonOperator): create_dataset_and_tables> dag:<DAG: tiki_schema_management_dag> dagrun:<DagRun tiki_schema_management_dag @ 2025-03-11 18:08:50.397454+00:00: manual__2025-03-11T18:08:50.397454+00:00, state:running, queued_at: 2025-03-11 18:08:50.625463+00:00. externally triggered: True>
[2025-03-11T18:08:57.804+0000] {logging_mixin.py:190} INFO - Failure caused by 409 POST https://bigquery.googleapis.com/bigquery/v2/projects/vietadc/datasets/tiki_data/tables?prettyPrint=false: Already Exists: Table vietadc:tiki_data.Fact_Sales
[2025-03-11T18:08:57.804+0000] {taskinstance.py:1226} INFO - Marking task as UP_FOR_RETRY. dag_id=tiki_schema_management_dag, task_id=create_dataset_and_tables, run_id=manual__2025-03-11T18:08:50.397454+00:00, execution_date=20250311T180850, start_date=20250311T180854, end_date=20250311T180857
[2025-03-11T18:08:57.846+0000] {taskinstance.py:341} INFO - ::group::Post task execution logs
[2025-03-11T18:08:57.847+0000] {standard_task_runner.py:124} ERROR - Failed to execute job 627 for task create_dataset_and_tables (409 POST https://bigquery.googleapis.com/bigquery/v2/projects/vietadc/datasets/tiki_data/tables?prettyPrint=false: Already Exists: Table vietadc:tiki_data.Fact_Sales; 1334)
Traceback (most recent call last):
  File "/home/airflow/.local/lib/python3.12/site-packages/airflow/task/task_runner/standard_task_runner.py", line 117, in _start_by_fork
    ret = args.func(args, dag=self.dag)
          ^^^^^^^^^^^^^^^^^^^^^^^^^^^^^
  File "/home/airflow/.local/lib/python3.12/site-packages/airflow/cli/cli_config.py", line 49, in command
    return func(*args, **kwargs)
           ^^^^^^^^^^^^^^^^^^^^^
  File "/home/airflow/.local/lib/python3.12/site-packages/airflow/utils/cli.py", line 116, in wrapper
    return f(*args, **kwargs)
           ^^^^^^^^^^^^^^^^^^
  File "/home/airflow/.local/lib/python3.12/site-packages/airflow/cli/commands/task_command.py", line 483, in task_run
    task_return_code = _run_task_by_selected_method(args, _dag, ti)
                       ^^^^^^^^^^^^^^^^^^^^^^^^^^^^^^^^^^^^^^^^^^^^
  File "/home/airflow/.local/lib/python3.12/site-packages/airflow/cli/commands/task_command.py", line 256, in _run_task_by_selected_method
    return _run_raw_task(args, ti)
           ^^^^^^^^^^^^^^^^^^^^^^^
  File "/home/airflow/.local/lib/python3.12/site-packages/airflow/cli/commands/task_command.py", line 341, in _run_raw_task
    return ti._run_raw_task(
           ^^^^^^^^^^^^^^^^^
  File "/home/airflow/.local/lib/python3.12/site-packages/airflow/utils/session.py", line 97, in wrapper
    return func(*args, session=session, **kwargs)
           ^^^^^^^^^^^^^^^^^^^^^^^^^^^^^^^^^^^^^^
  File "/home/airflow/.local/lib/python3.12/site-packages/airflow/models/taskinstance.py", line 3006, in _run_raw_task
    return _run_raw_task(
           ^^^^^^^^^^^^^^
  File "/home/airflow/.local/lib/python3.12/site-packages/airflow/models/taskinstance.py", line 274, in _run_raw_task
    TaskInstance._execute_task_with_callbacks(
  File "/home/airflow/.local/lib/python3.12/site-packages/airflow/models/taskinstance.py", line 3161, in _execute_task_with_callbacks
    result = self._execute_task(context, task_orig)
             ^^^^^^^^^^^^^^^^^^^^^^^^^^^^^^^^^^^^^^
  File "/home/airflow/.local/lib/python3.12/site-packages/airflow/models/taskinstance.py", line 3185, in _execute_task
    return _execute_task(self, context, task_orig)
           ^^^^^^^^^^^^^^^^^^^^^^^^^^^^^^^^^^^^^^^
  File "/home/airflow/.local/lib/python3.12/site-packages/airflow/models/taskinstance.py", line 768, in _execute_task
    result = _execute_callable(context=context, **execute_callable_kwargs)
             ^^^^^^^^^^^^^^^^^^^^^^^^^^^^^^^^^^^^^^^^^^^^^^^^^^^^^^^^^^^^^
  File "/home/airflow/.local/lib/python3.12/site-packages/airflow/models/taskinstance.py", line 734, in _execute_callable
    return ExecutionCallableRunner(
           ^^^^^^^^^^^^^^^^^^^^^^^^
  File "/home/airflow/.local/lib/python3.12/site-packages/airflow/utils/operator_helpers.py", line 252, in run
    return self.func(*args, **kwargs)
           ^^^^^^^^^^^^^^^^^^^^^^^^^^
  File "/home/airflow/.local/lib/python3.12/site-packages/airflow/models/baseoperator.py", line 424, in wrapper
    return func(self, *args, **kwargs)
           ^^^^^^^^^^^^^^^^^^^^^^^^^^^
  File "/home/airflow/.local/lib/python3.12/site-packages/airflow/operators/python.py", line 238, in execute
    return_value = self.execute_callable()
                   ^^^^^^^^^^^^^^^^^^^^^^^
  File "/home/airflow/.local/lib/python3.12/site-packages/airflow/operators/python.py", line 256, in execute_callable
    return runner.run(*self.op_args, **self.op_kwargs)
           ^^^^^^^^^^^^^^^^^^^^^^^^^^^^^^^^^^^^^^^^^^^
  File "/home/airflow/.local/lib/python3.12/site-packages/airflow/utils/operator_helpers.py", line 252, in run
    return self.func(*args, **kwargs)
           ^^^^^^^^^^^^^^^^^^^^^^^^^^
  File "/opt/airflow/dags/tiki_schema_management_dag.py", line 103, in create_dataset_and_tables
    bq_client.create_table(table)
  File "/home/airflow/.local/lib/python3.12/site-packages/google/cloud/bigquery/client.py", line 797, in create_table
    api_response = self._call_api(
                   ^^^^^^^^^^^^^^^
  File "/home/airflow/.local/lib/python3.12/site-packages/google/cloud/bigquery/client.py", line 831, in _call_api
    return call()
           ^^^^^^
  File "/home/airflow/.local/lib/python3.12/site-packages/google/api_core/retry/retry_unary.py", line 293, in retry_wrapped_func
    return retry_target(
           ^^^^^^^^^^^^^
  File "/home/airflow/.local/lib/python3.12/site-packages/google/api_core/retry/retry_unary.py", line 153, in retry_target
    _retry_error_helper(
  File "/home/airflow/.local/lib/python3.12/site-packages/google/api_core/retry/retry_base.py", line 212, in _retry_error_helper
    raise final_exc from source_exc
  File "/home/airflow/.local/lib/python3.12/site-packages/google/api_core/retry/retry_unary.py", line 144, in retry_target
    result = target()
             ^^^^^^^^
  File "/home/airflow/.local/lib/python3.12/site-packages/google/cloud/_http/__init__.py", line 494, in api_request
    raise exceptions.from_http_response(response)
google.api_core.exceptions.Conflict: 409 POST https://bigquery.googleapis.com/bigquery/v2/projects/vietadc/datasets/tiki_data/tables?prettyPrint=false: Already Exists: Table vietadc:tiki_data.Fact_Sales
[2025-03-11T18:08:57.892+0000] {local_task_job_runner.py:266} INFO - Task exited with return code 1
[2025-03-11T18:08:57.921+0000] {taskinstance.py:3901} INFO - 0 downstream tasks scheduled from follow-on schedule check
[2025-03-11T18:08:57.924+0000] {local_task_job_runner.py:245} INFO - ::endgroup::
