[2025-03-12T08:10:44.717+0000] {local_task_job_runner.py:123} INFO - ::group::Pre task execution logs
[2025-03-12T08:10:44.742+0000] {taskinstance.py:2614} INFO - Dependencies all met for dep_context=non-requeueable deps ti=<TaskInstance: tiki_transform_dag.transform_data manual__2025-03-12T08:10:41.951996+00:00 [queued]>
[2025-03-12T08:10:44.752+0000] {taskinstance.py:2614} INFO - Dependencies all met for dep_context=requeueable deps ti=<TaskInstance: tiki_transform_dag.transform_data manual__2025-03-12T08:10:41.951996+00:00 [queued]>
[2025-03-12T08:10:44.753+0000] {taskinstance.py:2867} INFO - Starting attempt 1 of 4
[2025-03-12T08:10:44.771+0000] {taskinstance.py:2890} INFO - Executing <Task(PythonOperator): transform_data> on 2025-03-12 08:10:41.951996+00:00
[2025-03-12T08:10:44.782+0000] {warnings.py:112} WARNING - /home/***/.local/lib/python3.12/site-packages/***/task/task_runner/standard_task_runner.py:70: DeprecationWarning: This process (pid=921) is multi-threaded, use of fork() may lead to deadlocks in the child.
  pid = os.fork()

[2025-03-12T08:10:44.784+0000] {standard_task_runner.py:72} INFO - Started process 923 to run task
[2025-03-12T08:10:44.785+0000] {standard_task_runner.py:104} INFO - Running: ['***', 'tasks', 'run', 'tiki_transform_dag', 'transform_data', 'manual__2025-03-12T08:10:41.951996+00:00', '--job-id', '713', '--raw', '--subdir', 'DAGS_FOLDER/tiki_transform_dag.py', '--cfg-path', '/tmp/tmp60xjbbsa']
[2025-03-12T08:10:44.786+0000] {standard_task_runner.py:105} INFO - Job 713: Subtask transform_data
[2025-03-12T08:10:44.853+0000] {task_command.py:467} INFO - Running <TaskInstance: tiki_transform_dag.transform_data manual__2025-03-12T08:10:41.951996+00:00 [running]> on host 3905098656d4
[2025-03-12T08:10:45.413+0000] {taskinstance.py:3134} INFO - Exporting env vars: AIRFLOW_CTX_DAG_OWNER='***' AIRFLOW_CTX_DAG_ID='tiki_transform_dag' AIRFLOW_CTX_TASK_ID='transform_data' AIRFLOW_CTX_EXECUTION_DATE='2025-03-12T08:10:41.951996+00:00' AIRFLOW_CTX_TRY_NUMBER='1' AIRFLOW_CTX_DAG_RUN_ID='manual__2025-03-12T08:10:41.951996+00:00'
[2025-03-12T08:10:45.415+0000] {logging_mixin.py:190} INFO - Task instance is in running state
[2025-03-12T08:10:45.415+0000] {logging_mixin.py:190} INFO -  Previous state of the Task instance: queued
[2025-03-12T08:10:45.416+0000] {logging_mixin.py:190} INFO - Current task name:transform_data state:running start_date:2025-03-12 08:10:44.742907+00:00
[2025-03-12T08:10:45.416+0000] {logging_mixin.py:190} INFO - Dag name:tiki_transform_dag and current dag run status:running
[2025-03-12T08:10:45.417+0000] {taskinstance.py:732} INFO - ::endgroup::
[2025-03-12T08:10:57.091+0000] {tiki_transform_dag.py:96} INFO - Loaded raw data from tiki-pipeline/tiki_raw_data/raw_dien-gia-dung_20250312_080050.json, 2000 rows
[2025-03-12T08:10:58.400+0000] {tiki_transform_dag.py:96} INFO - Loaded raw data from tiki-pipeline/tiki_raw_data/raw_dien-thoai-may-tinh-bang_20250312_074251.json, 361 rows
[2025-03-12T08:11:02.865+0000] {tiki_transform_dag.py:96} INFO - Loaded raw data from tiki-pipeline/tiki_raw_data/raw_dien-tu-dien-lanh_20250312_080131.json, 2000 rows
[2025-03-12T08:11:07.986+0000] {tiki_transform_dag.py:96} INFO - Loaded raw data from tiki-pipeline/tiki_raw_data/raw_dong-ho-va-trang-suc_20250312_074821.json, 2000 rows
[2025-03-12T08:11:12.497+0000] {tiki_transform_dag.py:96} INFO - Loaded raw data from tiki-pipeline/tiki_raw_data/raw_lam-dep-suc-khoe_20250312_074839.json, 2000 rows
[2025-03-12T08:11:21.595+0000] {tiki_transform_dag.py:96} INFO - Loaded raw data from tiki-pipeline/tiki_raw_data/raw_laptop-may-vi-tinh-linh-kien_20250312_080208.json, 2000 rows
[2025-03-12T08:11:41.971+0000] {tiki_transform_dag.py:96} INFO - Loaded raw data from tiki-pipeline/tiki_raw_data/raw_sach_20250312_074828.json, 2000 rows
[2025-03-12T08:11:54.107+0000] {tiki_transform_dag.py:96} INFO - Loaded raw data from tiki-pipeline/tiki_raw_data/raw_the-thao-da-ngoai_20250312_074838.json, 2000 rows
[2025-03-12T08:12:02.720+0000] {tiki_transform_dag.py:96} INFO - Loaded raw data from tiki-pipeline/tiki_raw_data/raw_thiet-bi-kts-phu-kien-so_20250312_080232.json, 2000 rows
[2025-03-12T08:12:10.683+0000] {tiki_transform_dag.py:96} INFO - Loaded raw data from tiki-pipeline/tiki_raw_data/raw_thoi-trang-nam_20250312_080215.json, 2000 rows
[2025-03-12T08:12:19.404+0000] {tiki_transform_dag.py:96} INFO - Loaded raw data from tiki-pipeline/tiki_raw_data/raw_thoi-trang-nu_20250312_080217.json, 2000 rows
[2025-03-12T08:12:19.448+0000] {tiki_transform_dag.py:106} INFO - After deduplication across all categories: 20357 rows
[2025-03-12T08:12:20.110+0000] {tiki_transform_dag.py:62} INFO - Data cleaning completed
[2025-03-12T08:12:20.352+0000] {tiki_transform_dag.py:45} INFO - Data validation passed
[2025-03-12T08:12:23.226+0000] {tiki_transform_dag.py:195} INFO - Saved fact_sales to tiki-pipeline/tiki_transformed_data/fact_sales_20250312_081220.csv
[2025-03-12T08:13:24.403+0000] {taskinstance.py:3313} ERROR - Task failed with exception
Traceback (most recent call last):
  File "/home/airflow/.local/lib/python3.12/site-packages/urllib3/connectionpool.py", line 787, in urlopen
    response = self._make_request(
               ^^^^^^^^^^^^^^^^^^^
  File "/home/airflow/.local/lib/python3.12/site-packages/urllib3/connectionpool.py", line 493, in _make_request
    conn.request(
  File "/home/airflow/.local/lib/python3.12/site-packages/urllib3/connection.py", line 459, in request
    self.send(chunk)
  File "/usr/local/lib/python3.12/http/client.py", line 1057, in send
    self.sock.sendall(data)
  File "/usr/local/lib/python3.12/ssl.py", line 1210, in sendall
    v = self.send(byte_view[count:])
        ^^^^^^^^^^^^^^^^^^^^^^^^^^^^
  File "/usr/local/lib/python3.12/ssl.py", line 1179, in send
    return self._sslobj.write(data)
           ^^^^^^^^^^^^^^^^^^^^^^^^
TimeoutError: The write operation timed out

During handling of the above exception, another exception occurred:

Traceback (most recent call last):
  File "/home/airflow/.local/lib/python3.12/site-packages/requests/adapters.py", line 667, in send
    resp = conn.urlopen(
           ^^^^^^^^^^^^^
  File "/home/airflow/.local/lib/python3.12/site-packages/urllib3/connectionpool.py", line 841, in urlopen
    retries = retries.increment(
              ^^^^^^^^^^^^^^^^^^
  File "/home/airflow/.local/lib/python3.12/site-packages/urllib3/util/retry.py", line 474, in increment
    raise reraise(type(error), error, _stacktrace)
          ^^^^^^^^^^^^^^^^^^^^^^^^^^^^^^^^^^^^^^^^
  File "/home/airflow/.local/lib/python3.12/site-packages/urllib3/util/util.py", line 38, in reraise
    raise value.with_traceback(tb)
  File "/home/airflow/.local/lib/python3.12/site-packages/urllib3/connectionpool.py", line 787, in urlopen
    response = self._make_request(
               ^^^^^^^^^^^^^^^^^^^
  File "/home/airflow/.local/lib/python3.12/site-packages/urllib3/connectionpool.py", line 493, in _make_request
    conn.request(
  File "/home/airflow/.local/lib/python3.12/site-packages/urllib3/connection.py", line 459, in request
    self.send(chunk)
  File "/usr/local/lib/python3.12/http/client.py", line 1057, in send
    self.sock.sendall(data)
  File "/usr/local/lib/python3.12/ssl.py", line 1210, in sendall
    v = self.send(byte_view[count:])
        ^^^^^^^^^^^^^^^^^^^^^^^^^^^^
  File "/usr/local/lib/python3.12/ssl.py", line 1179, in send
    return self._sslobj.write(data)
           ^^^^^^^^^^^^^^^^^^^^^^^^
urllib3.exceptions.ProtocolError: ('Connection aborted.', TimeoutError('The write operation timed out'))

During handling of the above exception, another exception occurred:

Traceback (most recent call last):
  File "/home/airflow/.local/lib/python3.12/site-packages/airflow/models/taskinstance.py", line 768, in _execute_task
    result = _execute_callable(context=context, **execute_callable_kwargs)
             ^^^^^^^^^^^^^^^^^^^^^^^^^^^^^^^^^^^^^^^^^^^^^^^^^^^^^^^^^^^^^
  File "/home/airflow/.local/lib/python3.12/site-packages/airflow/models/taskinstance.py", line 734, in _execute_callable
    return ExecutionCallableRunner(
           ^^^^^^^^^^^^^^^^^^^^^^^^
  File "/home/airflow/.local/lib/python3.12/site-packages/airflow/utils/operator_helpers.py", line 252, in run
    return self.func(*args, **kwargs)
           ^^^^^^^^^^^^^^^^^^^^^^^^^^
  File "/home/airflow/.local/lib/python3.12/site-packages/airflow/models/baseoperator.py", line 424, in wrapper
    return func(self, *args, **kwargs)
           ^^^^^^^^^^^^^^^^^^^^^^^^^^^
  File "/home/airflow/.local/lib/python3.12/site-packages/airflow/operators/python.py", line 238, in execute
    return_value = self.execute_callable()
                   ^^^^^^^^^^^^^^^^^^^^^^^
  File "/home/airflow/.local/lib/python3.12/site-packages/airflow/operators/python.py", line 256, in execute_callable
    return runner.run(*self.op_args, **self.op_kwargs)
           ^^^^^^^^^^^^^^^^^^^^^^^^^^^^^^^^^^^^^^^^^^^
  File "/home/airflow/.local/lib/python3.12/site-packages/airflow/utils/operator_helpers.py", line 252, in run
    return self.func(*args, **kwargs)
           ^^^^^^^^^^^^^^^^^^^^^^^^^^
  File "/opt/airflow/dags/tiki_transform_dag.py", line 193, in transform_data
  File "/usr/local/lib/python3.12/contextlib.py", line 81, in inner
    return func(*args, **kwds)
           ^^^^^^^^^^^^^^^^^^^
  File "/home/airflow/.local/lib/python3.12/site-packages/google/cloud/storage/blob.py", line 3128, in upload_from_string
    self.upload_from_file(
  File "/usr/local/lib/python3.12/contextlib.py", line 81, in inner
    return func(*args, **kwds)
           ^^^^^^^^^^^^^^^^^^^
  File "/home/airflow/.local/lib/python3.12/site-packages/google/cloud/storage/blob.py", line 2851, in upload_from_file
    self._prep_and_do_upload(
  File "/home/airflow/.local/lib/python3.12/site-packages/google/cloud/storage/blob.py", line 2700, in _prep_and_do_upload
    created_json = self._do_upload(
                   ^^^^^^^^^^^^^^^^
  File "/home/airflow/.local/lib/python3.12/site-packages/google/cloud/storage/blob.py", line 2523, in _do_upload
    response = self._do_resumable_upload(
               ^^^^^^^^^^^^^^^^^^^^^^^^^^
  File "/home/airflow/.local/lib/python3.12/site-packages/google/cloud/storage/blob.py", line 2359, in _do_resumable_upload
    response = upload.transmit_next_chunk(transport, timeout=timeout)
               ^^^^^^^^^^^^^^^^^^^^^^^^^^^^^^^^^^^^^^^^^^^^^^^^^^^^^^
  File "/home/airflow/.local/lib/python3.12/site-packages/google/resumable_media/requests/upload.py", line 515, in transmit_next_chunk
    return _request_helpers.wait_and_retry(
           ^^^^^^^^^^^^^^^^^^^^^^^^^^^^^^^^
  File "/home/airflow/.local/lib/python3.12/site-packages/google/resumable_media/requests/_request_helpers.py", line 178, in wait_and_retry
    raise error
  File "/home/airflow/.local/lib/python3.12/site-packages/google/resumable_media/requests/_request_helpers.py", line 155, in wait_and_retry
    response = func()
               ^^^^^^
  File "/home/airflow/.local/lib/python3.12/site-packages/google/resumable_media/requests/upload.py", line 507, in retriable_request
    result = transport.request(
             ^^^^^^^^^^^^^^^^^^
  File "/home/airflow/.local/lib/python3.12/site-packages/google/auth/transport/requests.py", line 537, in request
    response = super(AuthorizedSession, self).request(
               ^^^^^^^^^^^^^^^^^^^^^^^^^^^^^^^^^^^^^^^
  File "/home/airflow/.local/lib/python3.12/site-packages/requests/sessions.py", line 589, in request
    resp = self.send(prep, **send_kwargs)
           ^^^^^^^^^^^^^^^^^^^^^^^^^^^^^^
  File "/home/airflow/.local/lib/python3.12/site-packages/requests/sessions.py", line 703, in send
    r = adapter.send(request, **kwargs)
        ^^^^^^^^^^^^^^^^^^^^^^^^^^^^^^^
  File "/home/airflow/.local/lib/python3.12/site-packages/requests/adapters.py", line 682, in send
    raise ConnectionError(err, request=request)
requests.exceptions.ConnectionError: ('Connection aborted.', TimeoutError('The write operation timed out'))
[2025-03-12T08:13:24.448+0000] {logging_mixin.py:190} INFO - Task instance in failure state
[2025-03-12T08:13:24.449+0000] {logging_mixin.py:190} INFO - Task start:2025-03-12 08:10:44.742907+00:00 end:2025-03-12 08:13:24.447940+00:00 duration:159.705033
[2025-03-12T08:13:24.449+0000] {logging_mixin.py:190} INFO - Task:<Task(PythonOperator): transform_data> dag:<DAG: tiki_transform_dag> dagrun:<DagRun tiki_transform_dag @ 2025-03-12 08:10:41.951996+00:00: manual__2025-03-12T08:10:41.951996+00:00, state:running, queued_at: 2025-03-12 08:10:41.981500+00:00. externally triggered: True>
[2025-03-12T08:13:24.450+0000] {logging_mixin.py:190} INFO - Failure caused by ('Connection aborted.', TimeoutError('The write operation timed out'))
[2025-03-12T08:13:24.451+0000] {taskinstance.py:1226} INFO - Marking task as UP_FOR_RETRY. dag_id=tiki_transform_dag, task_id=transform_data, run_id=manual__2025-03-12T08:10:41.951996+00:00, execution_date=20250312T081041, start_date=20250312T081044, end_date=20250312T081324
[2025-03-12T08:13:24.493+0000] {taskinstance.py:341} INFO - ::group::Post task execution logs
[2025-03-12T08:13:24.494+0000] {standard_task_runner.py:124} ERROR - Failed to execute job 713 for task transform_data (('Connection aborted.', TimeoutError('The write operation timed out')); 923)
Traceback (most recent call last):
  File "/home/airflow/.local/lib/python3.12/site-packages/urllib3/connectionpool.py", line 787, in urlopen
    response = self._make_request(
               ^^^^^^^^^^^^^^^^^^^
  File "/home/airflow/.local/lib/python3.12/site-packages/urllib3/connectionpool.py", line 493, in _make_request
    conn.request(
  File "/home/airflow/.local/lib/python3.12/site-packages/urllib3/connection.py", line 459, in request
    self.send(chunk)
  File "/usr/local/lib/python3.12/http/client.py", line 1057, in send
    self.sock.sendall(data)
  File "/usr/local/lib/python3.12/ssl.py", line 1210, in sendall
    v = self.send(byte_view[count:])
        ^^^^^^^^^^^^^^^^^^^^^^^^^^^^
  File "/usr/local/lib/python3.12/ssl.py", line 1179, in send
    return self._sslobj.write(data)
           ^^^^^^^^^^^^^^^^^^^^^^^^
TimeoutError: The write operation timed out

During handling of the above exception, another exception occurred:

Traceback (most recent call last):
  File "/home/airflow/.local/lib/python3.12/site-packages/requests/adapters.py", line 667, in send
    resp = conn.urlopen(
           ^^^^^^^^^^^^^
  File "/home/airflow/.local/lib/python3.12/site-packages/urllib3/connectionpool.py", line 841, in urlopen
    retries = retries.increment(
              ^^^^^^^^^^^^^^^^^^
  File "/home/airflow/.local/lib/python3.12/site-packages/urllib3/util/retry.py", line 474, in increment
    raise reraise(type(error), error, _stacktrace)
          ^^^^^^^^^^^^^^^^^^^^^^^^^^^^^^^^^^^^^^^^
  File "/home/airflow/.local/lib/python3.12/site-packages/urllib3/util/util.py", line 38, in reraise
    raise value.with_traceback(tb)
  File "/home/airflow/.local/lib/python3.12/site-packages/urllib3/connectionpool.py", line 787, in urlopen
    response = self._make_request(
               ^^^^^^^^^^^^^^^^^^^
  File "/home/airflow/.local/lib/python3.12/site-packages/urllib3/connectionpool.py", line 493, in _make_request
    conn.request(
  File "/home/airflow/.local/lib/python3.12/site-packages/urllib3/connection.py", line 459, in request
    self.send(chunk)
  File "/usr/local/lib/python3.12/http/client.py", line 1057, in send
    self.sock.sendall(data)
  File "/usr/local/lib/python3.12/ssl.py", line 1210, in sendall
    v = self.send(byte_view[count:])
        ^^^^^^^^^^^^^^^^^^^^^^^^^^^^
  File "/usr/local/lib/python3.12/ssl.py", line 1179, in send
    return self._sslobj.write(data)
           ^^^^^^^^^^^^^^^^^^^^^^^^
urllib3.exceptions.ProtocolError: ('Connection aborted.', TimeoutError('The write operation timed out'))

During handling of the above exception, another exception occurred:

Traceback (most recent call last):
  File "/home/airflow/.local/lib/python3.12/site-packages/airflow/task/task_runner/standard_task_runner.py", line 117, in _start_by_fork
    ret = args.func(args, dag=self.dag)
          ^^^^^^^^^^^^^^^^^^^^^^^^^^^^^
  File "/home/airflow/.local/lib/python3.12/site-packages/airflow/cli/cli_config.py", line 49, in command
    return func(*args, **kwargs)
           ^^^^^^^^^^^^^^^^^^^^^
  File "/home/airflow/.local/lib/python3.12/site-packages/airflow/utils/cli.py", line 116, in wrapper
    return f(*args, **kwargs)
           ^^^^^^^^^^^^^^^^^^
  File "/home/airflow/.local/lib/python3.12/site-packages/airflow/cli/commands/task_command.py", line 483, in task_run
    task_return_code = _run_task_by_selected_method(args, _dag, ti)
                       ^^^^^^^^^^^^^^^^^^^^^^^^^^^^^^^^^^^^^^^^^^^^
  File "/home/airflow/.local/lib/python3.12/site-packages/airflow/cli/commands/task_command.py", line 256, in _run_task_by_selected_method
    return _run_raw_task(args, ti)
           ^^^^^^^^^^^^^^^^^^^^^^^
  File "/home/airflow/.local/lib/python3.12/site-packages/airflow/cli/commands/task_command.py", line 341, in _run_raw_task
    return ti._run_raw_task(
           ^^^^^^^^^^^^^^^^^
  File "/home/airflow/.local/lib/python3.12/site-packages/airflow/utils/session.py", line 97, in wrapper
    return func(*args, session=session, **kwargs)
           ^^^^^^^^^^^^^^^^^^^^^^^^^^^^^^^^^^^^^^
  File "/home/airflow/.local/lib/python3.12/site-packages/airflow/models/taskinstance.py", line 3006, in _run_raw_task
    return _run_raw_task(
           ^^^^^^^^^^^^^^
  File "/home/airflow/.local/lib/python3.12/site-packages/airflow/models/taskinstance.py", line 274, in _run_raw_task
    TaskInstance._execute_task_with_callbacks(
  File "/home/airflow/.local/lib/python3.12/site-packages/airflow/models/taskinstance.py", line 3161, in _execute_task_with_callbacks
    result = self._execute_task(context, task_orig)
             ^^^^^^^^^^^^^^^^^^^^^^^^^^^^^^^^^^^^^^
  File "/home/airflow/.local/lib/python3.12/site-packages/airflow/models/taskinstance.py", line 3185, in _execute_task
    return _execute_task(self, context, task_orig)
           ^^^^^^^^^^^^^^^^^^^^^^^^^^^^^^^^^^^^^^^
  File "/home/airflow/.local/lib/python3.12/site-packages/airflow/models/taskinstance.py", line 768, in _execute_task
    result = _execute_callable(context=context, **execute_callable_kwargs)
             ^^^^^^^^^^^^^^^^^^^^^^^^^^^^^^^^^^^^^^^^^^^^^^^^^^^^^^^^^^^^^
  File "/home/airflow/.local/lib/python3.12/site-packages/airflow/models/taskinstance.py", line 734, in _execute_callable
    return ExecutionCallableRunner(
           ^^^^^^^^^^^^^^^^^^^^^^^^
  File "/home/airflow/.local/lib/python3.12/site-packages/airflow/utils/operator_helpers.py", line 252, in run
    return self.func(*args, **kwargs)
           ^^^^^^^^^^^^^^^^^^^^^^^^^^
  File "/home/airflow/.local/lib/python3.12/site-packages/airflow/models/baseoperator.py", line 424, in wrapper
    return func(self, *args, **kwargs)
           ^^^^^^^^^^^^^^^^^^^^^^^^^^^
  File "/home/airflow/.local/lib/python3.12/site-packages/airflow/operators/python.py", line 238, in execute
    return_value = self.execute_callable()
                   ^^^^^^^^^^^^^^^^^^^^^^^
  File "/home/airflow/.local/lib/python3.12/site-packages/airflow/operators/python.py", line 256, in execute_callable
    return runner.run(*self.op_args, **self.op_kwargs)
           ^^^^^^^^^^^^^^^^^^^^^^^^^^^^^^^^^^^^^^^^^^^
  File "/home/airflow/.local/lib/python3.12/site-packages/airflow/utils/operator_helpers.py", line 252, in run
    return self.func(*args, **kwargs)
           ^^^^^^^^^^^^^^^^^^^^^^^^^^
  File "/opt/airflow/dags/tiki_transform_dag.py", line 193, in transform_data
  File "/usr/local/lib/python3.12/contextlib.py", line 81, in inner
    return func(*args, **kwds)
           ^^^^^^^^^^^^^^^^^^^
  File "/home/airflow/.local/lib/python3.12/site-packages/google/cloud/storage/blob.py", line 3128, in upload_from_string
    self.upload_from_file(
  File "/usr/local/lib/python3.12/contextlib.py", line 81, in inner
    return func(*args, **kwds)
           ^^^^^^^^^^^^^^^^^^^
  File "/home/airflow/.local/lib/python3.12/site-packages/google/cloud/storage/blob.py", line 2851, in upload_from_file
    self._prep_and_do_upload(
  File "/home/airflow/.local/lib/python3.12/site-packages/google/cloud/storage/blob.py", line 2700, in _prep_and_do_upload
    created_json = self._do_upload(
                   ^^^^^^^^^^^^^^^^
  File "/home/airflow/.local/lib/python3.12/site-packages/google/cloud/storage/blob.py", line 2523, in _do_upload
    response = self._do_resumable_upload(
               ^^^^^^^^^^^^^^^^^^^^^^^^^^
  File "/home/airflow/.local/lib/python3.12/site-packages/google/cloud/storage/blob.py", line 2359, in _do_resumable_upload
    response = upload.transmit_next_chunk(transport, timeout=timeout)
               ^^^^^^^^^^^^^^^^^^^^^^^^^^^^^^^^^^^^^^^^^^^^^^^^^^^^^^
  File "/home/airflow/.local/lib/python3.12/site-packages/google/resumable_media/requests/upload.py", line 515, in transmit_next_chunk
    return _request_helpers.wait_and_retry(
           ^^^^^^^^^^^^^^^^^^^^^^^^^^^^^^^^
  File "/home/airflow/.local/lib/python3.12/site-packages/google/resumable_media/requests/_request_helpers.py", line 178, in wait_and_retry
    raise error
  File "/home/airflow/.local/lib/python3.12/site-packages/google/resumable_media/requests/_request_helpers.py", line 155, in wait_and_retry
    response = func()
               ^^^^^^
  File "/home/airflow/.local/lib/python3.12/site-packages/google/resumable_media/requests/upload.py", line 507, in retriable_request
    result = transport.request(
             ^^^^^^^^^^^^^^^^^^
  File "/home/airflow/.local/lib/python3.12/site-packages/google/auth/transport/requests.py", line 537, in request
    response = super(AuthorizedSession, self).request(
               ^^^^^^^^^^^^^^^^^^^^^^^^^^^^^^^^^^^^^^^
  File "/home/airflow/.local/lib/python3.12/site-packages/requests/sessions.py", line 589, in request
    resp = self.send(prep, **send_kwargs)
           ^^^^^^^^^^^^^^^^^^^^^^^^^^^^^^
  File "/home/airflow/.local/lib/python3.12/site-packages/requests/sessions.py", line 703, in send
    r = adapter.send(request, **kwargs)
        ^^^^^^^^^^^^^^^^^^^^^^^^^^^^^^^
  File "/home/airflow/.local/lib/python3.12/site-packages/requests/adapters.py", line 682, in send
    raise ConnectionError(err, request=request)
requests.exceptions.ConnectionError: ('Connection aborted.', TimeoutError('The write operation timed out'))
[2025-03-12T08:13:24.577+0000] {local_task_job_runner.py:266} INFO - Task exited with return code 1
[2025-03-12T08:13:24.602+0000] {taskinstance.py:3901} INFO - 0 downstream tasks scheduled from follow-on schedule check
[2025-03-12T08:13:24.605+0000] {local_task_job_runner.py:245} INFO - ::endgroup::
