[2025-03-07T21:25:20.964+0000] {local_task_job_runner.py:123} INFO - ::group::Pre task execution logs
[2025-03-07T21:25:20.986+0000] {taskinstance.py:2614} INFO - Dependencies all met for dep_context=non-requeueable deps ti=<TaskInstance: tiki_schema_management_dag.create_schema manual__2025-03-07T21:25:17.203713+00:00 [queued]>
[2025-03-07T21:25:20.996+0000] {taskinstance.py:2614} INFO - Dependencies all met for dep_context=requeueable deps ti=<TaskInstance: tiki_schema_management_dag.create_schema manual__2025-03-07T21:25:17.203713+00:00 [queued]>
[2025-03-07T21:25:20.997+0000] {taskinstance.py:2867} INFO - Starting attempt 1 of 1
[2025-03-07T21:25:21.191+0000] {taskinstance.py:2890} INFO - Executing <Task(PythonOperator): create_schema> on 2025-03-07 21:25:17.203713+00:00
[2025-03-07T21:25:21.201+0000] {warnings.py:112} WARNING - /home/***/.local/lib/python3.12/site-packages/***/task/task_runner/standard_task_runner.py:70: DeprecationWarning: This process (pid=288) is multi-threaded, use of fork() may lead to deadlocks in the child.
  pid = os.fork()

[2025-03-07T21:25:21.203+0000] {standard_task_runner.py:72} INFO - Started process 290 to run task
[2025-03-07T21:25:21.203+0000] {standard_task_runner.py:104} INFO - Running: ['***', 'tasks', 'run', 'tiki_schema_management_dag', 'create_schema', 'manual__2025-03-07T21:25:17.203713+00:00', '--job-id', '17', '--raw', '--subdir', 'DAGS_FOLDER/tiki_schema_management_dag.py', '--cfg-path', '/tmp/tmpy9hv_l0l']
[2025-03-07T21:25:21.205+0000] {standard_task_runner.py:105} INFO - Job 17: Subtask create_schema
[2025-03-07T21:25:21.258+0000] {task_command.py:467} INFO - Running <TaskInstance: tiki_schema_management_dag.create_schema manual__2025-03-07T21:25:17.203713+00:00 [running]> on host c541acbda8df
[2025-03-07T21:25:21.363+0000] {taskinstance.py:3134} INFO - Exporting env vars: AIRFLOW_CTX_DAG_OWNER='***' AIRFLOW_CTX_DAG_ID='tiki_schema_management_dag' AIRFLOW_CTX_TASK_ID='create_schema' AIRFLOW_CTX_EXECUTION_DATE='2025-03-07T21:25:17.203713+00:00' AIRFLOW_CTX_TRY_NUMBER='1' AIRFLOW_CTX_DAG_RUN_ID='manual__2025-03-07T21:25:17.203713+00:00'
[2025-03-07T21:25:21.364+0000] {logging_mixin.py:190} INFO - Task instance is in running state
[2025-03-07T21:25:21.365+0000] {logging_mixin.py:190} INFO -  Previous state of the Task instance: queued
[2025-03-07T21:25:21.365+0000] {logging_mixin.py:190} INFO - Current task name:create_schema state:running start_date:2025-03-07 21:25:20.986950+00:00
[2025-03-07T21:25:21.366+0000] {logging_mixin.py:190} INFO - Dag name:tiki_schema_management_dag and current dag run status:running
[2025-03-07T21:25:21.366+0000] {taskinstance.py:732} INFO - ::endgroup::
[2025-03-07T21:25:21.387+0000] {_metadata.py:142} WARNING - Compute Engine Metadata server unavailable on attempt 1 of 3. Reason: [Errno 111] Connection refused
[2025-03-07T21:25:22.367+0000] {_metadata.py:142} WARNING - Compute Engine Metadata server unavailable on attempt 2 of 3. Reason: [Errno 111] Connection refused
[2025-03-07T21:25:24.259+0000] {_metadata.py:142} WARNING - Compute Engine Metadata server unavailable on attempt 3 of 3. Reason: [Errno 111] Connection refused
[2025-03-07T21:25:24.260+0000] {_default.py:362} WARNING - Authentication failed using Compute Engine authentication due to unavailable metadata server.
[2025-03-07T21:25:24.261+0000] {taskinstance.py:3313} ERROR - Task failed with exception
Traceback (most recent call last):
  File "/home/airflow/.local/lib/python3.12/site-packages/airflow/models/taskinstance.py", line 768, in _execute_task
    result = _execute_callable(context=context, **execute_callable_kwargs)
             ^^^^^^^^^^^^^^^^^^^^^^^^^^^^^^^^^^^^^^^^^^^^^^^^^^^^^^^^^^^^^
  File "/home/airflow/.local/lib/python3.12/site-packages/airflow/models/taskinstance.py", line 734, in _execute_callable
    return ExecutionCallableRunner(
           ^^^^^^^^^^^^^^^^^^^^^^^^
  File "/home/airflow/.local/lib/python3.12/site-packages/airflow/utils/operator_helpers.py", line 252, in run
    return self.func(*args, **kwargs)
           ^^^^^^^^^^^^^^^^^^^^^^^^^^
  File "/home/airflow/.local/lib/python3.12/site-packages/airflow/models/baseoperator.py", line 424, in wrapper
    return func(self, *args, **kwargs)
           ^^^^^^^^^^^^^^^^^^^^^^^^^^^
  File "/home/airflow/.local/lib/python3.12/site-packages/airflow/operators/python.py", line 238, in execute
    return_value = self.execute_callable()
                   ^^^^^^^^^^^^^^^^^^^^^^^
  File "/home/airflow/.local/lib/python3.12/site-packages/airflow/operators/python.py", line 256, in execute_callable
    return runner.run(*self.op_args, **self.op_kwargs)
           ^^^^^^^^^^^^^^^^^^^^^^^^^^^^^^^^^^^^^^^^^^^
  File "/home/airflow/.local/lib/python3.12/site-packages/airflow/utils/operator_helpers.py", line 252, in run
    return self.func(*args, **kwargs)
           ^^^^^^^^^^^^^^^^^^^^^^^^^^
  File "/opt/airflow/dags/tiki_schema_management_dag.py", line 16, in create_schema
    client = bigquery.Client(project=config['bigquery']['project_id'])
             ^^^^^^^^^^^^^^^^^^^^^^^^^^^^^^^^^^^^^^^^^^^^^^^^^^^^^^^^^
  File "/home/airflow/.local/lib/python3.12/site-packages/google/cloud/bigquery/client.py", line 241, in __init__
    super(Client, self).__init__(
  File "/home/airflow/.local/lib/python3.12/site-packages/google/cloud/client/__init__.py", line 321, in __init__
    Client.__init__(
  File "/home/airflow/.local/lib/python3.12/site-packages/google/cloud/client/__init__.py", line 178, in __init__
    credentials, _ = google.auth.default(scopes=scopes)
                     ^^^^^^^^^^^^^^^^^^^^^^^^^^^^^^^^^^
  File "/home/airflow/.local/lib/python3.12/site-packages/google/auth/_default.py", line 719, in default
    raise exceptions.DefaultCredentialsError(_CLOUD_SDK_MISSING_CREDENTIALS)
google.auth.exceptions.DefaultCredentialsError: Your default credentials were not found. To set up Application Default Credentials, see https://cloud.google.com/docs/authentication/external/set-up-adc for more information.
[2025-03-07T21:25:24.275+0000] {logging_mixin.py:190} INFO - Task instance in failure state
[2025-03-07T21:25:24.276+0000] {logging_mixin.py:190} INFO - Task start:2025-03-07 21:25:20.986950+00:00 end:2025-03-07 21:25:24.275348+00:00 duration:3.288398
[2025-03-07T21:25:24.277+0000] {logging_mixin.py:190} INFO - Task:<Task(PythonOperator): create_schema> dag:<DAG: tiki_schema_management_dag> dagrun:<DagRun tiki_schema_management_dag @ 2025-03-07 21:25:17.203713+00:00: manual__2025-03-07T21:25:17.203713+00:00, state:running, queued_at: 2025-03-07 21:25:17.237853+00:00. externally triggered: True>
[2025-03-07T21:25:24.277+0000] {logging_mixin.py:190} INFO - Failure caused by Your default credentials were not found. To set up Application Default Credentials, see https://cloud.google.com/docs/authentication/external/set-up-adc for more information.
[2025-03-07T21:25:24.278+0000] {taskinstance.py:1226} INFO - Marking task as FAILED. dag_id=tiki_schema_management_dag, task_id=create_schema, run_id=manual__2025-03-07T21:25:17.203713+00:00, execution_date=20250307T212517, start_date=20250307T212520, end_date=20250307T212524
[2025-03-07T21:25:24.311+0000] {taskinstance.py:341} INFO - ::group::Post task execution logs
[2025-03-07T21:25:24.312+0000] {standard_task_runner.py:124} ERROR - Failed to execute job 17 for task create_schema (Your default credentials were not found. To set up Application Default Credentials, see https://cloud.google.com/docs/authentication/external/set-up-adc for more information.; 290)
Traceback (most recent call last):
  File "/home/airflow/.local/lib/python3.12/site-packages/airflow/task/task_runner/standard_task_runner.py", line 117, in _start_by_fork
    ret = args.func(args, dag=self.dag)
          ^^^^^^^^^^^^^^^^^^^^^^^^^^^^^
  File "/home/airflow/.local/lib/python3.12/site-packages/airflow/cli/cli_config.py", line 49, in command
    return func(*args, **kwargs)
           ^^^^^^^^^^^^^^^^^^^^^
  File "/home/airflow/.local/lib/python3.12/site-packages/airflow/utils/cli.py", line 116, in wrapper
    return f(*args, **kwargs)
           ^^^^^^^^^^^^^^^^^^
  File "/home/airflow/.local/lib/python3.12/site-packages/airflow/cli/commands/task_command.py", line 483, in task_run
    task_return_code = _run_task_by_selected_method(args, _dag, ti)
                       ^^^^^^^^^^^^^^^^^^^^^^^^^^^^^^^^^^^^^^^^^^^^
  File "/home/airflow/.local/lib/python3.12/site-packages/airflow/cli/commands/task_command.py", line 256, in _run_task_by_selected_method
    return _run_raw_task(args, ti)
           ^^^^^^^^^^^^^^^^^^^^^^^
  File "/home/airflow/.local/lib/python3.12/site-packages/airflow/cli/commands/task_command.py", line 341, in _run_raw_task
    return ti._run_raw_task(
           ^^^^^^^^^^^^^^^^^
  File "/home/airflow/.local/lib/python3.12/site-packages/airflow/utils/session.py", line 97, in wrapper
    return func(*args, session=session, **kwargs)
           ^^^^^^^^^^^^^^^^^^^^^^^^^^^^^^^^^^^^^^
  File "/home/airflow/.local/lib/python3.12/site-packages/airflow/models/taskinstance.py", line 3006, in _run_raw_task
    return _run_raw_task(
           ^^^^^^^^^^^^^^
  File "/home/airflow/.local/lib/python3.12/site-packages/airflow/models/taskinstance.py", line 274, in _run_raw_task
    TaskInstance._execute_task_with_callbacks(
  File "/home/airflow/.local/lib/python3.12/site-packages/airflow/models/taskinstance.py", line 3161, in _execute_task_with_callbacks
    result = self._execute_task(context, task_orig)
             ^^^^^^^^^^^^^^^^^^^^^^^^^^^^^^^^^^^^^^
  File "/home/airflow/.local/lib/python3.12/site-packages/airflow/models/taskinstance.py", line 3185, in _execute_task
    return _execute_task(self, context, task_orig)
           ^^^^^^^^^^^^^^^^^^^^^^^^^^^^^^^^^^^^^^^
  File "/home/airflow/.local/lib/python3.12/site-packages/airflow/models/taskinstance.py", line 768, in _execute_task
    result = _execute_callable(context=context, **execute_callable_kwargs)
             ^^^^^^^^^^^^^^^^^^^^^^^^^^^^^^^^^^^^^^^^^^^^^^^^^^^^^^^^^^^^^
  File "/home/airflow/.local/lib/python3.12/site-packages/airflow/models/taskinstance.py", line 734, in _execute_callable
    return ExecutionCallableRunner(
           ^^^^^^^^^^^^^^^^^^^^^^^^
  File "/home/airflow/.local/lib/python3.12/site-packages/airflow/utils/operator_helpers.py", line 252, in run
    return self.func(*args, **kwargs)
           ^^^^^^^^^^^^^^^^^^^^^^^^^^
  File "/home/airflow/.local/lib/python3.12/site-packages/airflow/models/baseoperator.py", line 424, in wrapper
    return func(self, *args, **kwargs)
           ^^^^^^^^^^^^^^^^^^^^^^^^^^^
  File "/home/airflow/.local/lib/python3.12/site-packages/airflow/operators/python.py", line 238, in execute
    return_value = self.execute_callable()
                   ^^^^^^^^^^^^^^^^^^^^^^^
  File "/home/airflow/.local/lib/python3.12/site-packages/airflow/operators/python.py", line 256, in execute_callable
    return runner.run(*self.op_args, **self.op_kwargs)
           ^^^^^^^^^^^^^^^^^^^^^^^^^^^^^^^^^^^^^^^^^^^
  File "/home/airflow/.local/lib/python3.12/site-packages/airflow/utils/operator_helpers.py", line 252, in run
    return self.func(*args, **kwargs)
           ^^^^^^^^^^^^^^^^^^^^^^^^^^
  File "/opt/airflow/dags/tiki_schema_management_dag.py", line 16, in create_schema
    client = bigquery.Client(project=config['bigquery']['project_id'])
             ^^^^^^^^^^^^^^^^^^^^^^^^^^^^^^^^^^^^^^^^^^^^^^^^^^^^^^^^^
  File "/home/airflow/.local/lib/python3.12/site-packages/google/cloud/bigquery/client.py", line 241, in __init__
    super(Client, self).__init__(
  File "/home/airflow/.local/lib/python3.12/site-packages/google/cloud/client/__init__.py", line 321, in __init__
    Client.__init__(
  File "/home/airflow/.local/lib/python3.12/site-packages/google/cloud/client/__init__.py", line 178, in __init__
    credentials, _ = google.auth.default(scopes=scopes)
                     ^^^^^^^^^^^^^^^^^^^^^^^^^^^^^^^^^^
  File "/home/airflow/.local/lib/python3.12/site-packages/google/auth/_default.py", line 719, in default
    raise exceptions.DefaultCredentialsError(_CLOUD_SDK_MISSING_CREDENTIALS)
google.auth.exceptions.DefaultCredentialsError: Your default credentials were not found. To set up Application Default Credentials, see https://cloud.google.com/docs/authentication/external/set-up-adc for more information.
[2025-03-07T21:25:24.353+0000] {local_task_job_runner.py:266} INFO - Task exited with return code 1
[2025-03-07T21:25:24.374+0000] {taskinstance.py:3901} INFO - 0 downstream tasks scheduled from follow-on schedule check
[2025-03-07T21:25:24.377+0000] {local_task_job_runner.py:245} INFO - ::endgroup::
