[2025-03-08T05:32:49.175+0000] {local_task_job_runner.py:123} INFO - ::group::Pre task execution logs
[2025-03-08T05:32:49.218+0000] {taskinstance.py:2614} INFO - Dependencies all met for dep_context=non-requeueable deps ti=<TaskInstance: tiki_extract_dag.extract_data manual__2025-03-08T05:32:40.204088+00:00 [queued]>
[2025-03-08T05:32:49.241+0000] {taskinstance.py:2614} INFO - Dependencies all met for dep_context=requeueable deps ti=<TaskInstance: tiki_extract_dag.extract_data manual__2025-03-08T05:32:40.204088+00:00 [queued]>
[2025-03-08T05:32:49.242+0000] {taskinstance.py:2867} INFO - Starting attempt 1 of 1
[2025-03-08T05:32:49.284+0000] {taskinstance.py:2890} INFO - Executing <Task(PythonOperator): extract_data> on 2025-03-08 05:32:40.204088+00:00
[2025-03-08T05:32:49.300+0000] {warnings.py:112} WARNING - /home/***/.local/lib/python3.12/site-packages/***/task/task_runner/standard_task_runner.py:70: DeprecationWarning: This process (pid=1255) is multi-threaded, use of fork() may lead to deadlocks in the child.
  pid = os.fork()

[2025-03-08T05:32:49.306+0000] {standard_task_runner.py:104} INFO - Running: ['***', 'tasks', 'run', 'tiki_extract_dag', 'extract_data', 'manual__2025-03-08T05:32:40.204088+00:00', '--job-id', '46', '--raw', '--subdir', 'DAGS_FOLDER/tiki_extract_dag.py', '--cfg-path', '/tmp/tmppvcrpxb5']
[2025-03-08T05:32:49.309+0000] {standard_task_runner.py:72} INFO - Started process 1264 to run task
[2025-03-08T05:32:49.309+0000] {standard_task_runner.py:105} INFO - Job 46: Subtask extract_data
[2025-03-08T05:32:49.460+0000] {task_command.py:467} INFO - Running <TaskInstance: tiki_extract_dag.extract_data manual__2025-03-08T05:32:40.204088+00:00 [running]> on host 9a2d81a2e852
[2025-03-08T05:32:50.608+0000] {taskinstance.py:3134} INFO - Exporting env vars: AIRFLOW_CTX_DAG_OWNER='***' AIRFLOW_CTX_DAG_ID='tiki_extract_dag' AIRFLOW_CTX_TASK_ID='extract_data' AIRFLOW_CTX_EXECUTION_DATE='2025-03-08T05:32:40.204088+00:00' AIRFLOW_CTX_TRY_NUMBER='1' AIRFLOW_CTX_DAG_RUN_ID='manual__2025-03-08T05:32:40.204088+00:00'
[2025-03-08T05:32:50.610+0000] {logging_mixin.py:190} INFO - Task instance is in running state
[2025-03-08T05:32:50.612+0000] {logging_mixin.py:190} INFO -  Previous state of the Task instance: queued
[2025-03-08T05:32:50.614+0000] {logging_mixin.py:190} INFO - Current task name:extract_data state:running start_date:2025-03-08 05:32:49.221126+00:00
[2025-03-08T05:32:50.615+0000] {logging_mixin.py:190} INFO - Dag name:tiki_extract_dag and current dag run status:running
[2025-03-08T05:32:50.616+0000] {taskinstance.py:732} INFO - ::endgroup::
[2025-03-08T05:32:51.432+0000] {crawl_data.py:101} INFO - Crawling category lam-dep-suc-khoe with 40 pages
[2025-03-08T05:32:52.009+0000] {crawl_data.py:118} INFO - Extracted page 1 - lam-dep-suc-khoe, 10 items, total extracted: 0
[2025-03-08T05:32:54.266+0000] {crawl_data.py:118} INFO - Extracted page 2 - lam-dep-suc-khoe, 10 items, total extracted: 0
[2025-03-08T05:32:58.834+0000] {crawl_data.py:118} INFO - Extracted page 3 - lam-dep-suc-khoe, 10 items, total extracted: 0
[2025-03-08T05:33:02.039+0000] {crawl_data.py:118} INFO - Extracted page 4 - lam-dep-suc-khoe, 10 items, total extracted: 0
[2025-03-08T05:33:07.042+0000] {crawl_data.py:118} INFO - Extracted page 5 - lam-dep-suc-khoe, 10 items, total extracted: 0
[2025-03-08T05:33:11.514+0000] {crawl_data.py:118} INFO - Extracted page 6 - lam-dep-suc-khoe, 10 items, total extracted: 0
[2025-03-08T05:33:15.102+0000] {crawl_data.py:118} INFO - Extracted page 7 - lam-dep-suc-khoe, 10 items, total extracted: 0
[2025-03-08T05:33:19.045+0000] {crawl_data.py:118} INFO - Extracted page 8 - lam-dep-suc-khoe, 10 items, total extracted: 0
[2025-03-08T05:33:21.353+0000] {crawl_data.py:118} INFO - Extracted page 9 - lam-dep-suc-khoe, 10 items, total extracted: 0
[2025-03-08T05:33:26.288+0000] {crawl_data.py:118} INFO - Extracted page 10 - lam-dep-suc-khoe, 10 items, total extracted: 0
[2025-03-08T05:33:29.266+0000] {crawl_data.py:118} INFO - Extracted page 11 - lam-dep-suc-khoe, 10 items, total extracted: 0
[2025-03-08T05:33:33.657+0000] {crawl_data.py:118} INFO - Extracted page 12 - lam-dep-suc-khoe, 10 items, total extracted: 0
[2025-03-08T05:33:38.861+0000] {crawl_data.py:118} INFO - Extracted page 13 - lam-dep-suc-khoe, 10 items, total extracted: 0
[2025-03-08T05:33:43.870+0000] {crawl_data.py:118} INFO - Extracted page 14 - lam-dep-suc-khoe, 10 items, total extracted: 0
[2025-03-08T05:33:46.623+0000] {crawl_data.py:118} INFO - Extracted page 15 - lam-dep-suc-khoe, 10 items, total extracted: 0
[2025-03-08T05:33:50.861+0000] {crawl_data.py:118} INFO - Extracted page 16 - lam-dep-suc-khoe, 10 items, total extracted: 0
[2025-03-08T05:33:54.322+0000] {crawl_data.py:118} INFO - Extracted page 17 - lam-dep-suc-khoe, 10 items, total extracted: 0
[2025-03-08T05:33:56.960+0000] {crawl_data.py:118} INFO - Extracted page 18 - lam-dep-suc-khoe, 10 items, total extracted: 0
[2025-03-08T05:34:00.799+0000] {crawl_data.py:118} INFO - Extracted page 19 - lam-dep-suc-khoe, 10 items, total extracted: 0
[2025-03-08T05:34:04.327+0000] {crawl_data.py:118} INFO - Extracted page 20 - lam-dep-suc-khoe, 10 items, total extracted: 0
[2025-03-08T05:34:09.069+0000] {crawl_data.py:118} INFO - Extracted page 21 - lam-dep-suc-khoe, 10 items, total extracted: 0
[2025-03-08T05:34:12.259+0000] {crawl_data.py:118} INFO - Extracted page 22 - lam-dep-suc-khoe, 10 items, total extracted: 0
[2025-03-08T05:34:16.475+0000] {crawl_data.py:118} INFO - Extracted page 23 - lam-dep-suc-khoe, 10 items, total extracted: 0
[2025-03-08T05:34:19.711+0000] {crawl_data.py:118} INFO - Extracted page 24 - lam-dep-suc-khoe, 10 items, total extracted: 0
[2025-03-08T05:34:24.551+0000] {crawl_data.py:118} INFO - Extracted page 25 - lam-dep-suc-khoe, 10 items, total extracted: 0
[2025-03-08T05:34:28.634+0000] {crawl_data.py:118} INFO - Extracted page 26 - lam-dep-suc-khoe, 10 items, total extracted: 0
[2025-03-08T05:34:32.678+0000] {crawl_data.py:118} INFO - Extracted page 27 - lam-dep-suc-khoe, 10 items, total extracted: 0
[2025-03-08T05:34:37.937+0000] {crawl_data.py:118} INFO - Extracted page 28 - lam-dep-suc-khoe, 10 items, total extracted: 0
[2025-03-08T05:34:42.049+0000] {crawl_data.py:118} INFO - Extracted page 29 - lam-dep-suc-khoe, 10 items, total extracted: 0
[2025-03-08T05:34:46.442+0000] {crawl_data.py:118} INFO - Extracted page 30 - lam-dep-suc-khoe, 10 items, total extracted: 0
[2025-03-08T05:34:50.126+0000] {crawl_data.py:118} INFO - Extracted page 31 - lam-dep-suc-khoe, 10 items, total extracted: 0
[2025-03-08T05:34:53.342+0000] {crawl_data.py:118} INFO - Extracted page 32 - lam-dep-suc-khoe, 10 items, total extracted: 0
[2025-03-08T05:34:56.415+0000] {crawl_data.py:118} INFO - Extracted page 33 - lam-dep-suc-khoe, 10 items, total extracted: 0
[2025-03-08T05:34:59.573+0000] {crawl_data.py:118} INFO - Extracted page 34 - lam-dep-suc-khoe, 10 items, total extracted: 0
[2025-03-08T05:35:02.802+0000] {crawl_data.py:118} INFO - Extracted page 35 - lam-dep-suc-khoe, 10 items, total extracted: 0
[2025-03-08T05:35:06.228+0000] {crawl_data.py:118} INFO - Extracted page 36 - lam-dep-suc-khoe, 10 items, total extracted: 0
[2025-03-08T05:35:08.578+0000] {crawl_data.py:118} INFO - Extracted page 37 - lam-dep-suc-khoe, 10 items, total extracted: 1
[2025-03-08T05:35:13.004+0000] {crawl_data.py:118} INFO - Extracted page 38 - lam-dep-suc-khoe, 10 items, total extracted: 1
[2025-03-08T05:35:16.562+0000] {crawl_data.py:118} INFO - Extracted page 39 - lam-dep-suc-khoe, 10 items, total extracted: 1
[2025-03-08T05:35:19.520+0000] {crawl_data.py:118} INFO - Extracted page 40 - lam-dep-suc-khoe, 10 items, total extracted: 1
[2025-03-08T05:35:23.692+0000] {crawl_data.py:101} INFO - Crawling category dien-thoai-may-tinh-bang with 40 pages
[2025-03-08T05:35:23.895+0000] {crawl_data.py:118} INFO - Extracted page 1 - dien-thoai-may-tinh-bang, 10 items, total extracted: 1
[2025-03-08T05:35:28.128+0000] {crawl_data.py:118} INFO - Extracted page 2 - dien-thoai-may-tinh-bang, 10 items, total extracted: 1
[2025-03-08T05:35:32.740+0000] {crawl_data.py:118} INFO - Extracted page 3 - dien-thoai-may-tinh-bang, 10 items, total extracted: 1
[2025-03-08T05:35:35.332+0000] {crawl_data.py:118} INFO - Extracted page 4 - dien-thoai-may-tinh-bang, 10 items, total extracted: 1
[2025-03-08T05:35:40.485+0000] {crawl_data.py:118} INFO - Extracted page 5 - dien-thoai-may-tinh-bang, 10 items, total extracted: 2
[2025-03-08T05:35:45.159+0000] {crawl_data.py:118} INFO - Extracted page 6 - dien-thoai-may-tinh-bang, 10 items, total extracted: 2
[2025-03-08T05:35:50.121+0000] {crawl_data.py:118} INFO - Extracted page 7 - dien-thoai-may-tinh-bang, 10 items, total extracted: 2
[2025-03-08T05:35:53.300+0000] {crawl_data.py:118} INFO - Extracted page 8 - dien-thoai-may-tinh-bang, 10 items, total extracted: 2
[2025-03-08T05:35:56.005+0000] {crawl_data.py:118} INFO - Extracted page 9 - dien-thoai-may-tinh-bang, 10 items, total extracted: 2
[2025-03-08T05:35:58.793+0000] {crawl_data.py:118} INFO - Extracted page 10 - dien-thoai-may-tinh-bang, 10 items, total extracted: 2
[2025-03-08T05:36:04.016+0000] {crawl_data.py:118} INFO - Extracted page 11 - dien-thoai-may-tinh-bang, 10 items, total extracted: 2
[2025-03-08T05:36:08.057+0000] {crawl_data.py:118} INFO - Extracted page 12 - dien-thoai-may-tinh-bang, 10 items, total extracted: 2
[2025-03-08T05:36:12.697+0000] {crawl_data.py:118} INFO - Extracted page 13 - dien-thoai-may-tinh-bang, 10 items, total extracted: 2
[2025-03-08T05:36:17.561+0000] {crawl_data.py:118} INFO - Extracted page 14 - dien-thoai-may-tinh-bang, 10 items, total extracted: 2
[2025-03-08T05:36:20.137+0000] {crawl_data.py:118} INFO - Extracted page 15 - dien-thoai-may-tinh-bang, 10 items, total extracted: 2
[2025-03-08T05:36:24.732+0000] {crawl_data.py:118} INFO - Extracted page 16 - dien-thoai-may-tinh-bang, 10 items, total extracted: 2
[2025-03-08T05:36:28.760+0000] {crawl_data.py:118} INFO - Extracted page 17 - dien-thoai-may-tinh-bang, 10 items, total extracted: 2
[2025-03-08T05:36:32.973+0000] {crawl_data.py:118} INFO - Extracted page 18 - dien-thoai-may-tinh-bang, 10 items, total extracted: 2
[2025-03-08T05:36:36.955+0000] {crawl_data.py:118} INFO - Extracted page 19 - dien-thoai-may-tinh-bang, 10 items, total extracted: 2
[2025-03-08T05:36:41.373+0000] {crawl_data.py:118} INFO - Extracted page 20 - dien-thoai-may-tinh-bang, 10 items, total extracted: 2
[2025-03-08T05:36:44.724+0000] {crawl_data.py:118} INFO - Extracted page 21 - dien-thoai-may-tinh-bang, 10 items, total extracted: 2
[2025-03-08T05:36:49.176+0000] {crawl_data.py:118} INFO - Extracted page 22 - dien-thoai-may-tinh-bang, 10 items, total extracted: 2
[2025-03-08T05:36:53.989+0000] {crawl_data.py:118} INFO - Extracted page 23 - dien-thoai-may-tinh-bang, 10 items, total extracted: 2
[2025-03-08T05:36:58.266+0000] {crawl_data.py:118} INFO - Extracted page 24 - dien-thoai-may-tinh-bang, 10 items, total extracted: 2
[2025-03-08T05:37:01.326+0000] {crawl_data.py:118} INFO - Extracted page 25 - dien-thoai-may-tinh-bang, 10 items, total extracted: 4
[2025-03-08T05:37:03.733+0000] {crawl_data.py:118} INFO - Extracted page 26 - dien-thoai-may-tinh-bang, 10 items, total extracted: 4
[2025-03-08T05:37:05.924+0000] {crawl_data.py:118} INFO - Extracted page 27 - dien-thoai-may-tinh-bang, 10 items, total extracted: 4
[2025-03-08T05:37:09.232+0000] {crawl_data.py:118} INFO - Extracted page 28 - dien-thoai-may-tinh-bang, 10 items, total extracted: 4
[2025-03-08T05:37:11.780+0000] {crawl_data.py:118} INFO - Extracted page 29 - dien-thoai-may-tinh-bang, 10 items, total extracted: 4
[2025-03-08T05:37:14.337+0000] {crawl_data.py:118} INFO - Extracted page 30 - dien-thoai-may-tinh-bang, 10 items, total extracted: 4
[2025-03-08T05:37:18.509+0000] {crawl_data.py:118} INFO - Extracted page 31 - dien-thoai-may-tinh-bang, 10 items, total extracted: 4
[2025-03-08T05:37:22.340+0000] {crawl_data.py:118} INFO - Extracted page 32 - dien-thoai-may-tinh-bang, 10 items, total extracted: 4
[2025-03-08T05:37:27.439+0000] {crawl_data.py:118} INFO - Extracted page 33 - dien-thoai-may-tinh-bang, 10 items, total extracted: 4
[2025-03-08T05:37:29.961+0000] {crawl_data.py:118} INFO - Extracted page 34 - dien-thoai-may-tinh-bang, 9 items, total extracted: 4
[2025-03-08T05:37:35.009+0000] {crawl_data.py:109} WARNING - No data found for page 35 - dien-thoai-may-tinh-bang
[2025-03-08T05:37:35.507+0000] {crawl_data.py:109} WARNING - No data found for page 36 - dien-thoai-may-tinh-bang
[2025-03-08T05:37:35.634+0000] {crawl_data.py:109} WARNING - No data found for page 37 - dien-thoai-may-tinh-bang
[2025-03-08T05:37:35.732+0000] {crawl_data.py:109} WARNING - No data found for page 38 - dien-thoai-may-tinh-bang
[2025-03-08T05:37:36.009+0000] {crawl_data.py:109} WARNING - No data found for page 39 - dien-thoai-may-tinh-bang
[2025-03-08T05:37:36.115+0000] {crawl_data.py:109} WARNING - No data found for page 40 - dien-thoai-may-tinh-bang
[2025-03-08T05:37:36.116+0000] {crawl_data.py:101} INFO - Crawling category laptop-may-vi-tinh-linh-kien with 40 pages
[2025-03-08T05:37:36.873+0000] {crawl_data.py:118} INFO - Extracted page 1 - laptop-may-vi-tinh-linh-kien, 10 items, total extracted: 4
[2025-03-08T05:37:39.389+0000] {crawl_data.py:118} INFO - Extracted page 2 - laptop-may-vi-tinh-linh-kien, 10 items, total extracted: 4
[2025-03-08T05:37:43.155+0000] {crawl_data.py:118} INFO - Extracted page 3 - laptop-may-vi-tinh-linh-kien, 10 items, total extracted: 4
[2025-03-08T05:37:47.174+0000] {crawl_data.py:118} INFO - Extracted page 4 - laptop-may-vi-tinh-linh-kien, 10 items, total extracted: 4
[2025-03-08T05:38:02.060+0000] {connectionpool.py:868} WARNING - Retrying (Retry(total=2, connect=None, read=None, redirect=None, status=None)) after connection broken by 'ReadTimeoutError("HTTPSConnectionPool(host='tiki.vn', port=443): Read timed out. (read timeout=10)")': /api/v2/products?page=5&category=1846
[2025-03-08T05:38:10.671+0000] {connectionpool.py:868} WARNING - Retrying (Retry(total=1, connect=None, read=None, redirect=None, status=None)) after connection broken by 'NameResolutionError("<urllib3.connection.HTTPSConnection object at 0x7f444da090a0>: Failed to resolve 'tiki.vn' ([Errno -3] Temporary failure in name resolution)")': /api/v2/products?page=5&category=1846
[2025-03-08T05:38:19.882+0000] {connectionpool.py:868} WARNING - Retrying (Retry(total=0, connect=None, read=None, redirect=None, status=None)) after connection broken by 'NameResolutionError("<urllib3.connection.HTTPSConnection object at 0x7f444da09e50>: Failed to resolve 'tiki.vn' ([Errno -3] Temporary failure in name resolution)")': /api/v2/products?page=5&category=1846
[2025-03-08T05:38:27.890+0000] {crawl_data.py:121} ERROR - API error for page 5 - laptop-may-vi-tinh-linh-kien: HTTPSConnectionPool(host='tiki.vn', port=443): Max retries exceeded with url: /api/v2/products?page=5&category=1846 (Caused by NameResolutionError("<urllib3.connection.HTTPSConnection object at 0x7f444da0bef0>: Failed to resolve 'tiki.vn' ([Errno -3] Temporary failure in name resolution)"))
[2025-03-08T05:38:27.892+0000] {crawl_data.py:101} INFO - Crawling category dien-gia-dung with 40 pages
[2025-03-08T05:38:35.898+0000] {connectionpool.py:868} WARNING - Retrying (Retry(total=2, connect=None, read=None, redirect=None, status=None)) after connection broken by 'NameResolutionError("<urllib3.connection.HTTPSConnection object at 0x7f444da08920>: Failed to resolve 'tiki.vn' ([Errno -3] Temporary failure in name resolution)")': /api/v2/products?page=1&category=1882
[2025-03-08T05:38:44.506+0000] {connectionpool.py:868} WARNING - Retrying (Retry(total=1, connect=None, read=None, redirect=None, status=None)) after connection broken by 'NameResolutionError("<urllib3.connection.HTTPSConnection object at 0x7f444da0a9c0>: Failed to resolve 'tiki.vn' ([Errno -3] Temporary failure in name resolution)")': /api/v2/products?page=1&category=1882
[2025-03-08T05:38:53.711+0000] {connectionpool.py:868} WARNING - Retrying (Retry(total=0, connect=None, read=None, redirect=None, status=None)) after connection broken by 'NameResolutionError("<urllib3.connection.HTTPSConnection object at 0x7f444da09940>: Failed to resolve 'tiki.vn' ([Errno -3] Temporary failure in name resolution)")': /api/v2/products?page=1&category=1882
[2025-03-08T05:39:01.718+0000] {crawl_data.py:121} ERROR - API error for page 1 - dien-gia-dung: HTTPSConnectionPool(host='tiki.vn', port=443): Max retries exceeded with url: /api/v2/products?page=1&category=1882 (Caused by NameResolutionError("<urllib3.connection.HTTPSConnection object at 0x7f444da14770>: Failed to resolve 'tiki.vn' ([Errno -3] Temporary failure in name resolution)"))
[2025-03-08T05:39:01.719+0000] {crawl_data.py:101} INFO - Crawling category sach with 40 pages
[2025-03-08T05:39:09.723+0000] {connectionpool.py:868} WARNING - Retrying (Retry(total=2, connect=None, read=None, redirect=None, status=None)) after connection broken by 'NameResolutionError("<urllib3.connection.HTTPSConnection object at 0x7f444da14290>: Failed to resolve 'tiki.vn' ([Errno -3] Temporary failure in name resolution)")': /api/v2/products?page=1&category=8322
[2025-03-08T05:39:18.329+0000] {connectionpool.py:868} WARNING - Retrying (Retry(total=1, connect=None, read=None, redirect=None, status=None)) after connection broken by 'NameResolutionError("<urllib3.connection.HTTPSConnection object at 0x7f444da149e0>: Failed to resolve 'tiki.vn' ([Errno -3] Temporary failure in name resolution)")': /api/v2/products?page=1&category=8322
[2025-03-08T05:39:27.535+0000] {connectionpool.py:868} WARNING - Retrying (Retry(total=0, connect=None, read=None, redirect=None, status=None)) after connection broken by 'NameResolutionError("<urllib3.connection.HTTPSConnection object at 0x7f444da14bc0>: Failed to resolve 'tiki.vn' ([Errno -3] Temporary failure in name resolution)")': /api/v2/products?page=1&category=8322
[2025-03-08T05:39:35.541+0000] {crawl_data.py:121} ERROR - API error for page 1 - sach: HTTPSConnectionPool(host='tiki.vn', port=443): Max retries exceeded with url: /api/v2/products?page=1&category=8322 (Caused by NameResolutionError("<urllib3.connection.HTTPSConnection object at 0x7f444da14dd0>: Failed to resolve 'tiki.vn' ([Errno -3] Temporary failure in name resolution)"))
[2025-03-08T05:39:35.543+0000] {crawl_data.py:101} INFO - Crawling category thiet-bi-kts-phu-kien-so with 40 pages
[2025-03-08T05:39:43.547+0000] {connectionpool.py:868} WARNING - Retrying (Retry(total=2, connect=None, read=None, redirect=None, status=None)) after connection broken by 'NameResolutionError("<urllib3.connection.HTTPSConnection object at 0x7f444da08350>: Failed to resolve 'tiki.vn' ([Errno -3] Temporary failure in name resolution)")': /api/v2/products?page=1&category=1815
[2025-03-08T05:39:52.153+0000] {connectionpool.py:868} WARNING - Retrying (Retry(total=1, connect=None, read=None, redirect=None, status=None)) after connection broken by 'NameResolutionError("<urllib3.connection.HTTPSConnection object at 0x7f444da09970>: Failed to resolve 'tiki.vn' ([Errno -3] Temporary failure in name resolution)")': /api/v2/products?page=1&category=1815
[2025-03-08T05:40:01.359+0000] {connectionpool.py:868} WARNING - Retrying (Retry(total=0, connect=None, read=None, redirect=None, status=None)) after connection broken by 'NameResolutionError("<urllib3.connection.HTTPSConnection object at 0x7f444da08c80>: Failed to resolve 'tiki.vn' ([Errno -3] Temporary failure in name resolution)")': /api/v2/products?page=1&category=1815
[2025-03-08T05:40:09.364+0000] {crawl_data.py:121} ERROR - API error for page 1 - thiet-bi-kts-phu-kien-so: HTTPSConnectionPool(host='tiki.vn', port=443): Max retries exceeded with url: /api/v2/products?page=1&category=1815 (Caused by NameResolutionError("<urllib3.connection.HTTPSConnection object at 0x7f444da09e50>: Failed to resolve 'tiki.vn' ([Errno -3] Temporary failure in name resolution)"))
[2025-03-08T05:40:09.365+0000] {crawl_data.py:101} INFO - Crawling category thoi-trang-nu with 40 pages
[2025-03-08T05:40:13.674+0000] {connectionpool.py:868} WARNING - Retrying (Retry(total=2, connect=None, read=None, redirect=None, status=None)) after connection broken by 'NewConnectionError('<urllib3.connection.HTTPSConnection object at 0x7f444e18cdd0>: Failed to establish a new connection: [Errno 111] Connection refused')': /api/v2/products?page=1&category=931
[2025-03-08T05:40:14.324+0000] {connectionpool.py:868} WARNING - Retrying (Retry(total=1, connect=None, read=None, redirect=None, status=None)) after connection broken by 'NewConnectionError('<urllib3.connection.HTTPSConnection object at 0x7f444da14f20>: Failed to establish a new connection: [Errno 111] Connection refused')': /api/v2/products?page=1&category=931
[2025-03-08T05:40:15.549+0000] {connectionpool.py:868} WARNING - Retrying (Retry(total=0, connect=None, read=None, redirect=None, status=None)) after connection broken by 'NewConnectionError('<urllib3.connection.HTTPSConnection object at 0x7f444da15010>: Failed to establish a new connection: [Errno 111] Connection refused')': /api/v2/products?page=1&category=931
[2025-03-08T05:40:15.559+0000] {crawl_data.py:121} ERROR - API error for page 1 - thoi-trang-nu: HTTPSConnectionPool(host='tiki.vn', port=443): Max retries exceeded with url: /api/v2/products?page=1&category=931 (Caused by NewConnectionError('<urllib3.connection.HTTPSConnection object at 0x7f444da152e0>: Failed to establish a new connection: [Errno 111] Connection refused'))
[2025-03-08T05:40:15.561+0000] {crawl_data.py:101} INFO - Crawling category thoi-trang-nam with 40 pages
[2025-03-08T05:40:15.571+0000] {connectionpool.py:868} WARNING - Retrying (Retry(total=2, connect=None, read=None, redirect=None, status=None)) after connection broken by 'NewConnectionError('<urllib3.connection.HTTPSConnection object at 0x7f444da15580>: Failed to establish a new connection: [Errno 111] Connection refused')': /api/v2/products?page=1&category=915
[2025-03-08T05:40:16.180+0000] {connectionpool.py:868} WARNING - Retrying (Retry(total=1, connect=None, read=None, redirect=None, status=None)) after connection broken by 'NewConnectionError('<urllib3.connection.HTTPSConnection object at 0x7f444da15880>: Failed to establish a new connection: [Errno 111] Connection refused')': /api/v2/products?page=1&category=915
[2025-03-08T05:40:17.389+0000] {connectionpool.py:868} WARNING - Retrying (Retry(total=0, connect=None, read=None, redirect=None, status=None)) after connection broken by 'NewConnectionError('<urllib3.connection.HTTPSConnection object at 0x7f444da15a00>: Failed to establish a new connection: [Errno 111] Connection refused')': /api/v2/products?page=1&category=915
[2025-03-08T05:40:17.414+0000] {crawl_data.py:121} ERROR - API error for page 1 - thoi-trang-nam: HTTPSConnectionPool(host='tiki.vn', port=443): Max retries exceeded with url: /api/v2/products?page=1&category=915 (Caused by NewConnectionError('<urllib3.connection.HTTPSConnection object at 0x7f444da15ee0>: Failed to establish a new connection: [Errno 111] Connection refused'))
[2025-03-08T05:40:17.416+0000] {crawl_data.py:101} INFO - Crawling category dong-ho-va-trang-suc with 40 pages
[2025-03-08T05:40:17.425+0000] {connectionpool.py:868} WARNING - Retrying (Retry(total=2, connect=None, read=None, redirect=None, status=None)) after connection broken by 'NewConnectionError('<urllib3.connection.HTTPSConnection object at 0x7f444da162a0>: Failed to establish a new connection: [Errno 111] Connection refused')': /api/v2/products?page=1&category=8371
[2025-03-08T05:40:18.038+0000] {connectionpool.py:868} WARNING - Retrying (Retry(total=1, connect=None, read=None, redirect=None, status=None)) after connection broken by 'NewConnectionError('<urllib3.connection.HTTPSConnection object at 0x7f444da16510>: Failed to establish a new connection: [Errno 111] Connection refused')': /api/v2/products?page=1&category=8371
[2025-03-08T05:40:19.247+0000] {connectionpool.py:868} WARNING - Retrying (Retry(total=0, connect=None, read=None, redirect=None, status=None)) after connection broken by 'NewConnectionError('<urllib3.connection.HTTPSConnection object at 0x7f444da16780>: Failed to establish a new connection: [Errno 111] Connection refused')': /api/v2/products?page=1&category=8371
[2025-03-08T05:40:19.425+0000] {crawl_data.py:121} ERROR - API error for page 1 - dong-ho-va-trang-suc: HTTPSConnectionPool(host='tiki.vn', port=443): Max retries exceeded with url: /api/v2/products?page=1&category=8371 (Caused by NewConnectionError('<urllib3.connection.HTTPSConnection object at 0x7f444da16870>: Failed to establish a new connection: [Errno 111] Connection refused'))
[2025-03-08T05:40:19.426+0000] {crawl_data.py:101} INFO - Crawling category dien-tu-dien-lanh with 40 pages
[2025-03-08T05:40:19.439+0000] {connectionpool.py:868} WARNING - Retrying (Retry(total=2, connect=None, read=None, redirect=None, status=None)) after connection broken by 'NewConnectionError('<urllib3.connection.HTTPSConnection object at 0x7f444da16c60>: Failed to establish a new connection: [Errno 111] Connection refused')': /api/v2/products?page=1&category=4221
[2025-03-08T05:40:20.066+0000] {connectionpool.py:868} WARNING - Retrying (Retry(total=1, connect=None, read=None, redirect=None, status=None)) after connection broken by 'NewConnectionError('<urllib3.connection.HTTPSConnection object at 0x7f444e18c140>: Failed to establish a new connection: [Errno 111] Connection refused')': /api/v2/products?page=1&category=4221
[2025-03-08T05:40:21.280+0000] {connectionpool.py:868} WARNING - Retrying (Retry(total=0, connect=None, read=None, redirect=None, status=None)) after connection broken by 'NewConnectionError('<urllib3.connection.HTTPSConnection object at 0x7f444dfb1fd0>: Failed to establish a new connection: [Errno 111] Connection refused')': /api/v2/products?page=1&category=4221
[2025-03-08T05:40:21.288+0000] {crawl_data.py:121} ERROR - API error for page 1 - dien-tu-dien-lanh: HTTPSConnectionPool(host='tiki.vn', port=443): Max retries exceeded with url: /api/v2/products?page=1&category=4221 (Caused by NewConnectionError('<urllib3.connection.HTTPSConnection object at 0x7f444da08e30>: Failed to establish a new connection: [Errno 111] Connection refused'))
[2025-03-08T05:40:21.515+0000] {connectionpool.py:868} WARNING - Retrying (Retry(total=2, connect=None, read=None, redirect=None, status=None)) after connection broken by 'NewConnectionError('<urllib3.connection.HTTPSConnection object at 0x7f444db8bfe0>: Failed to establish a new connection: [Errno 101] Network is unreachable')': /token
[2025-03-08T05:40:21.543+0000] {connectionpool.py:868} WARNING - Retrying (Retry(total=1, connect=None, read=None, redirect=None, status=None)) after connection broken by 'NewConnectionError('<urllib3.connection.HTTPSConnection object at 0x7f444da16120>: Failed to establish a new connection: [Errno 101] Network is unreachable')': /token
[2025-03-08T05:40:21.571+0000] {connectionpool.py:868} WARNING - Retrying (Retry(total=0, connect=None, read=None, redirect=None, status=None)) after connection broken by 'NewConnectionError('<urllib3.connection.HTTPSConnection object at 0x7f444da161e0>: Failed to establish a new connection: [Errno 101] Network is unreachable')': /token
[2025-03-08T05:40:21.598+0000] {crawl_data.py:140} ERROR - Error uploading to GCS: HTTPSConnectionPool(host='oauth2.googleapis.com', port=443): Max retries exceeded with url: /token (Caused by NewConnectionError('<urllib3.connection.HTTPSConnection object at 0x7f444da167e0>: Failed to establish a new connection: [Errno 101] Network is unreachable'))
[2025-03-08T05:40:21.605+0000] {taskinstance.py:3313} ERROR - Task failed with exception
Traceback (most recent call last):
  File "/home/airflow/.local/lib/python3.12/site-packages/urllib3/connection.py", line 198, in _new_conn
    sock = connection.create_connection(
           ^^^^^^^^^^^^^^^^^^^^^^^^^^^^^
  File "/home/airflow/.local/lib/python3.12/site-packages/urllib3/util/connection.py", line 85, in create_connection
    raise err
  File "/home/airflow/.local/lib/python3.12/site-packages/urllib3/util/connection.py", line 73, in create_connection
    sock.connect(sa)
OSError: [Errno 101] Network is unreachable

The above exception was the direct cause of the following exception:

Traceback (most recent call last):
  File "/home/airflow/.local/lib/python3.12/site-packages/urllib3/connectionpool.py", line 787, in urlopen
    response = self._make_request(
               ^^^^^^^^^^^^^^^^^^^
  File "/home/airflow/.local/lib/python3.12/site-packages/urllib3/connectionpool.py", line 488, in _make_request
    raise new_e
  File "/home/airflow/.local/lib/python3.12/site-packages/urllib3/connectionpool.py", line 464, in _make_request
    self._validate_conn(conn)
  File "/home/airflow/.local/lib/python3.12/site-packages/urllib3/connectionpool.py", line 1093, in _validate_conn
    conn.connect()
  File "/home/airflow/.local/lib/python3.12/site-packages/urllib3/connection.py", line 704, in connect
    self.sock = sock = self._new_conn()
                       ^^^^^^^^^^^^^^^^
  File "/home/airflow/.local/lib/python3.12/site-packages/urllib3/connection.py", line 213, in _new_conn
    raise NewConnectionError(
urllib3.exceptions.NewConnectionError: <urllib3.connection.HTTPSConnection object at 0x7f444da167e0>: Failed to establish a new connection: [Errno 101] Network is unreachable

The above exception was the direct cause of the following exception:

Traceback (most recent call last):
  File "/home/airflow/.local/lib/python3.12/site-packages/requests/adapters.py", line 667, in send
    resp = conn.urlopen(
           ^^^^^^^^^^^^^
  File "/home/airflow/.local/lib/python3.12/site-packages/urllib3/connectionpool.py", line 871, in urlopen
    return self.urlopen(
           ^^^^^^^^^^^^^
  File "/home/airflow/.local/lib/python3.12/site-packages/urllib3/connectionpool.py", line 871, in urlopen
    return self.urlopen(
           ^^^^^^^^^^^^^
  File "/home/airflow/.local/lib/python3.12/site-packages/urllib3/connectionpool.py", line 871, in urlopen
    return self.urlopen(
           ^^^^^^^^^^^^^
  File "/home/airflow/.local/lib/python3.12/site-packages/urllib3/connectionpool.py", line 841, in urlopen
    retries = retries.increment(
              ^^^^^^^^^^^^^^^^^^
  File "/home/airflow/.local/lib/python3.12/site-packages/urllib3/util/retry.py", line 519, in increment
    raise MaxRetryError(_pool, url, reason) from reason  # type: ignore[arg-type]
    ^^^^^^^^^^^^^^^^^^^^^^^^^^^^^^^^^^^^^^^^^^^^^^^^^^^
urllib3.exceptions.MaxRetryError: HTTPSConnectionPool(host='oauth2.googleapis.com', port=443): Max retries exceeded with url: /token (Caused by NewConnectionError('<urllib3.connection.HTTPSConnection object at 0x7f444da167e0>: Failed to establish a new connection: [Errno 101] Network is unreachable'))

During handling of the above exception, another exception occurred:

Traceback (most recent call last):
  File "/home/airflow/.local/lib/python3.12/site-packages/google/auth/transport/requests.py", line 186, in __call__
    response = self.session.request(
               ^^^^^^^^^^^^^^^^^^^^^
  File "/home/airflow/.local/lib/python3.12/site-packages/requests/sessions.py", line 589, in request
    resp = self.send(prep, **send_kwargs)
           ^^^^^^^^^^^^^^^^^^^^^^^^^^^^^^
  File "/home/airflow/.local/lib/python3.12/site-packages/requests/sessions.py", line 703, in send
    r = adapter.send(request, **kwargs)
        ^^^^^^^^^^^^^^^^^^^^^^^^^^^^^^^
  File "/home/airflow/.local/lib/python3.12/site-packages/requests/adapters.py", line 700, in send
    raise ConnectionError(e, request=request)
requests.exceptions.ConnectionError: HTTPSConnectionPool(host='oauth2.googleapis.com', port=443): Max retries exceeded with url: /token (Caused by NewConnectionError('<urllib3.connection.HTTPSConnection object at 0x7f444da167e0>: Failed to establish a new connection: [Errno 101] Network is unreachable'))

The above exception was the direct cause of the following exception:

Traceback (most recent call last):
  File "/home/airflow/.local/lib/python3.12/site-packages/airflow/models/taskinstance.py", line 768, in _execute_task
    result = _execute_callable(context=context, **execute_callable_kwargs)
             ^^^^^^^^^^^^^^^^^^^^^^^^^^^^^^^^^^^^^^^^^^^^^^^^^^^^^^^^^^^^^
  File "/home/airflow/.local/lib/python3.12/site-packages/airflow/models/taskinstance.py", line 734, in _execute_callable
    return ExecutionCallableRunner(
           ^^^^^^^^^^^^^^^^^^^^^^^^
  File "/home/airflow/.local/lib/python3.12/site-packages/airflow/utils/operator_helpers.py", line 252, in run
    return self.func(*args, **kwargs)
           ^^^^^^^^^^^^^^^^^^^^^^^^^^
  File "/home/airflow/.local/lib/python3.12/site-packages/airflow/models/baseoperator.py", line 424, in wrapper
    return func(self, *args, **kwargs)
           ^^^^^^^^^^^^^^^^^^^^^^^^^^^
  File "/home/airflow/.local/lib/python3.12/site-packages/airflow/operators/python.py", line 238, in execute
    return_value = self.execute_callable()
                   ^^^^^^^^^^^^^^^^^^^^^^^
  File "/home/airflow/.local/lib/python3.12/site-packages/airflow/operators/python.py", line 256, in execute_callable
    return runner.run(*self.op_args, **self.op_kwargs)
           ^^^^^^^^^^^^^^^^^^^^^^^^^^^^^^^^^^^^^^^^^^^
  File "/home/airflow/.local/lib/python3.12/site-packages/airflow/utils/operator_helpers.py", line 252, in run
    return self.func(*args, **kwargs)
           ^^^^^^^^^^^^^^^^^^^^^^^^^^
  File "/opt/airflow/dags/scripts/crawl_data.py", line 133, in extract_data
    blob.upload_from_string(json.dumps(all_raw_data))
  File "/usr/local/lib/python3.12/contextlib.py", line 81, in inner
    return func(*args, **kwds)
           ^^^^^^^^^^^^^^^^^^^
  File "/home/airflow/.local/lib/python3.12/site-packages/google/cloud/storage/blob.py", line 3128, in upload_from_string
    self.upload_from_file(
  File "/usr/local/lib/python3.12/contextlib.py", line 81, in inner
    return func(*args, **kwds)
           ^^^^^^^^^^^^^^^^^^^
  File "/home/airflow/.local/lib/python3.12/site-packages/google/cloud/storage/blob.py", line 2851, in upload_from_file
    self._prep_and_do_upload(
  File "/home/airflow/.local/lib/python3.12/site-packages/google/cloud/storage/blob.py", line 2700, in _prep_and_do_upload
    created_json = self._do_upload(
                   ^^^^^^^^^^^^^^^^
  File "/home/airflow/.local/lib/python3.12/site-packages/google/cloud/storage/blob.py", line 2506, in _do_upload
    response = self._do_multipart_upload(
               ^^^^^^^^^^^^^^^^^^^^^^^^^^
  File "/home/airflow/.local/lib/python3.12/site-packages/google/cloud/storage/blob.py", line 2007, in _do_multipart_upload
    response = upload.transmit(
               ^^^^^^^^^^^^^^^^
  File "/home/airflow/.local/lib/python3.12/site-packages/google/resumable_media/requests/upload.py", line 153, in transmit
    return _request_helpers.wait_and_retry(
           ^^^^^^^^^^^^^^^^^^^^^^^^^^^^^^^^
  File "/home/airflow/.local/lib/python3.12/site-packages/google/resumable_media/requests/_request_helpers.py", line 155, in wait_and_retry
    response = func()
               ^^^^^^
  File "/home/airflow/.local/lib/python3.12/site-packages/google/resumable_media/requests/upload.py", line 145, in retriable_request
    result = transport.request(
             ^^^^^^^^^^^^^^^^^^
  File "/home/airflow/.local/lib/python3.12/site-packages/google/auth/transport/requests.py", line 533, in request
    self.credentials.before_request(auth_request, method, url, request_headers)
  File "/home/airflow/.local/lib/python3.12/site-packages/google/auth/credentials.py", line 239, in before_request
    self._blocking_refresh(request)
  File "/home/airflow/.local/lib/python3.12/site-packages/google/auth/credentials.py", line 202, in _blocking_refresh
    self.refresh(request)
  File "/home/airflow/.local/lib/python3.12/site-packages/google/oauth2/service_account.py", line 448, in refresh
    access_token, expiry, _ = _client.jwt_grant(
                              ^^^^^^^^^^^^^^^^^^
  File "/home/airflow/.local/lib/python3.12/site-packages/google/oauth2/_client.py", line 299, in jwt_grant
    response_data = _token_endpoint_request(
                    ^^^^^^^^^^^^^^^^^^^^^^^^
  File "/home/airflow/.local/lib/python3.12/site-packages/google/oauth2/_client.py", line 259, in _token_endpoint_request
    response_status_ok, response_data, retryable_error = _token_endpoint_request_no_throw(
                                                         ^^^^^^^^^^^^^^^^^^^^^^^^^^^^^^^^^
  File "/home/airflow/.local/lib/python3.12/site-packages/google/oauth2/_client.py", line 192, in _token_endpoint_request_no_throw
    response = request(
               ^^^^^^^^
  File "/home/airflow/.local/lib/python3.12/site-packages/google/auth/transport/requests.py", line 192, in __call__
    raise new_exc from caught_exc
google.auth.exceptions.TransportError: HTTPSConnectionPool(host='oauth2.googleapis.com', port=443): Max retries exceeded with url: /token (Caused by NewConnectionError('<urllib3.connection.HTTPSConnection object at 0x7f444da167e0>: Failed to establish a new connection: [Errno 101] Network is unreachable'))
[2025-03-08T05:40:21.688+0000] {logging_mixin.py:190} INFO - Task instance in failure state
[2025-03-08T05:40:21.690+0000] {logging_mixin.py:190} INFO - Task start:2025-03-08 05:32:49.221126+00:00 end:2025-03-08 05:40:21.682444+00:00 duration:452.461318
[2025-03-08T05:40:21.692+0000] {logging_mixin.py:190} INFO - Task:<Task(PythonOperator): extract_data> dag:<DAG: tiki_extract_dag> dagrun:<DagRun tiki_extract_dag @ 2025-03-08 05:32:40.204088+00:00: manual__2025-03-08T05:32:40.204088+00:00, state:running, queued_at: 2025-03-08 05:32:40.314531+00:00. externally triggered: True>
[2025-03-08T05:40:21.693+0000] {logging_mixin.py:190} INFO - Failure caused by HTTPSConnectionPool(host='oauth2.googleapis.com', port=443): Max retries exceeded with url: /token (Caused by NewConnectionError('<urllib3.connection.HTTPSConnection object at 0x7f444da167e0>: Failed to establish a new connection: [Errno 101] Network is unreachable'))
[2025-03-08T05:40:21.694+0000] {taskinstance.py:1226} INFO - Marking task as FAILED. dag_id=tiki_extract_dag, task_id=extract_data, run_id=manual__2025-03-08T05:32:40.204088+00:00, execution_date=20250308T053240, start_date=20250308T053249, end_date=20250308T054021
[2025-03-08T05:40:21.893+0000] {taskinstance.py:341} INFO - ::group::Post task execution logs
[2025-03-08T05:40:21.896+0000] {standard_task_runner.py:124} ERROR - Failed to execute job 46 for task extract_data (HTTPSConnectionPool(host='oauth2.googleapis.com', port=443): Max retries exceeded with url: /token (Caused by NewConnectionError('<urllib3.connection.HTTPSConnection object at 0x7f444da167e0>: Failed to establish a new connection: [Errno 101] Network is unreachable')); 1264)
Traceback (most recent call last):
  File "/home/airflow/.local/lib/python3.12/site-packages/urllib3/connection.py", line 198, in _new_conn
    sock = connection.create_connection(
           ^^^^^^^^^^^^^^^^^^^^^^^^^^^^^
  File "/home/airflow/.local/lib/python3.12/site-packages/urllib3/util/connection.py", line 85, in create_connection
    raise err
  File "/home/airflow/.local/lib/python3.12/site-packages/urllib3/util/connection.py", line 73, in create_connection
    sock.connect(sa)
OSError: [Errno 101] Network is unreachable

The above exception was the direct cause of the following exception:

Traceback (most recent call last):
  File "/home/airflow/.local/lib/python3.12/site-packages/urllib3/connectionpool.py", line 787, in urlopen
    response = self._make_request(
               ^^^^^^^^^^^^^^^^^^^
  File "/home/airflow/.local/lib/python3.12/site-packages/urllib3/connectionpool.py", line 488, in _make_request
    raise new_e
  File "/home/airflow/.local/lib/python3.12/site-packages/urllib3/connectionpool.py", line 464, in _make_request
    self._validate_conn(conn)
  File "/home/airflow/.local/lib/python3.12/site-packages/urllib3/connectionpool.py", line 1093, in _validate_conn
    conn.connect()
  File "/home/airflow/.local/lib/python3.12/site-packages/urllib3/connection.py", line 704, in connect
    self.sock = sock = self._new_conn()
                       ^^^^^^^^^^^^^^^^
  File "/home/airflow/.local/lib/python3.12/site-packages/urllib3/connection.py", line 213, in _new_conn
    raise NewConnectionError(
urllib3.exceptions.NewConnectionError: <urllib3.connection.HTTPSConnection object at 0x7f444da167e0>: Failed to establish a new connection: [Errno 101] Network is unreachable

The above exception was the direct cause of the following exception:

Traceback (most recent call last):
  File "/home/airflow/.local/lib/python3.12/site-packages/requests/adapters.py", line 667, in send
    resp = conn.urlopen(
           ^^^^^^^^^^^^^
  File "/home/airflow/.local/lib/python3.12/site-packages/urllib3/connectionpool.py", line 871, in urlopen
    return self.urlopen(
           ^^^^^^^^^^^^^
  File "/home/airflow/.local/lib/python3.12/site-packages/urllib3/connectionpool.py", line 871, in urlopen
    return self.urlopen(
           ^^^^^^^^^^^^^
  File "/home/airflow/.local/lib/python3.12/site-packages/urllib3/connectionpool.py", line 871, in urlopen
    return self.urlopen(
           ^^^^^^^^^^^^^
  File "/home/airflow/.local/lib/python3.12/site-packages/urllib3/connectionpool.py", line 841, in urlopen
    retries = retries.increment(
              ^^^^^^^^^^^^^^^^^^
  File "/home/airflow/.local/lib/python3.12/site-packages/urllib3/util/retry.py", line 519, in increment
    raise MaxRetryError(_pool, url, reason) from reason  # type: ignore[arg-type]
    ^^^^^^^^^^^^^^^^^^^^^^^^^^^^^^^^^^^^^^^^^^^^^^^^^^^
urllib3.exceptions.MaxRetryError: HTTPSConnectionPool(host='oauth2.googleapis.com', port=443): Max retries exceeded with url: /token (Caused by NewConnectionError('<urllib3.connection.HTTPSConnection object at 0x7f444da167e0>: Failed to establish a new connection: [Errno 101] Network is unreachable'))

During handling of the above exception, another exception occurred:

Traceback (most recent call last):
  File "/home/airflow/.local/lib/python3.12/site-packages/google/auth/transport/requests.py", line 186, in __call__
    response = self.session.request(
               ^^^^^^^^^^^^^^^^^^^^^
  File "/home/airflow/.local/lib/python3.12/site-packages/requests/sessions.py", line 589, in request
    resp = self.send(prep, **send_kwargs)
           ^^^^^^^^^^^^^^^^^^^^^^^^^^^^^^
  File "/home/airflow/.local/lib/python3.12/site-packages/requests/sessions.py", line 703, in send
    r = adapter.send(request, **kwargs)
        ^^^^^^^^^^^^^^^^^^^^^^^^^^^^^^^
  File "/home/airflow/.local/lib/python3.12/site-packages/requests/adapters.py", line 700, in send
    raise ConnectionError(e, request=request)
requests.exceptions.ConnectionError: HTTPSConnectionPool(host='oauth2.googleapis.com', port=443): Max retries exceeded with url: /token (Caused by NewConnectionError('<urllib3.connection.HTTPSConnection object at 0x7f444da167e0>: Failed to establish a new connection: [Errno 101] Network is unreachable'))

The above exception was the direct cause of the following exception:

Traceback (most recent call last):
  File "/home/airflow/.local/lib/python3.12/site-packages/airflow/task/task_runner/standard_task_runner.py", line 117, in _start_by_fork
    ret = args.func(args, dag=self.dag)
          ^^^^^^^^^^^^^^^^^^^^^^^^^^^^^
  File "/home/airflow/.local/lib/python3.12/site-packages/airflow/cli/cli_config.py", line 49, in command
    return func(*args, **kwargs)
           ^^^^^^^^^^^^^^^^^^^^^
  File "/home/airflow/.local/lib/python3.12/site-packages/airflow/utils/cli.py", line 116, in wrapper
    return f(*args, **kwargs)
           ^^^^^^^^^^^^^^^^^^
  File "/home/airflow/.local/lib/python3.12/site-packages/airflow/cli/commands/task_command.py", line 483, in task_run
    task_return_code = _run_task_by_selected_method(args, _dag, ti)
                       ^^^^^^^^^^^^^^^^^^^^^^^^^^^^^^^^^^^^^^^^^^^^
  File "/home/airflow/.local/lib/python3.12/site-packages/airflow/cli/commands/task_command.py", line 256, in _run_task_by_selected_method
    return _run_raw_task(args, ti)
           ^^^^^^^^^^^^^^^^^^^^^^^
  File "/home/airflow/.local/lib/python3.12/site-packages/airflow/cli/commands/task_command.py", line 341, in _run_raw_task
    return ti._run_raw_task(
           ^^^^^^^^^^^^^^^^^
  File "/home/airflow/.local/lib/python3.12/site-packages/airflow/utils/session.py", line 97, in wrapper
    return func(*args, session=session, **kwargs)
           ^^^^^^^^^^^^^^^^^^^^^^^^^^^^^^^^^^^^^^
  File "/home/airflow/.local/lib/python3.12/site-packages/airflow/models/taskinstance.py", line 3006, in _run_raw_task
    return _run_raw_task(
           ^^^^^^^^^^^^^^
  File "/home/airflow/.local/lib/python3.12/site-packages/airflow/models/taskinstance.py", line 274, in _run_raw_task
    TaskInstance._execute_task_with_callbacks(
  File "/home/airflow/.local/lib/python3.12/site-packages/airflow/models/taskinstance.py", line 3161, in _execute_task_with_callbacks
    result = self._execute_task(context, task_orig)
             ^^^^^^^^^^^^^^^^^^^^^^^^^^^^^^^^^^^^^^
  File "/home/airflow/.local/lib/python3.12/site-packages/airflow/models/taskinstance.py", line 3185, in _execute_task
    return _execute_task(self, context, task_orig)
           ^^^^^^^^^^^^^^^^^^^^^^^^^^^^^^^^^^^^^^^
  File "/home/airflow/.local/lib/python3.12/site-packages/airflow/models/taskinstance.py", line 768, in _execute_task
    result = _execute_callable(context=context, **execute_callable_kwargs)
             ^^^^^^^^^^^^^^^^^^^^^^^^^^^^^^^^^^^^^^^^^^^^^^^^^^^^^^^^^^^^^
  File "/home/airflow/.local/lib/python3.12/site-packages/airflow/models/taskinstance.py", line 734, in _execute_callable
    return ExecutionCallableRunner(
           ^^^^^^^^^^^^^^^^^^^^^^^^
  File "/home/airflow/.local/lib/python3.12/site-packages/airflow/utils/operator_helpers.py", line 252, in run
    return self.func(*args, **kwargs)
           ^^^^^^^^^^^^^^^^^^^^^^^^^^
  File "/home/airflow/.local/lib/python3.12/site-packages/airflow/models/baseoperator.py", line 424, in wrapper
    return func(self, *args, **kwargs)
           ^^^^^^^^^^^^^^^^^^^^^^^^^^^
  File "/home/airflow/.local/lib/python3.12/site-packages/airflow/operators/python.py", line 238, in execute
    return_value = self.execute_callable()
                   ^^^^^^^^^^^^^^^^^^^^^^^
  File "/home/airflow/.local/lib/python3.12/site-packages/airflow/operators/python.py", line 256, in execute_callable
    return runner.run(*self.op_args, **self.op_kwargs)
           ^^^^^^^^^^^^^^^^^^^^^^^^^^^^^^^^^^^^^^^^^^^
  File "/home/airflow/.local/lib/python3.12/site-packages/airflow/utils/operator_helpers.py", line 252, in run
    return self.func(*args, **kwargs)
           ^^^^^^^^^^^^^^^^^^^^^^^^^^
  File "/opt/airflow/dags/scripts/crawl_data.py", line 133, in extract_data
    blob.upload_from_string(json.dumps(all_raw_data))
  File "/usr/local/lib/python3.12/contextlib.py", line 81, in inner
    return func(*args, **kwds)
           ^^^^^^^^^^^^^^^^^^^
  File "/home/airflow/.local/lib/python3.12/site-packages/google/cloud/storage/blob.py", line 3128, in upload_from_string
    self.upload_from_file(
  File "/usr/local/lib/python3.12/contextlib.py", line 81, in inner
    return func(*args, **kwds)
           ^^^^^^^^^^^^^^^^^^^
  File "/home/airflow/.local/lib/python3.12/site-packages/google/cloud/storage/blob.py", line 2851, in upload_from_file
    self._prep_and_do_upload(
  File "/home/airflow/.local/lib/python3.12/site-packages/google/cloud/storage/blob.py", line 2700, in _prep_and_do_upload
    created_json = self._do_upload(
                   ^^^^^^^^^^^^^^^^
  File "/home/airflow/.local/lib/python3.12/site-packages/google/cloud/storage/blob.py", line 2506, in _do_upload
    response = self._do_multipart_upload(
               ^^^^^^^^^^^^^^^^^^^^^^^^^^
  File "/home/airflow/.local/lib/python3.12/site-packages/google/cloud/storage/blob.py", line 2007, in _do_multipart_upload
    response = upload.transmit(
               ^^^^^^^^^^^^^^^^
  File "/home/airflow/.local/lib/python3.12/site-packages/google/resumable_media/requests/upload.py", line 153, in transmit
    return _request_helpers.wait_and_retry(
           ^^^^^^^^^^^^^^^^^^^^^^^^^^^^^^^^
  File "/home/airflow/.local/lib/python3.12/site-packages/google/resumable_media/requests/_request_helpers.py", line 155, in wait_and_retry
    response = func()
               ^^^^^^
  File "/home/airflow/.local/lib/python3.12/site-packages/google/resumable_media/requests/upload.py", line 145, in retriable_request
    result = transport.request(
             ^^^^^^^^^^^^^^^^^^
  File "/home/airflow/.local/lib/python3.12/site-packages/google/auth/transport/requests.py", line 533, in request
    self.credentials.before_request(auth_request, method, url, request_headers)
  File "/home/airflow/.local/lib/python3.12/site-packages/google/auth/credentials.py", line 239, in before_request
    self._blocking_refresh(request)
  File "/home/airflow/.local/lib/python3.12/site-packages/google/auth/credentials.py", line 202, in _blocking_refresh
    self.refresh(request)
  File "/home/airflow/.local/lib/python3.12/site-packages/google/oauth2/service_account.py", line 448, in refresh
    access_token, expiry, _ = _client.jwt_grant(
                              ^^^^^^^^^^^^^^^^^^
  File "/home/airflow/.local/lib/python3.12/site-packages/google/oauth2/_client.py", line 299, in jwt_grant
    response_data = _token_endpoint_request(
                    ^^^^^^^^^^^^^^^^^^^^^^^^
  File "/home/airflow/.local/lib/python3.12/site-packages/google/oauth2/_client.py", line 259, in _token_endpoint_request
    response_status_ok, response_data, retryable_error = _token_endpoint_request_no_throw(
                                                         ^^^^^^^^^^^^^^^^^^^^^^^^^^^^^^^^^
  File "/home/airflow/.local/lib/python3.12/site-packages/google/oauth2/_client.py", line 192, in _token_endpoint_request_no_throw
    response = request(
               ^^^^^^^^
  File "/home/airflow/.local/lib/python3.12/site-packages/google/auth/transport/requests.py", line 192, in __call__
    raise new_exc from caught_exc
google.auth.exceptions.TransportError: HTTPSConnectionPool(host='oauth2.googleapis.com', port=443): Max retries exceeded with url: /token (Caused by NewConnectionError('<urllib3.connection.HTTPSConnection object at 0x7f444da167e0>: Failed to establish a new connection: [Errno 101] Network is unreachable'))
[2025-03-08T05:40:21.984+0000] {local_task_job_runner.py:266} INFO - Task exited with return code 1
[2025-03-08T05:40:22.036+0000] {taskinstance.py:3901} INFO - 0 downstream tasks scheduled from follow-on schedule check
[2025-03-08T05:40:22.040+0000] {local_task_job_runner.py:245} INFO - ::endgroup::
